Workbook
Name BillingFrequencyList: Settings!$N$3:$N$5
Name CategoryList: Settings!$A$3:$A$82
Name CategoryTypeList: Settings!$B$3:$B$82
Name CurrencyList: Settings!$H$3:$H$7
Name MonthList: Settings!$J$3:$J$14
Name PayFrequencyList: Settings!$F$3:$F$6
Name SubCategoryList: Settings!$T$3:$T$10
Name TypeList: Settings!$D$3:$D$7
Name WeekStartList: Settings!$L$3:$L$4
Name YearList: Settings!$P$3:$P$9
Name YesNoList: Settings!$R$3:$R$4
Name TriggerList: Settings!$V$3:$V$8
Name FeelingList: Settings!$X$3:$X$5
Name DecisionList: Settings!$Z$3:$Z$5
Name AsOfDate: 'Flexible Income Budget'!$B$66
Name PeriodEnd: 'Flexible Income Budget'!$B$7
Name PeriodStart: 'Flexible Income Budget'!$B$5
Name GoalNameList: 'Savings & Debt Goal Tracker'!$J$6:$J$21
Name PeriodEnd: 'Paycheck Budget'!$B$7
Name PeriodStart: 'Paycheck Budget'!$B$5
Name PeriodEnd: Example!$B$7
Name PeriodStart: Example!$B$5

Sheet 🌸 Welcome
A1: Calm Money Reset
A2: An ADHD-friendly budget and debt tracker. Shame-free, visual, and built to feel calm, not overwhelming.
A4: Hi, welcome! This planner takes care of the math for you. You just fill in your numbers.
A6: This planner is built for Microsoft Excel (and Excel Online/OneDrive). It also works in Google Sheets once uploaded, though some conditional formatting and colors may shift slightly.
A8: How to Use This Planner
A9: 1. Make it yours first. Go to the Transactions Log tab and the Settings tab to add your own income sources, bill names, expense categories, savings goals, and debts. You only need to do this once. Everything else in the workbook updates automatically from this list.
A10: 2. Set your starting point. On the Paycheck Budget tab (or the Flexible Income Budget tab if your income varies), choose your Start Date and how often you get paid: Weekly, Biweekly, Semi-Monthly, or Monthly. You can start on any day, not just the 1st of the month.
A11: 3. Log everything in one place. Every time money comes in or goes out, add one line to the Transactions Log: the date, the category, the type (Bill, Expense, Saving, Debt, or Income), and the amount. This is the only place you enter numbers. Every other tab reads from this log automatically, so nothing needs to be typed twice.
A12: 4. Watch your dashboard update. The Paycheck Budget tab shows your "Amount Left to Spend," your income vs. bills vs. expenses vs. savings vs. debt, and simple charts. All of it updates the moment you add a transaction. You don't need to touch any formulas.
A13: 5. Add your bills once, and let the calendar do the rest. Log your bills as Type "Bill" in the Transactions Log with their due date, and they'll automatically appear on the Bill Calendar that month.
A14: 6. Track subscriptions and goals as bonuses. Use the Subscription Tracker to see what you're really paying for streaming, memberships, and software each month. Use the Savings & Debt Goal Tracker to watch progress toward specific goals (like a holiday fund or paying off a credit card) fill up visually.
A15: 7. Not sure where to start? Look at the Example tab. It's a fully filled-out sample month. If anything ever looks broken, compare it to the Example tab rather than guessing.
... A29: Quick guide: paycheck-based income → Paycheck Budget tab. Irregular or freelance income → Flexible Income Budget tab.

Sheet 🌿 Dashboard
A1: 🌿 Calm Money Reset
A2: One calm glance. No dense charts, no red flags. Just what you need to decide right now.
B4: Safe to spend this week | D4: Days until next bill | F4: Low-spend streak
B5: =IFERROR(MAX('Flexible Income Budget'!E10,0)/MAX(ROUNDUP(('Flexible Income Budget'!B7-TODAY())/7,0),1),0) | D5: {=IFERROR(IF(COUNTIFS(TransactionsLog[Type],"Bill",TransactionsLog[Date],">="&TODAY())=0,"None",MIN(IF((TransactionsLog[Type]="Bill")*(TransactionsLog[Date]>=TODAY()),TransactionsLog[Date],""))-TODAY()),"None")} | F5: =IFERROR('🌱 Low-Spend Streaks'!$B$7,0)
A8: Your progress
A10: 💚 Debt paid off | D10: =REPT("█",ROUND($J$10*24,0))&REPT("░",24-ROUND($J$10*24,0)) | H10: =$J$10 | J10: =IFERROR(SUM('Savings & Debt Goal Tracker'!E17:E24)/SUM('Savings & Debt Goal Tracker'!B17:B24),0)
A12: 🌷 Savings goal | D12: =REPT("█",ROUND($J$12*24,0))&REPT("░",24-ROUND($J$12*24,0)) | H12: =$J$12 | J12: =IFERROR(SUM('Savings & Debt Goal Tracker'!E6:E13)/SUM('Savings & Debt Goal Tracker'!B6:B13),0)
A14: This month, at a glance
B15: Income | D15: Spent | F15: Left to spend
B16: ='Flexible Income Budget'!E5 | D16: ='Flexible Income Budget'!O5 | F16: ='Flexible Income Budget'!E10
A18: This isn't about restriction. It's about awareness, and you're already here, paying attention. That counts. 🤍

Sheet Flexible Income Budget
A1: Flexible Income Budget | G1: LEFT TO SPEND | I1: INCOME | J1: BILLS | K1: EXPENSES | L1: SAVINGS | M1: DEBT
A2: Built for income that changes month to month: freelance, commission, gig work, or multiple income streams. Everything below still reads from your Transactions Log automatically. | G2: =E10 | I2: =C20 | J2: =C32 | K2: =C44 | L2: =C53 | M2: =C61
N3: Chart data (auto, don't edit)
A4: Your Setup | D4: Cash Flow Summary | G4: ="Days left: "&IF(ISNUMBER(B7),MAX(B7-TODAY(),0),0) | N4: Left to Spend | O4: =MAX(E10,0)
A5: Start Date | B5: 46235 | D5: Income | E5: =C20 | N5: Spent | O5: =C32+C44+C53+C61
A6: Pay Frequency | B6: Monthly | D6: Bills | E6: =-C32
A7: Budget Period End | B7: 46265 | D7: Expenses | E7: =-C44
A8: Currency | B8: USD | D8: Savings | E8: =-C53 | N8: Bills | O8: =C32
D9: Debt | E9: =-C61 | N9: Expenses | O9: =C44
D10: Amount Left to Spend | E10: =E5+E6+E7+E8+E9 | I10: =E10 | N10: Savings | O10: =C53
N11: Debt | O11: =C61
N12: Left to Spend | O12: =MAX(E10,0)
A14: Income Summary | B14: Budget | C14: Actual | D14: Above/Below Budget | E14: ✓
A15: =Settings!A3 | B15: 0 | C15: =SUMIFS(TransactionsLog[Amount],TransactionsLog[Category],$A15,TransactionsLog[Date],">="&PeriodStart,TransactionsLog[Date],"<="&PeriodEnd) | D15: =C15-B15 | N15: Category | O15: Actual
A16: =Settings!A4 | B16: 0 | C16: =SUMIFS(TransactionsLog[Amount],TransactionsLog[Category],$A16,TransactionsLog[Date],">="&PeriodStart,TransactionsLog[Date],"<="&PeriodEnd) | D16: =C16-B16 | N16: =A36 | O16: =C36
A17: =Settings!A5 | B17: 0 | C17: =SUMIFS(TransactionsLog[Amount],TransactionsLog[Category],$A17,TransactionsLog[Date],">="&PeriodStart,TransactionsLog[Date],"<="&PeriodEnd) | D17: =C17-B17 | N17: =A37 | O17: =C37
A18: =Settings!A6 | B18: 0 | C18: =SUMIFS(TransactionsLog[Amount],TransactionsLog[Category],$A18,TransactionsLog[Date],">="&PeriodStart,TransactionsLog[Date],"<="&PeriodEnd) | D18: =C18-B18 | N18: =A38 | O18: =C38
A19: =Settings!A7 | B19: 0 | C19: =SUMIFS(TransactionsLog[Amount],TransactionsLog[Category],$A19,TransactionsLog[Date],">="&PeriodStart,TransactionsLog[Date],"<="&PeriodEnd) | D19: =C19-B19 | N19: =A39 | O19: =C39
A20: Total Income | B20: =SUM(B15:B19) | C20: =SUM(C15:C19) | D20: =C20-B20 | N20: =A40 | O20: =C40
N21: =A41 | O21: =C41
N22: =A42 | O22: =C42
A23: Bill Tracker | B23: Budget | C23: Actual | D23: Remaining | E23: ✓ | N23: =A43 | O23: =C43
A24: =Settings!A8 | B24: 0 | C24: =SUMIFS(TransactionsLog[Amount],TransactionsLog[Category],$A24,TransactionsLog[Date],">="&PeriodStart,TransactionsLog[Date],"<="&PeriodEnd) | D24: =B24-C24 | E24: ✓
A25: =Settings!A9 | B25: 0 | C25: =SUMIFS(TransactionsLog[Amount],TransactionsLog[Category],$A25,TransactionsLog[Date],">="&PeriodStart,TransactionsLog[Date],"<="&PeriodEnd) | D25: =B25-C25
A26: =Settings!A10 | B26: 0 | C26: =SUMIFS(TransactionsLog[Amount],TransactionsLog[Category],$A26,TransactionsLog[Date],">="&PeriodStart,TransactionsLog[Date],"<="&PeriodEnd) | D26: =B26-C26 | N26: Category | O26: Budget | P26: Actual
A27: =Settings!A11 | B27: 0 | C27: =SUMIFS(TransactionsLog[Amount],TransactionsLog[Category],$A27,TransactionsLog[Date],">="&PeriodStart,TransactionsLog[Date],"<="&PeriodEnd) | D27: =B27-C27 | N27: Income | O27: =B20 | P27: =C20
A28: =Settings!A12 | B28: 0 | C28: =SUMIFS(TransactionsLog[Amount],TransactionsLog[Category],$A28,TransactionsLog[Date],">="&PeriodStart,TransactionsLog[Date],"<="&PeriodEnd) | D28: =B28-C28 | N28: Bills | O28: =B32 | P28: =C32
A29: =Settings!A13 | B29: 0 | C29: =SUMIFS(TransactionsLog[Amount],TransactionsLog[Category],$A29,TransactionsLog[Date],">="&PeriodStart,TransactionsLog[Date],"<="&PeriodEnd) | D29: =B29-C29 | N29: Expenses | O29: =B44 | P29: =C44
A30: =Settings!A14 | B30: 0 | C30: =SUMIFS(TransactionsLog[Amount],TransactionsLog[Category],$A30,TransactionsLog[Date],">="&PeriodStart,TransactionsLog[Date],"<="&PeriodEnd) | D30: =B30-C30 | N30: Savings | O30: =B53 | P30: =C53
A31: =Settings!A15 | B31: 0 | C31: ='Subscription Tracker'!$C$4 | D31: =B31-C31 | N31: Debt | O31: =B61 | P31: =C61
A32: Total Bills | B32: =SUM(B24:B31) | C32: =SUM(C24:C31) | D32: =B32-C32
A35: Expense Summary | B35: Budget | C35: Actual | D35: Remaining | E35: ✓
A36: =Settings!A16 | B36: 0 | D36: =B36-C36
A37: =Settings!A17 | B37: 0 | C37: =SUMIFS(TransactionsLog[Amount],TransactionsLog[Category],$A37,TransactionsLog[Date],">="&PeriodStart,TransactionsLog[Date],"<="&PeriodEnd) | D37: =B37-C37
A38: =Settings!A18 | B38: 0 | C38: =SUMIFS(TransactionsLog[Amount],TransactionsLog[Category],$A38,TransactionsLog[Date],">="&PeriodStart,TransactionsLog[Date],"<="&PeriodEnd) | D38: =B38-C38
A39: =Settings!A19 | B39: 0 | C39: =SUMIFS(TransactionsLog[Amount],TransactionsLog[Category],$A39,TransactionsLog[Date],">="&PeriodStart,TransactionsLog[Date],"<="&PeriodEnd) | D39: =B39-C39
A40: =Settings!A20 | B40: 0 | C40: =SUMIFS(TransactionsLog[Amount],TransactionsLog[Category],$A40,TransactionsLog[Date],">="&PeriodStart,TransactionsLog[Date],"<="&PeriodEnd) | D40: =B40-C40
A41: =Settings!A21 | B41: 0 | C41: =SUMIFS(TransactionsLog[Amount],TransactionsLog[Category],$A41,TransactionsLog[Date],">="&PeriodStart,TransactionsLog[Date],"<="&PeriodEnd) | D41: =B41-C41
A42: =Settings!A22 | B42: 0 | C42: =SUMIFS(TransactionsLog[Amount],TransactionsLog[Category],$A42,TransactionsLog[Date],">="&PeriodStart,TransactionsLog[Date],"<="&PeriodEnd) | D42: =B42-C42
A43: =Settings!A23 | B43: 0 | C43: =SUMIFS(TransactionsLog[Amount],TransactionsLog[Category],$A43,TransactionsLog[Date],">="&PeriodStart,TransactionsLog[Date],"<="&PeriodEnd) | D43: =B43-C43
...

Sheet 🪴 Transactions Log
A1: Transactions Log
A2: Add one line every time money comes in or goes out. Type fills in automatically once you choose a Category. Every other tab reads from this list, so you only ever type a number once.
A4: Date | B4: Category | C4: Type | D4: Amount | E4: Notes
C6: =IFERROR(INDEX(CategoryTypeList,MATCH(TransactionsLog[[#This Row],[Category]],CategoryList,0)),"")
C7: =IFERROR(INDEX(CategoryTypeList,MATCH(TransactionsLog[[#This Row],[Category]],CategoryList,0)),"")
C8: =IFERROR(INDEX(CategoryTypeList,MATCH(TransactionsLog[[#This Row],[Category]],CategoryList,0)),"")
C9: =IFERROR(INDEX(CategoryTypeList,MATCH(TransactionsLog[[#This Row],[Category]],CategoryList,0)),"")
C10: =IFERROR(INDEX(CategoryTypeList,MATCH(TransactionsLog[[#This Row],[Category]],CategoryList,0)),"")
C11: =IFERROR(INDEX(CategoryTypeList,MATCH(TransactionsLog[[#This Row],[Category]],CategoryList,0)),"")
C12: =IFERROR(INDEX(CategoryTypeList,MATCH(TransactionsLog[[#This Row],[Category]],CategoryList,0)),"")
C13: =IFERROR(INDEX(CategoryTypeList,MATCH(TransactionsLog[[#This Row],[Category]],CategoryList,0)),"")
C14: =IFERROR(INDEX(CategoryTypeList,MATCH(TransactionsLog[[#This Row],[Category]],CategoryList,0)),"")
C15: =IFERROR(INDEX(CategoryTypeList,MATCH(TransactionsLog[[#This Row],[Category]],CategoryList,0)),"")
C16: =IFERROR(INDEX(CategoryTypeList,MATCH(TransactionsLog[[#This Row],[Category]],CategoryList,0)),"")
C17: =IFERROR(INDEX(CategoryTypeList,MATCH(TransactionsLog[[#This Row],[Category]],CategoryList,0)),"")
... C304: =IFERROR(INDEX(CategoryTypeList,MATCH(TransactionsLog[[#This Row],[Category]],CategoryList,0)),"")

Sheet 🏦 Bank Import
A1: Bank Import Helper
A2: 1. Export your bank statement as Excel or CSV. 2. Copy the Date, Description, and Amount columns and paste them into the yellow area below (paste values only). 3. Check the suggested category in column D. Change it using the dropdown if it's wrong. 4. Once everything looks right, copy columns E through I below and paste them into your Transactions Log.
A3: This tool does not connect to your bank. You export your statement yourself and paste it in here. | K3: Keyword List (edit this to teach the import your own categories)
A4: Paste your bank export here | D4: Ready to copy into Transactions Log | K4: Add your own rows here any time. If a bank description contains this keyword anywhere, it will suggest that category automatically.
A5: Date | B5: Description | C5: Amount | D5: Suggested Category | E5: Date | F5: Category | G5: Type | H5: Amount | I5: Notes | K5: Keyword | L5: Category
D6: {=IF(B6="","",IFERROR(INDEX($L$6:$L$33,MATCH(TRUE,ISNUMBER(SEARCH($K$6:$K$33,B6)),0)),"Review Manually"))} | E6: =IF(A6="","",A6) | F6: =IF(B6="","",D6) | G6: =IF(F6="","",IFERROR(INDEX(CategoryTypeList,MATCH(F6,CategoryList,0)),"")) | H6: =IF(C6="","",C6) | K6: NETFLIX | L6: Subscriptions
D7: {=IF(B7="","",IFERROR(INDEX($L$6:$L$33,MATCH(TRUE,ISNUMBER(SEARCH($K$6:$K$33,B7)),0)),"Review Manually"))} | E7: =IF(A7="","",A7) | F7: =IF(B7="","",D7) | G7: =IF(F7="","",IFERROR(INDEX(CategoryTypeList,MATCH(F7,CategoryList,0)),"")) | H7: =IF(C7="","",C7) | K7: SPOTIFY | L7: Subscriptions
D8: {=IF(B8="","",IFERROR(INDEX($L$6:$L$33,MATCH(TRUE,ISNUMBER(SEARCH($K$6:$K$33,B8)),0)),"Review Manually"))} | E8: =IF(A8="","",A8) | F8: =IF(B8="","",D8) | G8: =IF(F8="","",IFERROR(INDEX(CategoryTypeList,MATCH(F8,CategoryList,0)),"")) | H8: =IF(C8="","",C8) | K8: HULU | L8: Subscriptions
D9: {=IF(B9="","",IFERROR(INDEX($L$6:$L$33,MATCH(TRUE,ISNUMBER(SEARCH($K$6:$K$33,B9)),0)),"Review Manually"))} | E9: =IF(A9="","",A9) | F9: =IF(B9="","",D9) | G9: =IF(F9="","",IFERROR(INDEX(CategoryTypeList,MATCH(F9,CategoryList,0)),"")) | H9: =IF(C9="","",C9) | K9: DISNEY+ | L9: Subscriptions
D10: {=IF(B10="","",IFERROR(INDEX($L$6:$L$33,MATCH(TRUE,ISNUMBER(SEARCH($K$6:$K$33,B10)),0)),"Review Manually"))} | E10: =IF(A10="","",A10) | F10: =IF(B10="","",D10) | G10: =IF(F10="","",IFERROR(INDEX(CategoryTypeList,MATCH(F10,CategoryList,0)),"")) | H10: =IF(C10="","",C10) | K10: UBER | L10: Transportation
D11: {=IF(B11="","",IFERROR(INDEX($L$6:$L$33,MATCH(TRUE,ISNUMBER(SEARCH($K$6:$K$33,B11)),0)),"Review Manually"))} | E11: =IF(A11="","",A11) | F11: =IF(B11="","",D11) | G11: =IF(F11="","",IFERROR(INDEX(CategoryTypeList,MATCH(F11,CategoryList,0)),"")) | H11: =IF(C11="","",C11) | K11: LYFT | L11: Transportation
D12: {=IF(B12="","",IFERROR(INDEX($L$6:$L$33,MATCH(TRUE,ISNUMBER(SEARCH($K$6:$K$33,B12)),0)),"Review Manually"))} | E12: =IF(A12="","",A12) | F12: =IF(B12="","",D12) | G12: =IF(F12="","",IFERROR(INDEX(CategoryTypeList,MATCH(F12,CategoryList,0)),"")) | H12: =IF(C12="","",C12) | K12: SHELL | L12: Transportation
D13: {=IF(B13="","",IFERROR(INDEX($L$6:$L$33,MATCH(TRUE,ISNUMBER(SEARCH($K$6:$K$33,B13)),0)),"Review Manually"))} | E13: =IF(A13="","",A13) | F13: =IF(B13="","",D13) | G13: =IF(F13="","",IFERROR(INDEX(CategoryTypeList,MATCH(F13,CategoryList,0)),"")) | H13: =IF(C13="","",C13) | K13: GAS STATION | L13: Transportation
D14: {=IF(B14="","",IFERROR(INDEX($L$6:$L$33,MATCH(TRUE,ISNUMBER(SEARCH($K$6:$K$33,B14)),0)),"Review Manually"))} | E14: =IF(A14="","",A14) | F14: =IF(B14="","",D14) | G14: =IF(F14="","",IFERROR(INDEX(CategoryTypeList,MATCH(F14,CategoryList,0)),"")) | H14: =IF(C14="","",C14) | K14: WALMART | L14: Groceries
D15: {=IF(B15="","",IFERROR(INDEX($L$6:$L$33,MATCH(TRUE,ISNUMBER(SEARCH($K$6:$K$33,B15)),0)),"Review Manually"))} | E15: =IF(A15="","",A15) | F15: =IF(B15="","",D15) | G15: =IF(F15="","",IFERROR(INDEX(CategoryTypeList,MATCH(F15,CategoryList,0)),"")) | H15: =IF(C15="","",C15) | K15: TESCO | L15: Groceries
D16: {=IF(B16="","",IFERROR(INDEX($L$6:$L$33,MATCH(TRUE,ISNUMBER(SEARCH($K$6:$K$33,B16)),0)),"Review Manually"))} | E16: =IF(A16="","",A16) | F16: =IF(B16="","",D16) | G16: =IF(F16="","",IFERROR(INDEX(CategoryTypeList,MATCH(F16,CategoryList,0)),"")) | H16: =IF(C16="","",C16) | K16: WHOLE FOODS | L16: Groceries
D17: {=IF(B17="","",IFERROR(INDEX($L$6:$L$33,MATCH(TRUE,ISNUMBER(SEARCH($K$6:$K$33,B17)),0)),"Review Manually"))} | E17: =IF(A17="","",A17) | F17: =IF(B17="","",D17) | G17: =IF(F17="","",IFERROR(INDEX(CategoryTypeList,MATCH(F17,CategoryList,0)),"")) | H17: =IF(C17="","",C17) | K17: COSTCO | L17: Groceries
... D33: {=IF(B33="","",IFERROR(INDEX($L$6:$L$33,MATCH(TRUE,ISNUMBER(SEARCH($K$6:$K$33,B33)),0)),"Review Manually"))} | E33: =IF(A33="","",A33) | F33: =IF(B33="","",D33) | G33: =IF(F33="","",IFERROR(INDEX(CategoryTypeList,MATCH(F33,CategoryList,0)),"")) | H33: =IF(C33="","",C33) | K33: DIRECT DEPOSIT | L33: Paycheck
D34: {=IF(B34="","",IFERROR(INDEX($L$6:$L$33,MATCH(TRUE,ISNUMBER(SEARCH($K$6:$K$33,B34)),0)),"Review Manually"))} | E34: =IF(A34="","",A34) | F34: =IF(B34="","",D34) | G34: =IF(F34="","",IFERROR(INDEX(CategoryTypeList,MATCH(F34,CategoryList,0)),"")) | H34: =IF(C34="","",C34)
D35: {=IF(B35="","",IFERROR(INDEX($L$6:$L$33,MATCH(TRUE,ISNUMBER(SEARCH($K$6:$K$33,B35)),0)),"Review Manually"))} | E35: =IF(A35="","",A35) | F35: =IF(B35="","",D35) | G35: =IF(F35="","",IFERROR(INDEX(CategoryTypeList,MATCH(F35,CategoryList,0)),"")) | H35: =IF(C35="","",C35)
D36: {=IF(B36="","",IFERROR(INDEX($L$6:$L$33,MATCH(TRUE,ISNUMBER(SEARCH($K$6:$K$33,B36)),0)),"Review Manually"))} | E36: =IF(A36="","",A36) | F36: =IF(B36="","",D36) | G36: =IF(F36="","",IFERROR(INDEX(CategoryTypeList,MATCH(F36,CategoryList,0)),"")) | H36: =IF(C36="","",C36)
D37: {=IF(B37="","",IFERROR(INDEX($L$6:$L$33,MATCH(TRUE,ISNUMBER(SEARCH($K$6:$K$33,B37)),0)),"Review Manually"))} | E37: =IF(A37="","",A37) | F37: =IF(B37="","",D37) | G37: =IF(F37="","",IFERROR(INDEX(CategoryTypeList,MATCH(F37,CategoryList,0)),"")) | H37: =IF(C37="","",C37)
D38: {=IF(B38="","",IFERROR(INDEX($L$6:$L$33,MATCH(TRUE,ISNUMBER(SEARCH($K$6:$K$33,B38)),0)),"Review Manually"))} | E38: =IF(A38="","",A38) | F38: =IF(B38="","",D38) | G38: =IF(F38="","",IFERROR(INDEX(CategoryTypeList,MATCH(F38,CategoryList,0)),"")) | H38: =IF(C38="","",C38)
D39: {=IF(B39="","",IFERROR(INDEX($L$6:$L$33,MATCH(TRUE,ISNUMBER(SEARCH($K$6:$K$33,B39)),0)),"Review Manually"))} | E39: =IF(A39="","",A39) | F39: =IF(B39="","",D39) | G39: =IF(F39="","",IFERROR(INDEX(CategoryTypeList,MATCH(F39,CategoryList,0)),"")) | H39: =IF(C39="","",C39)
D40: {=IF(B40="","",IFERROR(INDEX($L$6:$L$33,MATCH(TRUE,ISNUMBER(SEARCH($K$6:$K$33,B40)),0)),"Review Manually"))} | E40: =IF(A40="","",A40) | F40: =IF(B40="","",D40) | G40: =IF(F40="","",IFERROR(INDEX(CategoryTypeList,MATCH(F40,CategoryList,0)),"")) | H40: =IF(C40="","",C40)
D41: {=IF(B41="","",IFERROR(INDEX($L$6:$L$33,MATCH(TRUE,ISNUMBER(SEARCH($K$6:$K$33,B41)),0)),"Review Manually"))} | E41: =IF(A41="","",A41) | F41: =IF(B41="","",D41) | G41: =IF(F41="","",IFERROR(INDEX(CategoryTypeList,MATCH(F41,CategoryList,0)),"")) | H41: =IF(C41="","",C41)
D42: {=IF(B42="","",IFERROR(INDEX($L$6:$L$33,MATCH(TRUE,ISNUMBER(SEARCH($K$6:$K$33,B42)),0)),"Review Manually"))} | E42: =IF(A42="","",A42) | F42: =IF(B42="","",D42) | G42: =IF(F42="","",IFERROR(INDEX(CategoryTypeList,MATCH(F42,CategoryList,0)),"")) | H42: =IF(C42="","",C42)
D43: {=IF(B43="","",IFERROR(INDEX($L$6:$L$33,MATCH(TRUE,ISNUMBER(SEARCH($K$6:$K$33,B43)),0)),"Review Manually"))} | E43: =IF(A43="","",A43) | F43: =IF(B43="","",D43) | G43: =IF(F43="","",IFERROR(INDEX(CategoryTypeList,MATCH(F43,CategoryList,0)),"")) | H43: =IF(C43="","",C43)
D44: {=IF(B44="","",IFERROR(INDEX($L$6:$L$33,MATCH(TRUE,ISNUMBER(SEARCH($K$6:$K$33,B44)),0)),"Review Manually"))} | E44: =IF(A44="","",A44) | F44: =IF(B44="","",D44) | G44: =IF(F44="","",IFERROR(INDEX(CategoryTypeList,MATCH(F44,CategoryList,0)),"")) | H44: =IF(C44="","",C44)
D45: {=IF(B45="","",IFERROR(INDEX($L$6:$L$33,MATCH(TRUE,ISNUMBER(SEARCH($K$6:$K$33,B45)),0)),"Review Manually"))} | E45: =IF(A45="","",A45) | F45: =IF(B45="","",D45) | G45: =IF(F45="","",IFERROR(INDEX(CategoryTypeList,MATCH(F45,CategoryList,0)),"")) | H45: =IF(C45="","",C45)
... D105: {=IF(B105="","",IFERROR(INDEX($L$6:$L$33,MATCH(TRUE,ISNUMBER(SEARCH($K$6:$K$33,B105)),0)),"Review Manually"))} | E105: =IF(A105="","",A105) | F105: =IF(B105="","",D105) | G105: =IF(F105="","",IFERROR(INDEX(CategoryTypeList,MATCH(F105,CategoryList,0)),"")) | H105: =IF(C105="","",C105)

Sheet 💛 Doom Spending Log
A1: 💛 Doom Spending Log
A2: Just noticing, not judging. Log the little impulse buys so you can see your own patterns gently over time. No shame here.
A4: Logged this month | C4: Spent this month | H4: By trigger
A5: =COUNTIFS($A$9:$A$508,">="&(EOMONTH(TODAY(),-1)+1),$A$9:$A$508,"<="&EOMONTH(TODAY(),0)) | C5: =SUMIFS($B$9:$B$508,$A$9:$A$508,">="&(EOMONTH(TODAY(),-1)+1),$A$9:$A$508,"<="&EOMONTH(TODAY(),0)) | H5: Boredom | I5: =COUNTIF($D$9:$D$508,"Boredom")
H6: Stress | I6: =COUNTIF($D$9:$D$508,"Stress")
A7: Date | B7: Amount | C7: What I bought | D7: Trigger | E7: How I feel now | H7: Scrolling | I7: =COUNTIF($D$9:$D$508,"Scrolling")
A8: =EOMONTH(TODAY(),-1)+3 | B8: 18.5 | C8: Impulse phone case (example, type over me) | D8: Scrolling | E8: Neutral | H8: Social pressure | I8: =COUNTIF($D$9:$D$508,"Social pressure")
H9: Celebration | I9: =COUNTIF($D$9:$D$508,"Celebration")
H10: Other | I10: =COUNTIF($D$9:$D$508,"Other")

Sheet 🌱 Low-Spend Streaks
A1: Low-Spend Streak Tracker | L1: =MATCH($C$4,MonthList,0)
A2: Every no-spend (or low-spend) day is a win. Mark a check and watch your streak grow. Miss a day? You just start a fresh one. That's it. | L2: =DAY(EOMONTH(DATE($G$4,$L$1,1),0))
L3: =IF(AND($L$1=MONTH(TODAY()),$G$4=YEAR(TODAY())),DAY(TODAY()),$L$2)
B4: Month | C4: January | F4: Year | G4: 2026
B6: CURRENT STREAK | F6: LONGEST THIS MONTH | K6: 1 | L6: =B11 | M6: =IF(AND(1<=$L$2,L6="✓"),0+1,0)
B7: =INDEX($M$6:$M$36,$L$3) | F7: =MAX($M$6:$M$36) | K7: 2 | L7: =C11 | M7: =IF(AND(2<=$L$2,L7="✓"),M6+1,0)
K8: 3 | L8: =D11 | M8: =IF(AND(3<=$L$2,L8="✓"),M7+1,0)
A9: Mark a check on every low-spend day | K9: 4 | L9: =E11 | M9: =IF(AND(4<=$L$2,L9="✓"),M8+1,0)
B10: =IF(1<=$L$2,1,"") | C10: =IF(2<=$L$2,2,"") | D10: =IF(3<=$L$2,3,"") | E10: =IF(4<=$L$2,4,"") | F10: =IF(5<=$L$2,5,"") | G10: =IF(6<=$L$2,6,"") | H10: =IF(7<=$L$2,7,"") | K10: 5 | L10: =F11 | M10: =IF(AND(5<=$L$2,L10="✓"),M9+1,0)
K11: 6 | L11: =G11 | M11: =IF(AND(6<=$L$2,L11="✓"),M10+1,0)
K12: 7 | L12: =H11 | M12: =IF(AND(7<=$L$2,L12="✓"),M11+1,0)
B13: =IF(8<=$L$2,8,"") | C13: =IF(9<=$L$2,9,"") | D13: =IF(10<=$L$2,10,"") | E13: =IF(11<=$L$2,11,"") | F13: =IF(12<=$L$2,12,"") | G13: =IF(13<=$L$2,13,"") | H13: =IF(14<=$L$2,14,"") | K13: 8 | L13: =B14 | M13: =IF(AND(8<=$L$2,L13="✓"),M12+1,0)
K14: 9 | L14: =C14 | M14: =IF(AND(9<=$L$2,L14="✓"),M13+1,0)
K15: 10 | L15: =D14 | M15: =IF(AND(10<=$L$2,L15="✓"),M14+1,0)
B16: =IF(15<=$L$2,15,"") | C16: =IF(16<=$L$2,16,"") | D16: =IF(17<=$L$2,17,"") | E16: =IF(18<=$L$2,18,"") | F16: =IF(19<=$L$2,19,"") | G16: =IF(20<=$L$2,20,"") | H16: =IF(21<=$L$2,21,"") | K16: 11 | L16: =E14 | M16: =IF(AND(11<=$L$2,L16="✓"),M15+1,0)
K17: 12 | L17: =F14 | M17: =IF(AND(12<=$L$2,L17="✓"),M16+1,0)
K18: 13 | L18: =G14 | M18: =IF(AND(13<=$L$2,L18="✓"),M17+1,0)
B19: =IF(22<=$L$2,22,"") | C19: =IF(23<=$L$2,23,"") | D19: =IF(24<=$L$2,24,"") | E19: =IF(25<=$L$2,25,"") | F19: =IF(26<=$L$2,26,"") | G19: =IF(27<=$L$2,27,"") | H19: =IF(28<=$L$2,28,"") | K19: 14 | L19: =H14 | M19: =IF(AND(14<=$L$2,L19="✓"),M18+1,0)
K20: 15 | L20: =B17 | M20: =IF(AND(15<=$L$2,L20="✓"),M19+1,0)
K21: 16 | L21: =C17 | M21: =IF(AND(16<=$L$2,L21="✓"),M20+1,0)
B22: =IF(29<=$L$2,29,"") | C22: =IF(30<=$L$2,30,"") | D22: =IF(31<=$L$2,31,"") | E22: =IF(32<=$L$2,32,"") | F22: =IF(33<=$L$2,33,"") | G22: =IF(34<=$L$2,34,"") | H22: =IF(35<=$L$2,35,"") | K22: 17 | L22: =D17 | M22: =IF(AND(17<=$L$2,L22="✓"),M21+1,0)
K23: 18 | L23: =E17 | M23: =IF(AND(18<=$L$2,L23="✓"),M22+1,0)
K24: 19 | L24: =F17 | M24: =IF(AND(19<=$L$2,L24="✓"),M23+1,0)
K25: 20 | L25: =G17 | M25: =IF(AND(20<=$L$2,L25="✓"),M24+1,0)
A26: =IF($B$7>=30,"30 days. A whole month of showing up for yourself. Incredible.",IF($B$7>=14,"Two weeks strong. Your brain is learning a new pattern. Keep going.",IF($B$7>=7,"A full week. That is real momentum. Be proud.",IF($B$7>=1,"You have started a streak. One day at a time.","A fresh page. Mark today whenever you are ready.")))) | K26: 21 | L26: =H17 | M26: =IF(AND(21<=$L$2,L26="✓"),M25+1,0)
K27: 22 | L27: =B20 | M27: =IF(AND(22<=$L$2,L27="✓"),M26+1,0)
K28: 23 | L28: =C20 | M28: =IF(AND(23<=$L$2,L28="✓"),M27+1,0)
K29: 24 | L29: =D20 | M29: =IF(AND(24<=$L$2,L29="✓"),M28+1,0)
K30: 25 | L30: =E20 | M30: =IF(AND(25<=$L$2,L30="✓"),M29+1,0)
K31: 26 | L31: =F20 | M31: =IF(AND(26<=$L$2,L31="✓"),M30+1,0)
K32: 27 | L32: =G20 | M32: =IF(AND(27<=$L$2,L32="✓"),M31+1,0)
K33: 28 | L33: =H20 | M33: =IF(AND(28<=$L$2,L33="✓"),M32+1,0)
K34: 29 | L34: =B23 | M34: =IF(AND(29<=$L$2,L34="✓"),M33+1,0)
K35: 30 | L35: =C23 | M35: =IF(AND(30<=$L$2,L35="✓"),M34+1,0)
K36: 31 | L36: =D23 | M36: =IF(AND(31<=$L$2,L36="✓"),M35+1,0)

Sheet ✋ Pause Before You Buy
A1: ✋ Pause Before You Buy
A2: The 24-hour rule, made simple. Before an impulse buy, log it here and give tomorrow-you a vote. Waiting is a win, not a loss.
A4: Times you paused | C4: Money paused | E4: Bought anyway
A5: =COUNTIF($F$9:$F$207,"Waited")+COUNTIF($F$9:$F$207,"Skipped") | C5: =SUMIF($F$9:$F$207,"Waited",$B$9:$B$207)+SUMIF($F$9:$F$207,"Skipped",$B$9:$B$207) | E5: =COUNTIF($F$9:$F$207,"Bought")
A7: Item | B7: Cost | C7: Do I need this? | D7: Can it wait 24h? | E7: How will I feel tomorrow? | F7: Decision
A8: Second pair of sneakers (example, type over me) | B8: 74 | C8: No | D8: Yes | E8: Relieved I waited | F8: Waited

Sheet 🗓️ Bill Calendar
A1: Bill Calendar
A2: Bills you've logged as Type "Bill" in your Transactions Log show up here automatically, on the day you dated them. Pick a month, year, and which day your week starts on.
A4: Month | B4: January | C4: Year | D4: 2026 | E4: Week Starts On | F4: Monday | I4: Month # | J4: =MATCH($B$4,MonthList,0)
I5: 1st of Month | J5: =DATE($D$4,$J$4,1)
B6: {=IF($F$4="Monday",INDEX({"Mon";"Tue";"Wed";"Thu";"Fri";"Sat";"Sun"},1),INDEX({"Sun";"Mon";"Tue";"Wed";"Thu";"Fri";"Sat"},1))} | C6: {=IF($F$4="Monday",INDEX({"Mon";"Tue";"Wed";"Thu";"Fri";"Sat";"Sun"},2),INDEX({"Sun";"Mon";"Tue";"Wed";"Thu";"Fri";"Sat"},2))} | D6: {=IF($F$4="Monday",INDEX({"Mon";"Tue";"Wed";"Thu";"Fri";"Sat";"Sun"},3),INDEX({"Sun";"Mon";"Tue";"Wed";"Thu";"Fri";"Sat"},3))} | E6: {=IF($F$4="Monday",INDEX({"Mon";"Tue";"Wed";"Thu";"Fri";"Sat";"Sun"},4),INDEX({"Sun";"Mon";"Tue";"Wed";"Thu";"Fri";"Sat"},4))} | F6: {=IF($F$4="Monday",INDEX({"Mon";"Tue";"Wed";"Thu";"Fri";"Sat";"Sun"},5),INDEX({"Sun";"Mon";"Tue";"Wed";"Thu";"Fri";"Sat"},5))} | G6: {=IF($F$4="Monday",INDEX({"Mon";"Tue";"Wed";"Thu";"Fri";"Sat";"Sun"},6),INDEX({"Sun";"Mon";"Tue";"Wed";"Thu";"Fri";"Sat"},6))} | H6: {=IF($F$4="Monday",INDEX({"Mon";"Tue";"Wed";"Thu";"Fri";"Sat";"Sun"},7),INDEX({"Sun";"Mon";"Tue";"Wed";"Thu";"Fri";"Sat"},7))} | I6: Offset | J6: =IF($F$4="Monday",WEEKDAY($J$5,2)-1,WEEKDAY($J$5,1)-1)
B7: =IF(MONTH(($J$5-$J$6+0))=$J$4,DAY(($J$5-$J$6+0)),"") | C7: =IF(MONTH(($J$5-$J$6+1))=$J$4,DAY(($J$5-$J$6+1)),"") | D7: =IF(MONTH(($J$5-$J$6+2))=$J$4,DAY(($J$5-$J$6+2)),"") | E7: =IF(MONTH(($J$5-$J$6+3))=$J$4,DAY(($J$5-$J$6+3)),"") | F7: =IF(MONTH(($J$5-$J$6+4))=$J$4,DAY(($J$5-$J$6+4)),"") | G7: =IF(MONTH(($J$5-$J$6+5))=$J$4,DAY(($J$5-$J$6+5)),"") | H7: =IF(MONTH(($J$5-$J$6+6))=$J$4,DAY(($J$5-$J$6+6)),"")
B8: {=IF(MONTH($J$5-$J$6+((ROW()-8)/2)*7+(COLUMN()-2))=$J$4,IFERROR(_xlfn.TEXTJOIN(CHAR(10),TRUE,IF((TransactionsLog[Type]="Bill")*(TransactionsLog[Date]=($J$5-$J$6+((ROW()-8)/2)*7+(COLUMN()-2))),"☐ "&TransactionsLog[Category]&" "&TEXT(TransactionsLog[Amount],"$0"),"")),""),"")} | C8: {=IF(MONTH($J$5-$J$6+((ROW()-8)/2)*7+(COLUMN()-2))=$J$4,IFERROR(_xlfn.TEXTJOIN(CHAR(10),TRUE,IF((TransactionsLog[Type]="Bill")*(TransactionsLog[Date]=($J$5-$J$6+((ROW()-8)/2)*7+(COLUMN()-2))),"☐ "&TransactionsLog[Category]&" "&TEXT(TransactionsLog[Amount],"$0"),"")),""),"")} | D8: {=IF(MONTH($J$5-$J$6+((ROW()-8)/2)*7+(COLUMN()-2))=$J$4,IFERROR(_xlfn.TEXTJOIN(CHAR(10),TRUE,IF((TransactionsLog[Type]="Bill")*(TransactionsLog[Date]=($J$5-$J$6+((ROW()-8)/2)*7+(COLUMN()-2))),"☐ "&TransactionsLog[Category]&" "&TEXT(TransactionsLog[Amount],"$0"),"")),""),"")} | E8: {=IF(MONTH($J$5-$J$6+((ROW()-8)/2)*7+(COLUMN()-2))=$J$4,IFERROR(_xlfn.TEXTJOIN(CHAR(10),TRUE,IF((TransactionsLog[Type]="Bill")*(TransactionsLog[Date]=($J$5-$J$6+((ROW()-8)/2)*7+(COLUMN()-2))),"☐ "&TransactionsLog[Category]&" "&TEXT(TransactionsLog[Amount],"$0"),"")),""),"")} | F8: {=IF(MONTH($J$5-$J$6+((ROW()-8)/2)*7+(COLUMN()-2))=$J$4,IFERROR(_xlfn.TEXTJOIN(CHAR(10),TRUE,IF((TransactionsLog[Type]="Bill")*(TransactionsLog[Date]=($J$5-$J$6+((ROW()-8)/2)*7+(COLUMN()-2))),"☐ "&TransactionsLog[Category]&" "&TEXT(TransactionsLog[Amount],"$0"),"")),""),"")} | G8: {=IF(MONTH($J$5-$J$6+((ROW()-8)/2)*7+(COLUMN()-2))=$J$4,IFERROR(_xlfn.TEXTJOIN(CHAR(10),TRUE,IF((TransactionsLog[Type]="Bill")*(TransactionsLog[Date]=($J$5-$J$6+((ROW()-8)/2)*7+(COLUMN()-2))),"☐ "&TransactionsLog[Category]&" "&TEXT(TransactionsLog[Amount],"$0"),"")),""),"")} | H8: {=IF(MONTH($J$5-$J$6+((ROW()-8)/2)*7+(COLUMN()-2))=$J$4,IFERROR(_xlfn.TEXTJOIN(CHAR(10),TRUE,IF((TransactionsLog[Type]="Bill")*(TransactionsLog[Date]=($J$5-$J$6+((ROW()-8)/2)*7+(COLUMN()-2))),"☐ "&TransactionsLog[Category]&" "&TEXT(TransactionsLog[Amount],"$0"),"")),""),"")}
B9: =IF(MONTH(($J$5-$J$6+7))=$J$4,DAY(($J$5-$J$6+7)),"") | C9: =IF(MONTH(($J$5-$J$6+8))=$J$4,DAY(($J$5-$J$6+8)),"") | D9: =IF(MONTH(($J$5-$J$6+9))=$J$4,DAY(($J$5-$J$6+9)),"") | E9: =IF(MONTH(($J$5-$J$6+10))=$J$4,DAY(($J$5-$J$6+10)),"") | F9: =IF(MONTH(($J$5-$J$6+11))=$J$4,DAY(($J$5-$J$6+11)),"") | G9: =IF(MONTH(($J$5-$J$6+12))=$J$4,DAY(($J$5-$J$6+12)),"") | H9: =IF(MONTH(($J$5-$J$6+13))=$J$4,DAY(($J$5-$J$6+13)),"")
B10: {=IF(MONTH($J$5-$J$6+((ROW()-8)/2)*7+(COLUMN()-2))=$J$4,IFERROR(_xlfn.TEXTJOIN(CHAR(10),TRUE,IF((TransactionsLog[Type]="Bill")*(TransactionsLog[Date]=($J$5-$J$6+((ROW()-8)/2)*7+(COLUMN()-2))),"☐ "&TransactionsLog[Category]&" "&TEXT(TransactionsLog[Amount],"$0"),"")),""),"")} | C10: {=IF(MONTH($J$5-$J$6+((ROW()-8)/2)*7+(COLUMN()-2))=$J$4,IFERROR(_xlfn.TEXTJOIN(CHAR(10),TRUE,IF((TransactionsLog[Type]="Bill")*(TransactionsLog[Date]=($J$5-$J$6+((ROW()-8)/2)*7+(COLUMN()-2))),"☐ "&TransactionsLog[Category]&" "&TEXT(TransactionsLog[Amount],"$0"),"")),""),"")} | D10: {=IF(MONTH($J$5-$J$6+((ROW()-8)/2)*7+(COLUMN()-2))=$J$4,IFERROR(_xlfn.TEXTJOIN(CHAR(10),TRUE,IF((TransactionsLog[Type]="Bill")*(TransactionsLog[Date]=($J$5-$J$6+((ROW()-8)/2)*7+(COLUMN()-2))),"☐ "&TransactionsLog[Category]&" "&TEXT(TransactionsLog[Amount],"$0"),"")),""),"")} | E10: {=IF(MONTH($J$5-$J$6+((ROW()-8)/2)*7+(COLUMN()-2))=$J$4,IFERROR(_xlfn.TEXTJOIN(CHAR(10),TRUE,IF((TransactionsLog[Type]="Bill")*(TransactionsLog[Date]=($J$5-$J$6+((ROW()-8)/2)*7+(COLUMN()-2))),"☐ "&TransactionsLog[Category]&" "&TEXT(TransactionsLog[Amount],"$0"),"")),""),"")} | F10: {=IF(MONTH($J$5-$J$6+((ROW()-8)/2)*7+(COLUMN()-2))=$J$4,IFERROR(_xlfn.TEXTJOIN(CHAR(10),TRUE,IF((TransactionsLog[Type]="Bill")*(TransactionsLog[Date]=($J$5-$J$6+((ROW()-8)/2)*7+(COLUMN()-2))),"☐ "&TransactionsLog[Category]&" "&TEXT(TransactionsLog[Amount],"$0"),"")),""),"")} | G10: {=IF(MONTH($J$5-$J$6+((ROW()-8)/2)*7+(COLUMN()-2))=$J$4,IFERROR(_xlfn.TEXTJOIN(CHAR(10),TRUE,IF((TransactionsLog[Type]="Bill")*(TransactionsLog[Date]=($J$5-$J$6+((ROW()-8)/2)*7+(COLUMN()-2))),"☐ "&TransactionsLog[Category]&" "&TEXT(TransactionsLog[Amount],"$0"),"")),""),"")} | H10: {=IF(MONTH($J$5-$J$6+((ROW()-8)/2)*7+(COLUMN()-2))=$J$4,IFERROR(_xlfn.TEXTJOIN(CHAR(10),TRUE,IF((TransactionsLog[Type]="Bill")*(TransactionsLog[Date]=($J$5-$J$6+((ROW()-8)/2)*7+(COLUMN()-2))),"☐ "&TransactionsLog[Category]&" "&TEXT(TransactionsLog[Amount],"$0"),"")),""),"")}
B11: =IF(MONTH(($J$5-$J$6+14))=$J$4,DAY(($J$5-$J$6+14)),"") | C11: =IF(MONTH(($J$5-$J$6+15))=$J$4,DAY(($J$5-$J$6+15)),"") | D11: =IF(MONTH(($J$5-$J$6+16))=$J$4,DAY(($J$5-$J$6+16)),"") | E11: =IF(MONTH(($J$5-$J$6+17))=$J$4,DAY(($J$5-$J$6+17)),"") | F11: =IF(MONTH(($J$5-$J$6+18))=$J$4,DAY(($J$5-$J$6+18)),"") | G11: =IF(MONTH(($J$5-$J$6+19))=$J$4,DAY(($J$5-$J$6+19)),"") | H11: =IF(MONTH(($J$5-$J$6+20))=$J$4,DAY(($J$5-$J$6+20)),"")
B12: {=IF(MONTH($J$5-$J$6+((ROW()-8)/2)*7+(COLUMN()-2))=$J$4,IFERROR(_xlfn.TEXTJOIN(CHAR(10),TRUE,IF((TransactionsLog[Type]="Bill")*(TransactionsLog[Date]=($J$5-$J$6+((ROW()-8)/2)*7+(COLUMN()-2))),"☐ "&TransactionsLog[Category]&" "&TEXT(TransactionsLog[Amount],"$0"),"")),""),"")} | C12: {=IF(MONTH($J$5-$J$6+((ROW()-8)/2)*7+(COLUMN()-2))=$J$4,IFERROR(_xlfn.TEXTJOIN(CHAR(10),TRUE,IF((TransactionsLog[Type]="Bill")*(TransactionsLog[Date]=($J$5-$J$6+((ROW()-8)/2)*7+(COLUMN()-2))),"☐ "&TransactionsLog[Category]&" "&TEXT(TransactionsLog[Amount],"$0"),"")),""),"")} | D12: {=IF(MONTH($J$5-$J$6+((ROW()-8)/2)*7+(COLUMN()-2))=$J$4,IFERROR(_xlfn.TEXTJOIN(CHAR(10),TRUE,IF((TransactionsLog[Type]="Bill")*(TransactionsLog[Date]=($J$5-$J$6+((ROW()-8)/2)*7+(COLUMN()-2))),"☐ "&TransactionsLog[Category]&" "&TEXT(TransactionsLog[Amount],"$0"),"")),""),"")} | E12: {=IF(MONTH($J$5-$J$6+((ROW()-8)/2)*7+(COLUMN()-2))=$J$4,IFERROR(_xlfn.TEXTJOIN(CHAR(10),TRUE,IF((TransactionsLog[Type]="Bill")*(TransactionsLog[Date]=($J$5-$J$6+((ROW()-8)/2)*7+(COLUMN()-2))),"☐ "&TransactionsLog[Category]&" "&TEXT(TransactionsLog[Amount],"$0"),"")),""),"")} | F12: {=IF(MONTH($J$5-$J$6+((ROW()-8)/2)*7+(COLUMN()-2))=$J$4,IFERROR(_xlfn.TEXTJOIN(CHAR(10),TRUE,IF((TransactionsLog[Type]="Bill")*(TransactionsLog[Date]=($J$5-$J$6+((ROW()-8)/2)*7+(COLUMN()-2))),"☐ "&TransactionsLog[Category]&" "&TEXT(TransactionsLog[Amount],"$0"),"")),""),"")} | G12: {=IF(MONTH($J$5-$J$6+((ROW()-8)/2)*7+(COLUMN()-2))=$J$4,IFERROR(_xlfn.TEXTJOIN(CHAR(10),TRUE,IF((TransactionsLog[Type]="Bill")*(TransactionsLog[Date]=($J$5-$J$6+((ROW()-8)/2)*7+(COLUMN()-2))),"☐ "&TransactionsLog[Category]&" "&TEXT(TransactionsLog[Amount],"$0"),"")),""),"")} | H12: {=IF(MONTH($J$5-$J$6+((ROW()-8)/2)*7+(COLUMN()-2))=$J$4,IFERROR(_xlfn.TEXTJOIN(CHAR(10),TRUE,IF((TransactionsLog[Type]="Bill")*(TransactionsLog[Date]=($J$5-$J$6+((ROW()-8)/2)*7+(COLUMN()-2))),"☐ "&TransactionsLog[Category]&" "&TEXT(TransactionsLog[Amount],"$0"),"")),""),"")}
B13: =IF(MONTH(($J$5-$J$6+21))=$J$4,DAY(($J$5-$J$6+21)),"") | C13: =IF(MONTH(($J$5-$J$6+22))=$J$4,DAY(($J$5-$J$6+22)),"") | D13: =IF(MONTH(($J$5-$J$6+23))=$J$4,DAY(($J$5-$J$6+23)),"") | E13: =IF(MONTH(($J$5-$J$6+24))=$J$4,DAY(($J$5-$J$6+24)),"") | F13: =IF(MONTH(($J$5-$J$6+25))=$J$4,DAY(($J$5-$J$6+25)),"") | G13: =IF(MONTH(($J$5-$J$6+26))=$J$4,DAY(($J$5-$J$6+26)),"") | H13: =IF(MONTH(($J$5-$J$6+27))=$J$4,DAY(($J$5-$J$6+27)),"")
B14: {=IF(MONTH($J$5-$J$6+((ROW()-8)/2)*7+(COLUMN()-2))=$J$4,IFERROR(_xlfn.TEXTJOIN(CHAR(10),TRUE,IF((TransactionsLog[Type]="Bill")*(TransactionsLog[Date]=($J$5-$J$6+((ROW()-8)/2)*7+(COLUMN()-2))),"☐ "&TransactionsLog[Category]&" "&TEXT(TransactionsLog[Amount],"$0"),"")),""),"")} | C14: {=IF(MONTH($J$5-$J$6+((ROW()-8)/2)*7+(COLUMN()-2))=$J$4,IFERROR(_xlfn.TEXTJOIN(CHAR(10),TRUE,IF((TransactionsLog[Type]="Bill")*(TransactionsLog[Date]=($J$5-$J$6+((ROW()-8)/2)*7+(COLUMN()-2))),"☐ "&TransactionsLog[Category]&" "&TEXT(TransactionsLog[Amount],"$0"),"")),""),"")} | D14: {=IF(MONTH($J$5-$J$6+((ROW()-8)/2)*7+(COLUMN()-2))=$J$4,IFERROR(_xlfn.TEXTJOIN(CHAR(10),TRUE,IF((TransactionsLog[Type]="Bill")*(TransactionsLog[Date]=($J$5-$J$6+((ROW()-8)/2)*7+(COLUMN()-2))),"☐ "&TransactionsLog[Category]&" "&TEXT(TransactionsLog[Amount],"$0"),"")),""),"")} | E14: {=IF(MONTH($J$5-$J$6+((ROW()-8)/2)*7+(COLUMN()-2))=$J$4,IFERROR(_xlfn.TEXTJOIN(CHAR(10),TRUE,IF((TransactionsLog[Type]="Bill")*(TransactionsLog[Date]=($J$5-$J$6+((ROW()-8)/2)*7+(COLUMN()-2))),"☐ "&TransactionsLog[Category]&" "&TEXT(TransactionsLog[Amount],"$0"),"")),""),"")} | F14: {=IF(MONTH($J$5-$J$6+((ROW()-8)/2)*7+(COLUMN()-2))=$J$4,IFERROR(_xlfn.TEXTJOIN(CHAR(10),TRUE,IF((TransactionsLog[Type]="Bill")*(TransactionsLog[Date]=($J$5-$J$6+((ROW()-8)/2)*7+(COLUMN()-2))),"☐ "&TransactionsLog[Category]&" "&TEXT(TransactionsLog[Amount],"$0"),"")),""),"")} | G14: {=IF(MONTH($J$5-$J$6+((ROW()-8)/2)*7+(COLUMN()-2))=$J$4,IFERROR(_xlfn.TEXTJOIN(CHAR(10),TRUE,IF((TransactionsLog[Type]="Bill")*(TransactionsLog[Date]=($J$5-$J$6+((ROW()-8)/2)*7+(COLUMN()-2))),"☐ "&TransactionsLog[Category]&" "&TEXT(TransactionsLog[Amount],"$0"),"")),""),"")} | H14: {=IF(MONTH($J$5-$J$6+((ROW()-8)/2)*7+(COLUMN()-2))=$J$4,IFERROR(_xlfn.TEXTJOIN(CHAR(10),TRUE,IF((TransactionsLog[Type]="Bill")*(TransactionsLog[Date]=($J$5-$J$6+((ROW()-8)/2)*7+(COLUMN()-2))),"☐ "&TransactionsLog[Category]&" "&TEXT(TransactionsLog[Amount],"$0"),"")),""),"")}
B15: =IF(MONTH(($J$5-$J$6+28))=$J$4,DAY(($J$5-$J$6+28)),"") | C15: =IF(MONTH(($J$5-$J$6+29))=$J$4,DAY(($J$5-$J$6+29)),"") | D15: =IF(MONTH(($J$5-$J$6+30))=$J$4,DAY(($J$5-$J$6+30)),"") | E15: =IF(MONTH(($J$5-$J$6+31))=$J$4,DAY(($J$5-$J$6+31)),"") | F15: =IF(MONTH(($J$5-$J$6+32))=$J$4,DAY(($J$5-$J$6+32)),"") | G15: =IF(MONTH(($J$5-$J$6+33))=$J$4,DAY(($J$5-$J$6+33)),"") | H15: =IF(MONTH(($J$5-$J$6+34))=$J$4,DAY(($J$5-$J$6+34)),"")
B16: {=IF(MONTH($J$5-$J$6+((ROW()-8)/2)*7+(COLUMN()-2))=$J$4,IFERROR(_xlfn.TEXTJOIN(CHAR(10),TRUE,IF((TransactionsLog[Type]="Bill")*(TransactionsLog[Date]=($J$5-$J$6+((ROW()-8)/2)*7+(COLUMN()-2))),"☐ "&TransactionsLog[Category]&" "&TEXT(TransactionsLog[Amount],"$0"),"")),""),"")} | C16: {=IF(MONTH($J$5-$J$6+((ROW()-8)/2)*7+(COLUMN()-2))=$J$4,IFERROR(_xlfn.TEXTJOIN(CHAR(10),TRUE,IF((TransactionsLog[Type]="Bill")*(TransactionsLog[Date]=($J$5-$J$6+((ROW()-8)/2)*7+(COLUMN()-2))),"☐ "&TransactionsLog[Category]&" "&TEXT(TransactionsLog[Amount],"$0"),"")),""),"")} | D16: {=IF(MONTH($J$5-$J$6+((ROW()-8)/2)*7+(COLUMN()-2))=$J$4,IFERROR(_xlfn.TEXTJOIN(CHAR(10),TRUE,IF((TransactionsLog[Type]="Bill")*(TransactionsLog[Date]=($J$5-$J$6+((ROW()-8)/2)*7+(COLUMN()-2))),"☐ "&TransactionsLog[Category]&" "&TEXT(TransactionsLog[Amount],"$0"),"")),""),"")} | E16: {=IF(MONTH($J$5-$J$6+((ROW()-8)/2)*7+(COLUMN()-2))=$J$4,IFERROR(_xlfn.TEXTJOIN(CHAR(10),TRUE,IF((TransactionsLog[Type]="Bill")*(TransactionsLog[Date]=($J$5-$J$6+((ROW()-8)/2)*7+(COLUMN()-2))),"☐ "&TransactionsLog[Category]&" "&TEXT(TransactionsLog[Amount],"$0"),"")),""),"")} | F16: {=IF(MONTH($J$5-$J$6+((ROW()-8)/2)*7+(COLUMN()-2))=$J$4,IFERROR(_xlfn.TEXTJOIN(CHAR(10),TRUE,IF((TransactionsLog[Type]="Bill")*(TransactionsLog[Date]=($J$5-$J$6+((ROW()-8)/2)*7+(COLUMN()-2))),"☐ "&TransactionsLog[Category]&" "&TEXT(TransactionsLog[Amount],"$0"),"")),""),"")} | G16: {=IF(MONTH($J$5-$J$6+((ROW()-8)/2)*7+(COLUMN()-2))=$J$4,IFERROR(_xlfn.TEXTJOIN(CHAR(10),TRUE,IF((TransactionsLog[Type]="Bill")*(TransactionsLog[Date]=($J$5-$J$6+((ROW()-8)/2)*7+(COLUMN()-2))),"☐ "&TransactionsLog[Category]&" "&TEXT(TransactionsLog[Amount],"$0"),"")),""),"")} | H16: {=IF(MONTH($J$5-$J$6+((ROW()-8)/2)*7+(COLUMN()-2))=$J$4,IFERROR(_xlfn.TEXTJOIN(CHAR(10),TRUE,IF((TransactionsLog[Type]="Bill")*(TransactionsLog[Date]=($J$5-$J$6+((ROW()-8)/2)*7+(COLUMN()-2))),"☐ "&TransactionsLog[Category]&" "&TEXT(TransactionsLog[Amount],"$0"),"")),""),"")}
B17: =IF(MONTH(($J$5-$J$6+35))=$J$4,DAY(($J$5-$J$6+35)),"") | C17: =IF(MONTH(($J$5-$J$6+36))=$J$4,DAY(($J$5-$J$6+36)),"") | D17: =IF(MONTH(($J$5-$J$6+37))=$J$4,DAY(($J$5-$J$6+37)),"") | E17: =IF(MONTH(($J$5-$J$6+38))=$J$4,DAY(($J$5-$J$6+38)),"") | F17: =IF(MONTH(($J$5-$J$6+39))=$J$4,DAY(($J$5-$J$6+39)),"") | G17: =IF(MONTH(($J$5-$J$6+40))=$J$4,DAY(($J$5-$J$6+40)),"") | H17: =IF(MONTH(($J$5-$J$6+41))=$J$4,DAY(($J$5-$J$6+41)),"")
B18: {=IF(MONTH($J$5-$J$6+((ROW()-8)/2)*7+(COLUMN()-2))=$J$4,IFERROR(_xlfn.TEXTJOIN(CHAR(10),TRUE,IF((TransactionsLog[Type]="Bill")*(TransactionsLog[Date]=($J$5-$J$6+((ROW()-8)/2)*7+(COLUMN()-2))),"☐ "&TransactionsLog[Category]&" "&TEXT(TransactionsLog[Amount],"$0"),"")),""),"")} | C18: {=IF(MONTH($J$5-$J$6+((ROW()-8)/2)*7+(COLUMN()-2))=$J$4,IFERROR(_xlfn.TEXTJOIN(CHAR(10),TRUE,IF((TransactionsLog[Type]="Bill")*(TransactionsLog[Date]=($J$5-$J$6+((ROW()-8)/2)*7+(COLUMN()-2))),"☐ "&TransactionsLog[Category]&" "&TEXT(TransactionsLog[Amount],"$0"),"")),""),"")} | D18: {=IF(MONTH($J$5-$J$6+((ROW()-8)/2)*7+(COLUMN()-2))=$J$4,IFERROR(_xlfn.TEXTJOIN(CHAR(10),TRUE,IF((TransactionsLog[Type]="Bill")*(TransactionsLog[Date]=($J$5-$J$6+((ROW()-8)/2)*7+(COLUMN()-2))),"☐ "&TransactionsLog[Category]&" "&TEXT(TransactionsLog[Amount],"$0"),"")),""),"")} | E18: {=IF(MONTH($J$5-$J$6+((ROW()-8)/2)*7+(COLUMN()-2))=$J$4,IFERROR(_xlfn.TEXTJOIN(CHAR(10),TRUE,IF((TransactionsLog[Type]="Bill")*(TransactionsLog[Date]=($J$5-$J$6+((ROW()-8)/2)*7+(COLUMN()-2))),"☐ "&TransactionsLog[Category]&" "&TEXT(TransactionsLog[Amount],"$0"),"")),""),"")} | F18: {=IF(MONTH($J$5-$J$6+((ROW()-8)/2)*7+(COLUMN()-2))=$J$4,IFERROR(_xlfn.TEXTJOIN(CHAR(10),TRUE,IF((TransactionsLog[Type]="Bill")*(TransactionsLog[Date]=($J$5-$J$6+((ROW()-8)/2)*7+(COLUMN()-2))),"☐ "&TransactionsLog[Category]&" "&TEXT(TransactionsLog[Amount],"$0"),"")),""),"")} | G18: {=IF(MONTH($J$5-$J$6+((ROW()-8)/2)*7+(COLUMN()-2))=$J$4,IFERROR(_xlfn.TEXTJOIN(CHAR(10),TRUE,IF((TransactionsLog[Type]="Bill")*(TransactionsLog[Date]=($J$5-$J$6+((ROW()-8)/2)*7+(COLUMN()-2))),"☐ "&TransactionsLog[Category]&" "&TEXT(TransactionsLog[Amount],"$0"),"")),""),"")} | H18: {=IF(MONTH($J$5-$J$6+((ROW()-8)/2)*7+(COLUMN()-2))=$J$4,IFERROR(_xlfn.TEXTJOIN(CHAR(10),TRUE,IF((TransactionsLog[Type]="Bill")*(TransactionsLog[Date]=($J$5-$J$6+((ROW()-8)/2)*7+(COLUMN()-2))),"☐ "&TransactionsLog[Category]&" "&TEXT(TransactionsLog[Amount],"$0"),"")),""),"")}

Sheet Savings & Debt Goal Tracker
A1: Savings & Debt Goal Tracker
A2: Set up to 8 savings goals and 8 debt payoff goals below. Log a contribution or payment at the bottom any time, and your progress updates automatically.
A4: Savings Goals
A5: Goal Name | B5: Goal Amount | C5: Starting Point | D5: Logged Contributions | E5: Total Saved | F5: Left to Save | G5: Progress % | J5: Goal List (auto)
A6: Emergency Fund | C6: 0 | D6: =IFERROR(SUMIF(GoalLog[Goal Name],$A6,GoalLog[Amount]),0) | E6: =C6+D6 | F6: =B6-E6 | G6: =IFERROR(E6/B6,0) | J6: =A6
A7: Vacation Fund | B7: 0 | C7: 0 | D7: =IFERROR(SUMIF(GoalLog[Goal Name],$A7,GoalLog[Amount]),0) | E7: =C7+D7 | F7: =B7-E7 | G7: =IFERROR(E7/B7,0) | J7: =A7
A8: Holiday Fund | B8: 0 | C8: 0 | D8: =IFERROR(SUMIF(GoalLog[Goal Name],$A8,GoalLog[Amount]),0) | E8: =C8+D8 | F8: =B8-E8 | G8: =IFERROR(E8/B8,0) | J8: =A8
A9: Retirement Savings | B9: 0 | C9: 0 | D9: =IFERROR(SUMIF(GoalLog[Goal Name],$A9,GoalLog[Amount]),0) | E9: =C9+D9 | F9: =B9-E9 | G9: =IFERROR(E9/B9,0) | J9: =A9
A10: General Savings | B10: 0 | C10: 0 | D10: =IFERROR(SUMIF(GoalLog[Goal Name],$A10,GoalLog[Amount]),0) | E10: =C10+D10 | F10: =B10-E10 | G10: =IFERROR(E10/B10,0) | J10: =A10
B11: 0 | C11: 0 | D11: =IFERROR(SUMIF(GoalLog[Goal Name],$A11,GoalLog[Amount]),0) | E11: =C11+D11 | F11: =B11-E11 | G11: =IFERROR(E11/B11,0) | J11: =A11
B12: 0 | C12: 0 | D12: =IFERROR(SUMIF(GoalLog[Goal Name],$A12,GoalLog[Amount]),0) | E12: =C12+D12 | F12: =B12-E12 | G12: =IFERROR(E12/B12,0) | J12: =A12
B13: 0 | C13: 0 | D13: =IFERROR(SUMIF(GoalLog[Goal Name],$A13,GoalLog[Amount]),0) | E13: =C13+D13 | F13: =B13-E13 | G13: =IFERROR(E13/B13,0) | J13: =A13
J14: =A17
A15: Debt Payoff Goals | J15: =A18
A16: Goal Name | B16: Starting Balance | C16: Already Paid | D16: Logged Payments | E16: Total Paid | F16: Remaining Balance | G16: Progress % | J16: =A19
A17: Credit Card | D17: =IFERROR(SUMIF(GoalLog[Goal Name],$A17,GoalLog[Amount]),0) | E17: =C17+D17 | F17: =B17-E17 | G17: =IFERROR(E17/B17,0) | J17: =A20
A18: Student Loan | B18: 0 | C18: 0 | D18: =IFERROR(SUMIF(GoalLog[Goal Name],$A18,GoalLog[Amount]),0) | E18: =C18+D18 | F18: =B18-E18 | G18: =IFERROR(E18/B18,0) | J18: =A21
A19: Personal Loan | B19: 0 | C19: 0 | D19: =IFERROR(SUMIF(GoalLog[Goal Name],$A19,GoalLog[Amount]),0) | E19: =C19+D19 | F19: =B19-E19 | G19: =IFERROR(E19/B19,0) | J19: =A22
A20: Medical Debt | B20: 0 | C20: 0 | D20: =IFERROR(SUMIF(GoalLog[Goal Name],$A20,GoalLog[Amount]),0) | E20: =C20+D20 | F20: =B20-E20 | G20: =IFERROR(E20/B20,0) | J20: =A23
B21: 0 | C21: 0 | D21: =IFERROR(SUMIF(GoalLog[Goal Name],$A21,GoalLog[Amount]),0) | E21: =C21+D21 | F21: =B21-E21 | G21: =IFERROR(E21/B21,0) | J21: =A24
B22: 0 | C22: 0 | D22: =IFERROR(SUMIF(GoalLog[Goal Name],$A22,GoalLog[Amount]),0) | E22: =C22+D22 | F22: =B22-E22 | G22: =IFERROR(E22/B22,0)
B23: 0 | C23: 0 | D23: =IFERROR(SUMIF(GoalLog[Goal Name],$A23,GoalLog[Amount]),0) | E23: =C23+D23 | F23: =B23-E23 | G23: =IFERROR(E23/B23,0)
B24: 0 | C24: 0 | D24: =IFERROR(SUMIF(GoalLog[Goal Name],$A24,GoalLog[Amount]),0) | E24: =C24+D24 | F24: =B24-E24 | G24: =IFERROR(E24/B24,0)
A27: Goal Contributions Log
A28: Log a contribution toward a savings goal or a payment toward a debt any time, pick the goal from the dropdown and the totals above update automatically.
A30: Date | B30: Goal Name | C30: Amount | D30: Notes

Sheet Subscription Tracker
A1: Subscription Tracker
A2: See what you're really paying for streaming, memberships, and software each month. The total below flows into your Bill Tracker automatically. No need to log these in the Transactions Log too.
B4: Monthly Subscriptions Total | C4: =SUM(SubscriptionTracker[Monthly Price]) | D4: Annual Subscriptions Total | E4: =SUM(SubscriptionTracker[Annual Price])
K5: By Category | L5: Monthly
A6: Subscription | B6: Category | C6: Billing Frequency | D6: Auto-Renew | E6: Debit Day | F6: Price | G6: Monthly Price | H6: Annual Price | I6: Notes | K6: =Settings!T3 | L6: =SUMIF(SubscriptionTracker[Category],$K6,SubscriptionTracker[Monthly Price])
G7: =IFERROR(IF(SubscriptionTracker[[#This Row],[Billing Frequency]]="Monthly",SubscriptionTracker[[#This Row],[Price]],IF(SubscriptionTracker[[#This Row],[Billing Frequency]]="Quarterly",SubscriptionTracker[[#This Row],[Price]]/3,IF(SubscriptionTracker[[#This Row],[Billing Frequency]]="Annually",SubscriptionTracker[[#This Row],[Price]]/12,""))),"") | H7: =IFERROR(SubscriptionTracker[[#This Row],[Monthly Price]]*12,"") | K7: =Settings!T4 | L7: =SUMIF(SubscriptionTracker[Category],$K7,SubscriptionTracker[Monthly Price])
G8: =IFERROR(IF(SubscriptionTracker[[#This Row],[Billing Frequency]]="Monthly",SubscriptionTracker[[#This Row],[Price]],IF(SubscriptionTracker[[#This Row],[Billing Frequency]]="Quarterly",SubscriptionTracker[[#This Row],[Price]]/3,IF(SubscriptionTracker[[#This Row],[Billing Frequency]]="Annually",SubscriptionTracker[[#This Row],[Price]]/12,""))),"") | H8: =IFERROR(SubscriptionTracker[[#This Row],[Monthly Price]]*12,"") | K8: =Settings!T5 | L8: =SUMIF(SubscriptionTracker[Category],$K8,SubscriptionTracker[Monthly Price])
G9: =IFERROR(IF(SubscriptionTracker[[#This Row],[Billing Frequency]]="Monthly",SubscriptionTracker[[#This Row],[Price]],IF(SubscriptionTracker[[#This Row],[Billing Frequency]]="Quarterly",SubscriptionTracker[[#This Row],[Price]]/3,IF(SubscriptionTracker[[#This Row],[Billing Frequency]]="Annually",SubscriptionTracker[[#This Row],[Price]]/12,""))),"") | H9: =IFERROR(SubscriptionTracker[[#This Row],[Monthly Price]]*12,"") | K9: =Settings!T6 | L9: =SUMIF(SubscriptionTracker[Category],$K9,SubscriptionTracker[Monthly Price])
G10: =IFERROR(IF(SubscriptionTracker[[#This Row],[Billing Frequency]]="Monthly",SubscriptionTracker[[#This Row],[Price]],IF(SubscriptionTracker[[#This Row],[Billing Frequency]]="Quarterly",SubscriptionTracker[[#This Row],[Price]]/3,IF(SubscriptionTracker[[#This Row],[Billing Frequency]]="Annually",SubscriptionTracker[[#This Row],[Price]]/12,""))),"") | H10: =IFERROR(SubscriptionTracker[[#This Row],[Monthly Price]]*12,"") | K10: =Settings!T7 | L10: =SUMIF(SubscriptionTracker[Category],$K10,SubscriptionTracker[Monthly Price])
G11: =IFERROR(IF(SubscriptionTracker[[#This Row],[Billing Frequency]]="Monthly",SubscriptionTracker[[#This Row],[Price]],IF(SubscriptionTracker[[#This Row],[Billing Frequency]]="Quarterly",SubscriptionTracker[[#This Row],[Price]]/3,IF(SubscriptionTracker[[#This Row],[Billing Frequency]]="Annually",SubscriptionTracker[[#This Row],[Price]]/12,""))),"") | H11: =IFERROR(SubscriptionTracker[[#This Row],[Monthly Price]]*12,"") | K11: =Settings!T8 | L11: =SUMIF(SubscriptionTracker[Category],$K11,SubscriptionTracker[Monthly Price])
G12: =IFERROR(IF(SubscriptionTracker[[#This Row],[Billing Frequency]]="Monthly",SubscriptionTracker[[#This Row],[Price]],IF(SubscriptionTracker[[#This Row],[Billing Frequency]]="Quarterly",SubscriptionTracker[[#This Row],[Price]]/3,IF(SubscriptionTracker[[#This Row],[Billing Frequency]]="Annually",SubscriptionTracker[[#This Row],[Price]]/12,""))),"") | H12: =IFERROR(SubscriptionTracker[[#This Row],[Monthly Price]]*12,"") | K12: =Settings!T9 | L12: =SUMIF(SubscriptionTracker[Category],$K12,SubscriptionTracker[Monthly Price])
G13: =IFERROR(IF(SubscriptionTracker[[#This Row],[Billing Frequency]]="Monthly",SubscriptionTracker[[#This Row],[Price]],IF(SubscriptionTracker[[#This Row],[Billing Frequency]]="Quarterly",SubscriptionTracker[[#This Row],[Price]]/3,IF(SubscriptionTracker[[#This Row],[Billing Frequency]]="Annually",SubscriptionTracker[[#This Row],[Price]]/12,""))),"") | H13: =IFERROR(SubscriptionTracker[[#This Row],[Monthly Price]]*12,"") | K13: =Settings!T10 | L13: =SUMIF(SubscriptionTracker[Category],$K13,SubscriptionTracker[Monthly Price])
G14: =IFERROR(IF(SubscriptionTracker[[#This Row],[Billing Frequency]]="Monthly",SubscriptionTracker[[#This Row],[Price]],IF(SubscriptionTracker[[#This Row],[Billing Frequency]]="Quarterly",SubscriptionTracker[[#This Row],[Price]]/3,IF(SubscriptionTracker[[#This Row],[Billing Frequency]]="Annually",SubscriptionTracker[[#This Row],[Price]]/12,""))),"") | H14: =IFERROR(SubscriptionTracker[[#This Row],[Monthly Price]]*12,"")
G15: =IFERROR(IF(SubscriptionTracker[[#This Row],[Billing Frequency]]="Monthly",SubscriptionTracker[[#This Row],[Price]],IF(SubscriptionTracker[[#This Row],[Billing Frequency]]="Quarterly",SubscriptionTracker[[#This Row],[Price]]/3,IF(SubscriptionTracker[[#This Row],[Billing Frequency]]="Annually",SubscriptionTracker[[#This Row],[Price]]/12,""))),"") | H15: =IFERROR(SubscriptionTracker[[#This Row],[Monthly Price]]*12,"")
G16: =IFERROR(IF(SubscriptionTracker[[#This Row],[Billing Frequency]]="Monthly",SubscriptionTracker[[#This Row],[Price]],IF(SubscriptionTracker[[#This Row],[Billing Frequency]]="Quarterly",SubscriptionTracker[[#This Row],[Price]]/3,IF(SubscriptionTracker[[#This Row],[Billing Frequency]]="Annually",SubscriptionTracker[[#This Row],[Price]]/12,""))),"") | H16: =IFERROR(SubscriptionTracker[[#This Row],[Monthly Price]]*12,"")
G17: =IFERROR(IF(SubscriptionTracker[[#This Row],[Billing Frequency]]="Monthly",SubscriptionTracker[[#This Row],[Price]],IF(SubscriptionTracker[[#This Row],[Billing Frequency]]="Quarterly",SubscriptionTracker[[#This Row],[Price]]/3,IF(SubscriptionTracker[[#This Row],[Billing Frequency]]="Annually",SubscriptionTracker[[#This Row],[Price]]/12,""))),"") | H17: =IFERROR(SubscriptionTracker[[#This Row],[Monthly Price]]*12,"")
G18: =IFERROR(IF(SubscriptionTracker[[#This Row],[Billing Frequency]]="Monthly",SubscriptionTracker[[#This Row],[Price]],IF(SubscriptionTracker[[#This Row],[Billing Frequency]]="Quarterly",SubscriptionTracker[[#This Row],[Price]]/3,IF(SubscriptionTracker[[#This Row],[Billing Frequency]]="Annually",SubscriptionTracker[[#This Row],[Price]]/12,""))),"") | H18: =IFERROR(SubscriptionTracker[[#This Row],[Monthly Price]]*12,"")
G19: =IFERROR(IF(SubscriptionTracker[[#This Row],[Billing Frequency]]="Monthly",SubscriptionTracker[[#This Row],[Price]],IF(SubscriptionTracker[[#This Row],[Billing Frequency]]="Quarterly",SubscriptionTracker[[#This Row],[Price]]/3,IF(SubscriptionTracker[[#This Row],[Billing Frequency]]="Annually",SubscriptionTracker[[#This Row],[Price]]/12,""))),"") | H19: =IFERROR(SubscriptionTracker[[#This Row],[Monthly Price]]*12,"")
G20: =IFERROR(IF(SubscriptionTracker[[#This Row],[Billing Frequency]]="Monthly",SubscriptionTracker[[#This Row],[Price]],IF(SubscriptionTracker[[#This Row],[Billing Frequency]]="Quarterly",SubscriptionTracker[[#This Row],[Price]]/3,IF(SubscriptionTracker[[#This Row],[Billing Frequency]]="Annually",SubscriptionTracker[[#This Row],[Price]]/12,""))),"") | H20: =IFERROR(SubscriptionTracker[[#This Row],[Monthly Price]]*12,"")
G21: =IFERROR(IF(SubscriptionTracker[[#This Row],[Billing Frequency]]="Monthly",SubscriptionTracker[[#This Row],[Price]],IF(SubscriptionTracker[[#This Row],[Billing Frequency]]="Quarterly",SubscriptionTracker[[#This Row],[Price]]/3,IF(SubscriptionTracker[[#This Row],[Billing Frequency]]="Annually",SubscriptionTracker[[#This Row],[Price]]/12,""))),"") | H21: =IFERROR(SubscriptionTracker[[#This Row],[Monthly Price]]*12,"")
G22: =IFERROR(IF(SubscriptionTracker[[#This Row],[Billing Frequency]]="Monthly",SubscriptionTracker[[#This Row],[Price]],IF(SubscriptionTracker[[#This Row],[Billing Frequency]]="Quarterly",SubscriptionTracker[[#This Row],[Price]]/3,IF(SubscriptionTracker[[#This Row],[Billing Frequency]]="Annually",SubscriptionTracker[[#This Row],[Price]]/12,""))),"") | H22: =IFERROR(SubscriptionTracker[[#This Row],[Monthly Price]]*12,"")
G23: =IFERROR(IF(SubscriptionTracker[[#This Row],[Billing Frequency]]="Monthly",SubscriptionTracker[[#This Row],[Price]],IF(SubscriptionTracker[[#This Row],[Billing Frequency]]="Quarterly",SubscriptionTracker[[#This Row],[Price]]/3,IF(SubscriptionTracker[[#This Row],[Billing Frequency]]="Annually",SubscriptionTracker[[#This Row],[Price]]/12,""))),"") | H23: =IFERROR(SubscriptionTracker[[#This Row],[Monthly Price]]*12,"")
G24: =IFERROR(IF(SubscriptionTracker[[#This Row],[Billing Frequency]]="Monthly",SubscriptionTracker[[#This Row],[Price]],IF(SubscriptionTracker[[#This Row],[Billing Frequency]]="Quarterly",SubscriptionTracker[[#This Row],[Price]]/3,IF(SubscriptionTracker[[#This Row],[Billing Frequency]]="Annually",SubscriptionTracker[[#This Row],[Price]]/12,""))),"") | H24: =IFERROR(SubscriptionTracker[[#This Row],[Monthly Price]]*12,"")
G25: =IFERROR(IF(SubscriptionTracker[[#This Row],[Billing Frequency]]="Monthly",SubscriptionTracker[[#This Row],[Price]],IF(SubscriptionTracker[[#This Row],[Billing Frequency]]="Quarterly",SubscriptionTracker[[#This Row],[Price]]/3,IF(SubscriptionTracker[[#This Row],[Billing Frequency]]="Annually",SubscriptionTracker[[#This Row],[Price]]/12,""))),"") | H25: =IFERROR(SubscriptionTracker[[#This Row],[Monthly Price]]*12,"")
... G36: =IFERROR(IF(SubscriptionTracker[[#This Row],[Billing Frequency]]="Monthly",SubscriptionTracker[[#This Row],[Price]],IF(SubscriptionTracker[[#This Row],[Billing Frequency]]="Quarterly",SubscriptionTracker[[#This Row],[Price]]/3,IF(SubscriptionTracker[[#This Row],[Billing Frequency]]="Annually",SubscriptionTracker[[#This Row],[Price]]/12,""))),"") | H36: =IFERROR(SubscriptionTracker[[#This Row],[Monthly Price]]*12,"")

Sheet 🌼 Habit Tracker
A1: Habit Tracker | AJ1: Day | AK1: Habits Completed
A2: A simple bonus tracker for daily habits. Pick a month, type your habits in the list, and mark a checkmark on the days you did them. | AJ2: 1 | AK2: =IF($C$8="","",COUNTIF(C$9:C$18,"✓"))
AJ3: 2 | AK3: =IF($D$8="","",COUNTIF(D$9:D$18,"✓"))
A4: Month | B4: January | D4: COMPLETION | AJ4: 3 | AK4: =IF($E$8="","",COUNTIF(E$9:E$18,"✓")) | AL4: =MATCH($B$4,MonthList,0)
A5: Year | B5: 2026 | D5: =B6 | AJ5: 4 | AK5: =IF($F$8="","",COUNTIF(F$9:F$18,"✓")) | AL5: =DAY(EOMONTH(DATE($B$5,$AL$4,1),0))
A6: Overall Completion % | B6: =IFERROR(AVERAGE(AH9:AH18),0) | AJ6: 5 | AK6: =IF($G$8="","",COUNTIF(G$9:G$18,"✓"))
AJ7: 6 | AK7: =IF($H$8="","",COUNTIF(H$9:H$18,"✓"))
A8: Habit | B8: Category | C8: =IF(1<=$AL$5,1,"") | D8: =IF(2<=$AL$5,2,"") | E8: =IF(3<=$AL$5,3,"") | F8: =IF(4<=$AL$5,4,"") | G8: =IF(5<=$AL$5,5,"") | H8: =IF(6<=$AL$5,6,"") | I8: =IF(7<=$AL$5,7,"") | J8: =IF(8<=$AL$5,8,"") | K8: =IF(9<=$AL$5,9,"") | L8: =IF(10<=$AL$5,10,"") | M8: =IF(11<=$AL$5,11,"") | N8: =IF(12<=$AL$5,12,"") | O8: =IF(13<=$AL$5,13,"") | P8: =IF(14<=$AL$5,14,"") | Q8: =IF(15<=$AL$5,15,"") | R8: =IF(16<=$AL$5,16,"") | S8: =IF(17<=$AL$5,17,"") | T8: =IF(18<=$AL$5,18,"") | U8: =IF(19<=$AL$5,19,"") | V8: =IF(20<=$AL$5,20,"") | W8: =IF(21<=$AL$5,21,"") | X8: =IF(22<=$AL$5,22,"") | Y8: =IF(23<=$AL$5,23,"") | Z8: =IF(24<=$AL$5,24,"") | AA8: =IF(25<=$AL$5,25,"") | AB8: =IF(26<=$AL$5,26,"") | AC8: =IF(27<=$AL$5,27,"") | AD8: =IF(28<=$AL$5,28,"") | AE8: =IF(29<=$AL$5,29,"") | AF8: =IF(30<=$AL$5,30,"") | AG8: =IF(31<=$AL$5,31,"") | AH8: Completion % | AJ8: 7 | AK8: =IF($I$8="","",COUNTIF(I$9:I$18,"✓"))
A9: Drink Water | AH9: =IFERROR(COUNTIF(C9:AG9,"✓")/$AL$5,0) | AJ9: 8 | AK9: =IF($J$8="","",COUNTIF(J$9:J$18,"✓"))
A10: Move My Body | AH10: =IFERROR(COUNTIF(C10:AG10,"✓")/$AL$5,0) | AJ10: 9 | AK10: =IF($K$8="","",COUNTIF(K$9:K$18,"✓"))
A11: Sleep 7+ Hours | AH11: =IFERROR(COUNTIF(C11:AG11,"✓")/$AL$5,0) | AJ11: 10 | AK11: =IF($L$8="","",COUNTIF(L$9:L$18,"✓"))
AH12: =IFERROR(COUNTIF(C12:AG12,"✓")/$AL$5,0) | AJ12: 11 | AK12: =IF($M$8="","",COUNTIF(M$9:M$18,"✓"))
AH13: =IFERROR(COUNTIF(C13:AG13,"✓")/$AL$5,0) | AJ13: 12 | AK13: =IF($N$8="","",COUNTIF(N$9:N$18,"✓"))
AH14: =IFERROR(COUNTIF(C14:AG14,"✓")/$AL$5,0) | AJ14: 13 | AK14: =IF($O$8="","",COUNTIF(O$9:O$18,"✓"))
AH15: =IFERROR(COUNTIF(C15:AG15,"✓")/$AL$5,0) | AJ15: 14 | AK15: =IF($P$8="","",COUNTIF(P$9:P$18,"✓"))
AH16: =IFERROR(COUNTIF(C16:AG16,"✓")/$AL$5,0) | AJ16: 15 | AK16: =IF($Q$8="","",COUNTIF(Q$9:Q$18,"✓"))
AH17: =IFERROR(COUNTIF(C17:AG17,"✓")/$AL$5,0) | AJ17: 16 | AK17: =IF($R$8="","",COUNTIF(R$9:R$18,"✓"))
AH18: =IFERROR(COUNTIF(C18:AG18,"✓")/$AL$5,0) | AJ18: 17 | AK18: =IF($S$8="","",COUNTIF(S$9:S$18,"✓"))
AJ19: 18 | AK19: =IF($T$8="","",COUNTIF(T$9:T$18,"✓"))
AJ20: 19 | AK20: =IF($U$8="","",COUNTIF(U$9:U$18,"✓"))
AJ21: 20 | AK21: =IF($V$8="","",COUNTIF(V$9:V$18,"✓"))
AJ22: 21 | AK22: =IF($W$8="","",COUNTIF(W$9:W$18,"✓"))
AJ23: 22 | AK23: =IF($X$8="","",COUNTIF(X$9:X$18,"✓"))
AJ24: 23 | AK24: =IF($Y$8="","",COUNTIF(Y$9:Y$18,"✓"))
AJ25: 24 | AK25: =IF($Z$8="","",COUNTIF(Z$9:Z$18,"✓"))
AJ26: 25 | AK26: =IF($AA$8="","",COUNTIF(AA$9:AA$18,"✓"))
AJ27: 26 | AK27: =IF($AB$8="","",COUNTIF(AB$9:AB$18,"✓"))
AJ28: 27 | AK28: =IF($AC$8="","",COUNTIF(AC$9:AC$18,"✓"))
AJ29: 28 | AK29: =IF($AD$8="","",COUNTIF(AD$9:AD$18,"✓"))
AJ30: 29 | AK30: =IF($AE$8="","",COUNTIF(AE$9:AE$18,"✓"))
AJ31: 30 | AK31: =IF($AF$8="","",COUNTIF(AF$9:AF$18,"✓"))
AJ32: 31 | AK32: =IF($AG$8="","",COUNTIF(AG$9:AG$18,"✓"))

Sheet ✨ Monthly Reflection
A1: ✨ Monthly Reflection
A2: Four gentle questions to close out the month. No scores, no grades, just a soft look back before you begin again.
B4: Month
B6: 1. What felt good about my money this month?
B10: 2. What did I notice about my spending? (just noticing, no judgement)
B14: 3. What is one small, kind thing I want to try next month?
B18: 4. What am I proud of this month, money or otherwise?
B22: 🤍 Life Happens
B23: If this month went sideways, you overspent, you stopped logging, life got loud, that is completely okay. Nothing is broken. You have not failed. Take a breath, start a new month tab whenever you are ready, and pick up exactly where you are. This tool waits for you, without judgement. Always.

Sheet Paycheck Budget
A1: Paycheck Budget | G1: LEFT TO SPEND | I1: INCOME | J1: BILLS | K1: EXPENSES | L1: SAVINGS | M1: DEBT
A2: Your automatic budget dashboard. Log transactions on the Transactions Log tab and everything below updates on its own. | G2: =E10 | I2: =C20 | J2: =C32 | K2: =C44 | L2: =C53 | M2: =C61
N3: Chart data (auto, don't edit)
A4: Your Setup | D4: Cash Flow Summary | G4: ="Days left: "&IF(ISNUMBER(B7),MAX(B7-TODAY(),0),0) | N4: Left to Spend | O4: =MAX(E10,0)
A5: Start Date | B5: 46235 | D5: Income | E5: =C20 | N5: Spent | O5: =C32+C44+C53+C61
A6: Pay Frequency | B6: Monthly | D6: Bills | E6: =-C32
A7: Budget Period End | B7: 46265 | D7: Expenses | E7: =-C44
A8: Currency | B8: USD | D8: Savings | E8: =-C53 | N8: Bills | O8: =C32
D9: Debt | E9: =-C61 | N9: Expenses | O9: =C44
D10: Amount Left to Spend | E10: =E5+E6+E7+E8+E9 | I10: =E10 | N10: Savings | O10: =C53
N11: Debt | O11: =C61
