Workbook

Sheet Get Started
A1: WELCOME TO YOUR WEDDING PLANNER
A3: Partner 1 Name | B3: Partner 2 Name | C3: Wedding Date | D3: Wedding Hashtag
A4: Taylor | B4: Jordan | C4: 46552 | D4: #TaylorAndJordan2026
A6: Wedding Photo Placeholder | E6: HOW TO USE THIS PLANNER
A7: [ Insert your favorite photo here: Insert > Image > Cell ] | E7: 1. Fill in your names, wedding date, and hashtag above.
E8: 2. Start on the Dashboard tab to see your planning snapshot.
E9: 3. Work through the Wedding Checklist tab by timeframe.
E10: 4. Add vendors on the Vendor Selection tab. Mark Final Yes and enter the Amount to auto fill your Budget.
E11: 5. Add guests on the Guest List tab. RSVPs sync automatically to your Seating Plan.
E12: 6. Every dropdown list can be edited on the hidden Lists tab.
E13: 7. Tabs with colored banners are organized by wedding planning category. Use the table of contents below to jump to any tab.
E14: 8. Video tutorial: [insert your tutorial link here]
A17: TABLE OF CONTENTS
A18: 1. Dashboard | C18: 18. Aisle Order
A19: 2. Smart Calendar | C19: 19. Wedding Party Gifts
A20: 3. Wedding Checklist | C20: 20. Moodboard
A21: 4. Wedding Itinerary | C21: 21. Decor Inventory
A22: 5. Wedding Activities | C22: 22. Flower Arrangements
A23: 6. Music Planner | C23: 23. Attire and Makeup
A24: 7. Packing List | C24: 24. Accommodation
A25: 8. Wedding Budget | C25: 25. Transportation
A26: 9. Vendor Selection | C26: 26. Stationery Checklist
A27: 10. Venue Comparison | C27: 27. Save the Date
A28: 11. Food and Drinks | C28: 28. Engagement Party
A29: 12. Photo and Video Shot List | C29: 29. Bridal Shower
... A32: 15. Rehearsal Dinner Seating | C32: 32. Gifts and Thank You
A33: 16. Wedding Registry
A34: 17. Wedding Party

Sheet Dashboard
A1: WEDDING DASHBOARD
A3: ='Get Started'!$A$4&" & "&'Get Started'!$B$4 -> Taylor & Jordan | D3: DAYS UNTIL THE WEDDING | G3: WEDDING DATE | I3: [ Wedding photo placeholder ]
D4: =DATEDIF(TODAY(),'Get Started'!$C$4,"d") -> 300 | G4: ='Get Started'!$C$4 -> 46552 | P4: Checklist | Q4: Value
P5: Done | Q5: =COUNTIFS('Wedding Checklist'!A5:A855,TRUE()) -> 0
P6: Remaining | Q6: =COUNTIFS('Wedding Checklist'!A5:A855,FALSE()) -> 851
A8: WEDDING BUDGET | C8: TOTAL SPENT | E8: LEFT TO SPEND | G8: VENDOR PAYMENTS LEFT | P8: Bride | Q8: =COUNTIFS('Guest List'!B7:B206,"Bride") -> 2
A9: ='Wedding Budget'!A4 -> 21000 | C9: ='Wedding Budget'!E4 -> 17900 | E9: ='Wedding Budget'!G4 -> 3100 | G9: ='Wedding Budget'!I4 -> 1600 | P9: Groom | Q9: =COUNTIFS('Guest List'!B7:B206,"Groom") -> 2
P10: Both | Q10: =COUNTIFS('Guest List'!B7:B206,"Both") -> 2
A11: CONFIRMED GUESTS | C11: CONFIRMED AND SEATED | E11: TENTATIVE SEATS | G11: REMAINING SEATS
A12: ='Guest List'!G4 -> 2 | C12: ='Reception Seating Plan'!E4 -> 0 | E12: ='Reception Seating Plan'!G4 -> 2 | G12: ='Reception Seating Plan'!I4 -> 80 | P12: STD Sent | Q12: ='Guest List'!C4 -> 6
P13: STD Not Sent | Q13: ='Guest List'!A4-'Guest List'!C4 -> 0
A14: CHECKLIST PROGRESS
P15: Invites Sent | Q15: ='Guest List'!E4 -> 6
P16: Invites Not Sent | Q16: ='Guest List'!A4-'Guest List'!E4 -> 0
P18: Attire Status | Q18: Count
P19: Not Started | Q19: =COUNTIFS('Wedding Party'!G$9:G$60,P19) -> 20
P20: Ordered | Q20: =COUNTIFS('Wedding Party'!G$9:G$60,P20) -> 0
P21: Received | Q21: =COUNTIFS('Wedding Party'!G$9:G$60,P21) -> 0
P22: Fitting Scheduled | Q22: =COUNTIFS('Wedding Party'!G$9:G$60,P22) -> 0
P23: Alterations Needed | Q23: =COUNTIFS('Wedding Party'!G$9:G$60,P23) -> 0
P24: Ready | Q24: =COUNTIFS('Wedding Party'!G$9:G$60,P24) -> 0
A64: TODAY | F64: PROGRESS RATIOS
A65: Checklist items due today | C65: =COUNTIFS('Wedding Checklist'!C5:C855,TODAY(),'Wedding Checklist'!A5:A855,FALSE()) -> 0 | F65: Vendor Selection Progress | I65: ='Vendor Selection'!A4 -> 0.6
A66: Deadlines due today | C66: =COUNTIFS('Wedding Budget'!C36:C75,TODAY()) -> 0 | F66: Wedding Party Confirmation | I66: =IFERROR(COUNTIF('Wedding Party'!A8:A60,TRUE())/COUNTA('Wedding Party'!B8:B60),0) -> 0.66666667
F67: Thank You Sent Ratio | I67: =IFERROR(COUNTIF('Gifts and Thank You'!D8:D400,TRUE())/COUNTA('Gifts and Thank You'!A8:A400),0) -> 0

Sheet Smart Calendar
A1: SMART CALENDAR
A3: Month | B3: August | C3: Year | D3: 2026
B4: Budget | C4: Checklist | D4: Important Dates | E4: Stationery | F4: Dance Lessons
A5: SHOW ON CALENDAR: | B5: =TRUE() -> 1 | C5: =TRUE() -> 1 | D5: =TRUE() -> 1 | E5: =TRUE() -> 1 | F5: =TRUE() -> 1
A7: LEGEND: | B7: Due Today | C7: Overdue | D7: Due Later
A9: Sun | B9: Mon | C9: Tue | D9: Wed | E9: Thu | F9: Fri | G9: Sat
A10: =DATE($D$3,MATCH($B$3,MonthNames,0),1)-WEEKDAY(DATE($D$3,MATCH($B$3,MonthNames,0),1))+0+1 -> 46229 | B10: =DATE($D$3,MATCH($B$3,MonthNames,0),1)-WEEKDAY(DATE($D$3,MATCH($B$3,MonthNames,0),1))+1+1 -> 46230 | C10: =DATE($D$3,MATCH($B$3,MonthNames,0),1)-WEEKDAY(DATE($D$3,MATCH($B$3,MonthNames,0),1))+2+1 -> 46231 | D10: =DATE($D$3,MATCH($B$3,MonthNames,0),1)-WEEKDAY(DATE($D$3,MATCH($B$3,MonthNames,0),1))+3+1 -> 46232 | E10: =DATE($D$3,MATCH($B$3,MonthNames,0),1)-WEEKDAY(DATE($D$3,MATCH($B$3,MonthNames,0),1))+4+1 -> 46233 | F10: =DATE($D$3,MATCH($B$3,MonthNames,0),1)-WEEKDAY(DATE($D$3,MATCH($B$3,MonthNames,0),1))+5+1 -> 46234 | G10: =DATE($D$3,MATCH($B$3,MonthNames,0),1)-WEEKDAY(DATE($D$3,MATCH($B$3,MonthNames,0),1))+6+1 -> 46235
A11: =TRIM(IF(AND($C5,COUNTIFS('Wedding Checklist'!$C$5:$C$855,A10,'Wedding Checklist'!$A$5:$A$855,FALSE())>0),COUNTIFS('Wedding Checklist'!$C$5:$C$855,A10,'Wedding Checklist'!$A$5:$A$855,FALSE())&" checklist item(s)"&CHAR(10),"")&IF(AND($B5,COUNTIFS('Wedding Budget'!$C$36:$C$75,A10)>0),COUNTIFS('Wedding Budget'!$C$36:$C$75,A10)&" payment(s) due"&CHAR(10),"")) | B11: =TRIM(IF(AND($C5,COUNTIFS('Wedding Checklist'!$C$5:$C$855,B10,'Wedding Checklist'!$A$5:$A$855,FALSE())>0),COUNTIFS('Wedding Checklist'!$C$5:$C$855,B10,'Wedding Checklist'!$A$5:$A$855,FALSE())&" checklist item(s)"&CHAR(10),"")&IF(AND($B5,COUNTIFS('Wedding Budget'!$C$36:$C$75,B10)>0),COUNTIFS('Wedding Budget'!$C$36:$C$75,B10)&" payment(s) due"&CHAR(10),"")) | C11: =TRIM(IF(AND($C5,COUNTIFS('Wedding Checklist'!$C$5:$C$855,C10,'Wedding Checklist'!$A$5:$A$855,FALSE())>0),COUNTIFS('Wedding Checklist'!$C$5:$C$855,C10,'Wedding Checklist'!$A$5:$A$855,FALSE())&" checklist item(s)"&CHAR(10),"")&IF(AND($B5,COUNTIFS('Wedding Budget'!$C$36:$C$75,C10)>0),COUNTIFS('Wedding Budget'!$C$36:$C$75,C10)&" payment(s) due"&CHAR(10),"")) | D11: =TRIM(IF(AND($C5,COUNTIFS('Wedding Checklist'!$C$5:$C$855,D10,'Wedding Checklist'!$A$5:$A$855,FALSE())>0),COUNTIFS('Wedding Checklist'!$C$5:$C$855,D10,'Wedding Checklist'!$A$5:$A$855,FALSE())&" checklist item(s)"&CHAR(10),"")&IF(AND($B5,COUNTIFS('Wedding Budget'!$C$36:$C$75,D10)>0),COUNTIFS('Wedding Budget'!$C$36:$C$75,D10)&" payment(s) due"&CHAR(10),"")) | E11: =TRIM(IF(AND($C5,COUNTIFS('Wedding Checklist'!$C$5:$C$855,E10,'Wedding Checklist'!$A$5:$A$855,FALSE())>0),COUNTIFS('Wedding Checklist'!$C$5:$C$855,E10,'Wedding Checklist'!$A$5:$A$855,FALSE())&" checklist item(s)"&CHAR(10),"")&IF(AND($B5,COUNTIFS('Wedding Budget'!$C$36:$C$75,E10)>0),COUNTIFS('Wedding Budget'!$C$36:$C$75,E10)&" payment(s) due"&CHAR(10),"")) | F11: =TRIM(IF(AND($C5,COUNTIFS('Wedding Checklist'!$C$5:$C$855,F10,'Wedding Checklist'!$A$5:$A$855,FALSE())>0),COUNTIFS('Wedding Checklist'!$C$5:$C$855,F10,'Wedding Checklist'!$A$5:$A$855,FALSE())&" checklist item(s)"&CHAR(10),"")&IF(AND($B5,COUNTIFS('Wedding Budget'!$C$36:$C$75,F10)>0),COUNTIFS('Wedding Budget'!$C$36:$C$75,F10)&" payment(s) due"&CHAR(10),"")) | G11: =TRIM(IF(AND($C5,COUNTIFS('Wedding Checklist'!$C$5:$C$855,G10,'Wedding Checklist'!$A$5:$A$855,FALSE())>0),COUNTIFS('Wedding Checklist'!$C$5:$C$855,G10,'Wedding Checklist'!$A$5:$A$855,FALSE())&" checklist item(s)"&CHAR(10),"")&IF(AND($B5,COUNTIFS('Wedding Budget'!$C$36:$C$75,G10)>0),COUNTIFS('Wedding Budget'!$C$36:$C$75,G10)&" payment(s) due"&CHAR(10),""))
A13: =DATE($D$3,MATCH($B$3,MonthNames,0),1)-WEEKDAY(DATE($D$3,MATCH($B$3,MonthNames,0),1))+7+1 -> 46236 | B13: =DATE($D$3,MATCH($B$3,MonthNames,0),1)-WEEKDAY(DATE($D$3,MATCH($B$3,MonthNames,0),1))+8+1 -> 46237 | C13: =DATE($D$3,MATCH($B$3,MonthNames,0),1)-WEEKDAY(DATE($D$3,MATCH($B$3,MonthNames,0),1))+9+1 -> 46238 | D13: =DATE($D$3,MATCH($B$3,MonthNames,0),1)-WEEKDAY(DATE($D$3,MATCH($B$3,MonthNames,0),1))+10+1 -> 46239 | E13: =DATE($D$3,MATCH($B$3,MonthNames,0),1)-WEEKDAY(DATE($D$3,MATCH($B$3,MonthNames,0),1))+11+1 -> 46240 | F13: =DATE($D$3,MATCH($B$3,MonthNames,0),1)-WEEKDAY(DATE($D$3,MATCH($B$3,MonthNames,0),1))+12+1 -> 46241 | G13: =DATE($D$3,MATCH($B$3,MonthNames,0),1)-WEEKDAY(DATE($D$3,MATCH($B$3,MonthNames,0),1))+13+1 -> 46242
A14: =TRIM(IF(AND($C5,COUNTIFS('Wedding Checklist'!$C$5:$C$855,A13,'Wedding Checklist'!$A$5:$A$855,FALSE())>0),COUNTIFS('Wedding Checklist'!$C$5:$C$855,A13,'Wedding Checklist'!$A$5:$A$855,FALSE())&" checklist item(s)"&CHAR(10),"")&IF(AND($B5,COUNTIFS('Wedding Budget'!$C$36:$C$75,A13)>0),COUNTIFS('Wedding Budget'!$C$36:$C$75,A13)&" payment(s) due"&CHAR(10),"")) | B14: =TRIM(IF(AND($C5,COUNTIFS('Wedding Checklist'!$C$5:$C$855,B13,'Wedding Checklist'!$A$5:$A$855,FALSE())>0),COUNTIFS('Wedding Checklist'!$C$5:$C$855,B13,'Wedding Checklist'!$A$5:$A$855,FALSE())&" checklist item(s)"&CHAR(10),"")&IF(AND($B5,COUNTIFS('Wedding Budget'!$C$36:$C$75,B13)>0),COUNTIFS('Wedding Budget'!$C$36:$C$75,B13)&" payment(s) due"&CHAR(10),"")) | C14: =TRIM(IF(AND($C5,COUNTIFS('Wedding Checklist'!$C$5:$C$855,C13,'Wedding Checklist'!$A$5:$A$855,FALSE())>0),COUNTIFS('Wedding Checklist'!$C$5:$C$855,C13,'Wedding Checklist'!$A$5:$A$855,FALSE())&" checklist item(s)"&CHAR(10),"")&IF(AND($B5,COUNTIFS('Wedding Budget'!$C$36:$C$75,C13)>0),COUNTIFS('Wedding Budget'!$C$36:$C$75,C13)&" payment(s) due"&CHAR(10),"")) | D14: =TRIM(IF(AND($C5,COUNTIFS('Wedding Checklist'!$C$5:$C$855,D13,'Wedding Checklist'!$A$5:$A$855,FALSE())>0),COUNTIFS('Wedding Checklist'!$C$5:$C$855,D13,'Wedding Checklist'!$A$5:$A$855,FALSE())&" checklist item(s)"&CHAR(10),"")&IF(AND($B5,COUNTIFS('Wedding Budget'!$C$36:$C$75,D13)>0),COUNTIFS('Wedding Budget'!$C$36:$C$75,D13)&" payment(s) due"&CHAR(10),"")) | E14: =TRIM(IF(AND($C5,COUNTIFS('Wedding Checklist'!$C$5:$C$855,E13,'Wedding Checklist'!$A$5:$A$855,FALSE())>0),COUNTIFS('Wedding Checklist'!$C$5:$C$855,E13,'Wedding Checklist'!$A$5:$A$855,FALSE())&" checklist item(s)"&CHAR(10),"")&IF(AND($B5,COUNTIFS('Wedding Budget'!$C$36:$C$75,E13)>0),COUNTIFS('Wedding Budget'!$C$36:$C$75,E13)&" payment(s) due"&CHAR(10),"")) | F14: =TRIM(IF(AND($C5,COUNTIFS('Wedding Checklist'!$C$5:$C$855,F13,'Wedding Checklist'!$A$5:$A$855,FALSE())>0),COUNTIFS('Wedding Checklist'!$C$5:$C$855,F13,'Wedding Checklist'!$A$5:$A$855,FALSE())&" checklist item(s)"&CHAR(10),"")&IF(AND($B5,COUNTIFS('Wedding Budget'!$C$36:$C$75,F13)>0),COUNTIFS('Wedding Budget'!$C$36:$C$75,F13)&" payment(s) due"&CHAR(10),"")) | G14: =TRIM(IF(AND($C5,COUNTIFS('Wedding Checklist'!$C$5:$C$855,G13,'Wedding Checklist'!$A$5:$A$855,FALSE())>0),COUNTIFS('Wedding Checklist'!$C$5:$C$855,G13,'Wedding Checklist'!$A$5:$A$855,FALSE())&" checklist item(s)"&CHAR(10),"")&IF(AND($B5,COUNTIFS('Wedding Budget'!$C$36:$C$75,G13)>0),COUNTIFS('Wedding Budget'!$C$36:$C$75,G13)&" payment(s) due"&CHAR(10),""))
A16: =DATE($D$3,MATCH($B$3,MonthNames,0),1)-WEEKDAY(DATE($D$3,MATCH($B$3,MonthNames,0),1))+14+1 -> 46243 | B16: =DATE($D$3,MATCH($B$3,MonthNames,0),1)-WEEKDAY(DATE($D$3,MATCH($B$3,MonthNames,0),1))+15+1 -> 46244 | C16: =DATE($D$3,MATCH($B$3,MonthNames,0),1)-WEEKDAY(DATE($D$3,MATCH($B$3,MonthNames,0),1))+16+1 -> 46245 | D16: =DATE($D$3,MATCH($B$3,MonthNames,0),1)-WEEKDAY(DATE($D$3,MATCH($B$3,MonthNames,0),1))+17+1 -> 46246 | E16: =DATE($D$3,MATCH($B$3,MonthNames,0),1)-WEEKDAY(DATE($D$3,MATCH($B$3,MonthNames,0),1))+18+1 -> 46247 | F16: =DATE($D$3,MATCH($B$3,MonthNames,0),1)-WEEKDAY(DATE($D$3,MATCH($B$3,MonthNames,0),1))+19+1 -> 46248 | G16: =DATE($D$3,MATCH($B$3,MonthNames,0),1)-WEEKDAY(DATE($D$3,MATCH($B$3,MonthNames,0),1))+20+1 -> 46249
A17: =TRIM(IF(AND($C5,COUNTIFS('Wedding Checklist'!$C$5:$C$855,A16,'Wedding Checklist'!$A$5:$A$855,FALSE())>0),COUNTIFS('Wedding Checklist'!$C$5:$C$855,A16,'Wedding Checklist'!$A$5:$A$855,FALSE())&" checklist item(s)"&CHAR(10),"")&IF(AND($B5,COUNTIFS('Wedding Budget'!$C$36:$C$75,A16)>0),COUNTIFS('Wedding Budget'!$C$36:$C$75,A16)&" payment(s) due"&CHAR(10),"")) | B17: =TRIM(IF(AND($C5,COUNTIFS('Wedding Checklist'!$C$5:$C$855,B16,'Wedding Checklist'!$A$5:$A$855,FALSE())>0),COUNTIFS('Wedding Checklist'!$C$5:$C$855,B16,'Wedding Checklist'!$A$5:$A$855,FALSE())&" checklist item(s)"&CHAR(10),"")&IF(AND($B5,COUNTIFS('Wedding Budget'!$C$36:$C$75,B16)>0),COUNTIFS('Wedding Budget'!$C$36:$C$75,B16)&" payment(s) due"&CHAR(10),"")) | C17: =TRIM(IF(AND($C5,COUNTIFS('Wedding Checklist'!$C$5:$C$855,C16,'Wedding Checklist'!$A$5:$A$855,FALSE())>0),COUNTIFS('Wedding Checklist'!$C$5:$C$855,C16,'Wedding Checklist'!$A$5:$A$855,FALSE())&" checklist item(s)"&CHAR(10),"")&IF(AND($B5,COUNTIFS('Wedding Budget'!$C$36:$C$75,C16)>0),COUNTIFS('Wedding Budget'!$C$36:$C$75,C16)&" payment(s) due"&CHAR(10),"")) | D17: =TRIM(IF(AND($C5,COUNTIFS('Wedding Checklist'!$C$5:$C$855,D16,'Wedding Checklist'!$A$5:$A$855,FALSE())>0),COUNTIFS('Wedding Checklist'!$C$5:$C$855,D16,'Wedding Checklist'!$A$5:$A$855,FALSE())&" checklist item(s)"&CHAR(10),"")&IF(AND($B5,COUNTIFS('Wedding Budget'!$C$36:$C$75,D16)>0),COUNTIFS('Wedding Budget'!$C$36:$C$75,D16)&" payment(s) due"&CHAR(10),"")) | E17: =TRIM(IF(AND($C5,COUNTIFS('Wedding Checklist'!$C$5:$C$855,E16,'Wedding Checklist'!$A$5:$A$855,FALSE())>0),COUNTIFS('Wedding Checklist'!$C$5:$C$855,E16,'Wedding Checklist'!$A$5:$A$855,FALSE())&" checklist item(s)"&CHAR(10),"")&IF(AND($B5,COUNTIFS('Wedding Budget'!$C$36:$C$75,E16)>0),COUNTIFS('Wedding Budget'!$C$36:$C$75,E16)&" payment(s) due"&CHAR(10),"")) | F17: =TRIM(IF(AND($C5,COUNTIFS('Wedding Checklist'!$C$5:$C$855,F16,'Wedding Checklist'!$A$5:$A$855,FALSE())>0),COUNTIFS('Wedding Checklist'!$C$5:$C$855,F16,'Wedding Checklist'!$A$5:$A$855,FALSE())&" checklist item(s)"&CHAR(10),"")&IF(AND($B5,COUNTIFS('Wedding Budget'!$C$36:$C$75,F16)>0),COUNTIFS('Wedding Budget'!$C$36:$C$75,F16)&" payment(s) due"&CHAR(10),"")) | G17: =TRIM(IF(AND($C5,COUNTIFS('Wedding Checklist'!$C$5:$C$855,G16,'Wedding Checklist'!$A$5:$A$855,FALSE())>0),COUNTIFS('Wedding Checklist'!$C$5:$C$855,G16,'Wedding Checklist'!$A$5:$A$855,FALSE())&" checklist item(s)"&CHAR(10),"")&IF(AND($B5,COUNTIFS('Wedding Budget'!$C$36:$C$75,G16)>0),COUNTIFS('Wedding Budget'!$C$36:$C$75,G16)&" payment(s) due"&CHAR(10),""))
A19: =DATE($D$3,MATCH($B$3,MonthNames,0),1)-WEEKDAY(DATE($D$3,MATCH($B$3,MonthNames,0),1))+21+1 -> 46250 | B19: =DATE($D$3,MATCH($B$3,MonthNames,0),1)-WEEKDAY(DATE($D$3,MATCH($B$3,MonthNames,0),1))+22+1 -> 46251 | C19: =DATE($D$3,MATCH($B$3,MonthNames,0),1)-WEEKDAY(DATE($D$3,MATCH($B$3,MonthNames,0),1))+23+1 -> 46252 | D19: =DATE($D$3,MATCH($B$3,MonthNames,0),1)-WEEKDAY(DATE($D$3,MATCH($B$3,MonthNames,0),1))+24+1 -> 46253 | E19: =DATE($D$3,MATCH($B$3,MonthNames,0),1)-WEEKDAY(DATE($D$3,MATCH($B$3,MonthNames,0),1))+25+1 -> 46254 | F19: =DATE($D$3,MATCH($B$3,MonthNames,0),1)-WEEKDAY(DATE($D$3,MATCH($B$3,MonthNames,0),1))+26+1 -> 46255 | G19: =DATE($D$3,MATCH($B$3,MonthNames,0),1)-WEEKDAY(DATE($D$3,MATCH($B$3,MonthNames,0),1))+27+1 -> 46256
A20: =TRIM(IF(AND($C5,COUNTIFS('Wedding Checklist'!$C$5:$C$855,A19,'Wedding Checklist'!$A$5:$A$855,FALSE())>0),COUNTIFS('Wedding Checklist'!$C$5:$C$855,A19,'Wedding Checklist'!$A$5:$A$855,FALSE())&" checklist item(s)"&CHAR(10),"")&IF(AND($B5,COUNTIFS('Wedding Budget'!$C$36:$C$75,A19)>0),COUNTIFS('Wedding Budget'!$C$36:$C$75,A19)&" payment(s) due"&CHAR(10),"")) | B20: =TRIM(IF(AND($C5,COUNTIFS('Wedding Checklist'!$C$5:$C$855,B19,'Wedding Checklist'!$A$5:$A$855,FALSE())>0),COUNTIFS('Wedding Checklist'!$C$5:$C$855,B19,'Wedding Checklist'!$A$5:$A$855,FALSE())&" checklist item(s)"&CHAR(10),"")&IF(AND($B5,COUNTIFS('Wedding Budget'!$C$36:$C$75,B19)>0),COUNTIFS('Wedding Budget'!$C$36:$C$75,B19)&" payment(s) due"&CHAR(10),"")) | C20: =TRIM(IF(AND($C5,COUNTIFS('Wedding Checklist'!$C$5:$C$855,C19,'Wedding Checklist'!$A$5:$A$855,FALSE())>0),COUNTIFS('Wedding Checklist'!$C$5:$C$855,C19,'Wedding Checklist'!$A$5:$A$855,FALSE())&" checklist item(s)"&CHAR(10),"")&IF(AND($B5,COUNTIFS('Wedding Budget'!$C$36:$C$75,C19)>0),COUNTIFS('Wedding Budget'!$C$36:$C$75,C19)&" payment(s) due"&CHAR(10),"")) | D20: =TRIM(IF(AND($C5,COUNTIFS('Wedding Checklist'!$C$5:$C$855,D19,'Wedding Checklist'!$A$5:$A$855,FALSE())>0),COUNTIFS('Wedding Checklist'!$C$5:$C$855,D19,'Wedding Checklist'!$A$5:$A$855,FALSE())&" checklist item(s)"&CHAR(10),"")&IF(AND($B5,COUNTIFS('Wedding Budget'!$C$36:$C$75,D19)>0),COUNTIFS('Wedding Budget'!$C$36:$C$75,D19)&" payment(s) due"&CHAR(10),"")) | E20: =TRIM(IF(AND($C5,COUNTIFS('Wedding Checklist'!$C$5:$C$855,E19,'Wedding Checklist'!$A$5:$A$855,FALSE())>0),COUNTIFS('Wedding Checklist'!$C$5:$C$855,E19,'Wedding Checklist'!$A$5:$A$855,FALSE())&" checklist item(s)"&CHAR(10),"")&IF(AND($B5,COUNTIFS('Wedding Budget'!$C$36:$C$75,E19)>0),COUNTIFS('Wedding Budget'!$C$36:$C$75,E19)&" payment(s) due"&CHAR(10),"")) | F20: =TRIM(IF(AND($C5,COUNTIFS('Wedding Checklist'!$C$5:$C$855,F19,'Wedding Checklist'!$A$5:$A$855,FALSE())>0),COUNTIFS('Wedding Checklist'!$C$5:$C$855,F19,'Wedding Checklist'!$A$5:$A$855,FALSE())&" checklist item(s)"&CHAR(10),"")&IF(AND($B5,COUNTIFS('Wedding Budget'!$C$36:$C$75,F19)>0),COUNTIFS('Wedding Budget'!$C$36:$C$75,F19)&" payment(s) due"&CHAR(10),"")) | G20: =TRIM(IF(AND($C5,COUNTIFS('Wedding Checklist'!$C$5:$C$855,G19,'Wedding Checklist'!$A$5:$A$855,FALSE())>0),COUNTIFS('Wedding Checklist'!$C$5:$C$855,G19,'Wedding Checklist'!$A$5:$A$855,FALSE())&" checklist item(s)"&CHAR(10),"")&IF(AND($B5,COUNTIFS('Wedding Budget'!$C$36:$C$75,G19)>0),COUNTIFS('Wedding Budget'!$C$36:$C$75,G19)&" payment(s) due"&CHAR(10),""))
A22: =DATE($D$3,MATCH($B$3,MonthNames,0),1)-WEEKDAY(DATE($D$3,MATCH($B$3,MonthNames,0),1))+28+1 -> 46257 | B22: =DATE($D$3,MATCH($B$3,MonthNames,0),1)-WEEKDAY(DATE($D$3,MATCH($B$3,MonthNames,0),1))+29+1 -> 46258 | C22: =DATE($D$3,MATCH($B$3,MonthNames,0),1)-WEEKDAY(DATE($D$3,MATCH($B$3,MonthNames,0),1))+30+1 -> 46259 | D22: =DATE($D$3,MATCH($B$3,MonthNames,0),1)-WEEKDAY(DATE($D$3,MATCH($B$3,MonthNames,0),1))+31+1 -> 46260 | E22: =DATE($D$3,MATCH($B$3,MonthNames,0),1)-WEEKDAY(DATE($D$3,MATCH($B$3,MonthNames,0),1))+32+1 -> 46261 | F22: =DATE($D$3,MATCH($B$3,MonthNames,0),1)-WEEKDAY(DATE($D$3,MATCH($B$3,MonthNames,0),1))+33+1 -> 46262 | G22: =DATE($D$3,MATCH($B$3,MonthNames,0),1)-WEEKDAY(DATE($D$3,MATCH($B$3,MonthNames,0),1))+34+1 -> 46263
A23: =TRIM(IF(AND($C5,COUNTIFS('Wedding Checklist'!$C$5:$C$855,A22,'Wedding Checklist'!$A$5:$A$855,FALSE())>0),COUNTIFS('Wedding Checklist'!$C$5:$C$855,A22,'Wedding Checklist'!$A$5:$A$855,FALSE())&" checklist item(s)"&CHAR(10),"")&IF(AND($B5,COUNTIFS('Wedding Budget'!$C$36:$C$75,A22)>0),COUNTIFS('Wedding Budget'!$C$36:$C$75,A22)&" payment(s) due"&CHAR(10),"")) | B23: =TRIM(IF(AND($C5,COUNTIFS('Wedding Checklist'!$C$5:$C$855,B22,'Wedding Checklist'!$A$5:$A$855,FALSE())>0),COUNTIFS('Wedding Checklist'!$C$5:$C$855,B22,'Wedding Checklist'!$A$5:$A$855,FALSE())&" checklist item(s)"&CHAR(10),"")&IF(AND($B5,COUNTIFS('Wedding Budget'!$C$36:$C$75,B22)>0),COUNTIFS('Wedding Budget'!$C$36:$C$75,B22)&" payment(s) due"&CHAR(10),"")) | C23: =TRIM(IF(AND($C5,COUNTIFS('Wedding Checklist'!$C$5:$C$855,C22,'Wedding Checklist'!$A$5:$A$855,FALSE())>0),COUNTIFS('Wedding Checklist'!$C$5:$C$855,C22,'Wedding Checklist'!$A$5:$A$855,FALSE())&" checklist item(s)"&CHAR(10),"")&IF(AND($B5,COUNTIFS('Wedding Budget'!$C$36:$C$75,C22)>0),COUNTIFS('Wedding Budget'!$C$36:$C$75,C22)&" payment(s) due"&CHAR(10),"")) | D23: =TRIM(IF(AND($C5,COUNTIFS('Wedding Checklist'!$C$5:$C$855,D22,'Wedding Checklist'!$A$5:$A$855,FALSE())>0),COUNTIFS('Wedding Checklist'!$C$5:$C$855,D22,'Wedding Checklist'!$A$5:$A$855,FALSE())&" checklist item(s)"&CHAR(10),"")&IF(AND($B5,COUNTIFS('Wedding Budget'!$C$36:$C$75,D22)>0),COUNTIFS('Wedding Budget'!$C$36:$C$75,D22)&" payment(s) due"&CHAR(10),"")) | E23: =TRIM(IF(AND($C5,COUNTIFS('Wedding Checklist'!$C$5:$C$855,E22,'Wedding Checklist'!$A$5:$A$855,FALSE())>0),COUNTIFS('Wedding Checklist'!$C$5:$C$855,E22,'Wedding Checklist'!$A$5:$A$855,FALSE())&" checklist item(s)"&CHAR(10),"")&IF(AND($B5,COUNTIFS('Wedding Budget'!$C$36:$C$75,E22)>0),COUNTIFS('Wedding Budget'!$C$36:$C$75,E22)&" payment(s) due"&CHAR(10),"")) | F23: =TRIM(IF(AND($C5,COUNTIFS('Wedding Checklist'!$C$5:$C$855,F22,'Wedding Checklist'!$A$5:$A$855,FALSE())>0),COUNTIFS('Wedding Checklist'!$C$5:$C$855,F22,'Wedding Checklist'!$A$5:$A$855,FALSE())&" checklist item(s)"&CHAR(10),"")&IF(AND($B5,COUNTIFS('Wedding Budget'!$C$36:$C$75,F22)>0),COUNTIFS('Wedding Budget'!$C$36:$C$75,F22)&" payment(s) due"&CHAR(10),"")) | G23: =TRIM(IF(AND($C5,COUNTIFS('Wedding Checklist'!$C$5:$C$855,G22,'Wedding Checklist'!$A$5:$A$855,FALSE())>0),COUNTIFS('Wedding Checklist'!$C$5:$C$855,G22,'Wedding Checklist'!$A$5:$A$855,FALSE())&" checklist item(s)"&CHAR(10),"")&IF(AND($B5,COUNTIFS('Wedding Budget'!$C$36:$C$75,G22)>0),COUNTIFS('Wedding Budget'!$C$36:$C$75,G22)&" payment(s) due"&CHAR(10),""))
A25: =DATE($D$3,MATCH($B$3,MonthNames,0),1)-WEEKDAY(DATE($D$3,MATCH($B$3,MonthNames,0),1))+35+1 -> 46264 | B25: =DATE($D$3,MATCH($B$3,MonthNames,0),1)-WEEKDAY(DATE($D$3,MATCH($B$3,MonthNames,0),1))+36+1 -> 46265 | C25: =DATE($D$3,MATCH($B$3,MonthNames,0),1)-WEEKDAY(DATE($D$3,MATCH($B$3,MonthNames,0),1))+37+1 -> 46266 | D25: =DATE($D$3,MATCH($B$3,MonthNames,0),1)-WEEKDAY(DATE($D$3,MATCH($B$3,MonthNames,0),1))+38+1 -> 46267 | E25: =DATE($D$3,MATCH($B$3,MonthNames,0),1)-WEEKDAY(DATE($D$3,MATCH($B$3,MonthNames,0),1))+39+1 -> 46268 | F25: =DATE($D$3,MATCH($B$3,MonthNames,0),1)-WEEKDAY(DATE($D$3,MATCH($B$3,MonthNames,0),1))+40+1 -> 46269 | G25: =DATE($D$3,MATCH($B$3,MonthNames,0),1)-WEEKDAY(DATE($D$3,MATCH($B$3,MonthNames,0),1))+41+1 -> 46270
A26: =TRIM(IF(AND($C5,COUNTIFS('Wedding Checklist'!$C$5:$C$855,A25,'Wedding Checklist'!$A$5:$A$855,FALSE())>0),COUNTIFS('Wedding Checklist'!$C$5:$C$855,A25,'Wedding Checklist'!$A$5:$A$855,FALSE())&" checklist item(s)"&CHAR(10),"")&IF(AND($B5,COUNTIFS('Wedding Budget'!$C$36:$C$75,A25)>0),COUNTIFS('Wedding Budget'!$C$36:$C$75,A25)&" payment(s) due"&CHAR(10),"")) | B26: =TRIM(IF(AND($C5,COUNTIFS('Wedding Checklist'!$C$5:$C$855,B25,'Wedding Checklist'!$A$5:$A$855,FALSE())>0),COUNTIFS('Wedding Checklist'!$C$5:$C$855,B25,'Wedding Checklist'!$A$5:$A$855,FALSE())&" checklist item(s)"&CHAR(10),"")&IF(AND($B5,COUNTIFS('Wedding Budget'!$C$36:$C$75,B25)>0),COUNTIFS('Wedding Budget'!$C$36:$C$75,B25)&" payment(s) due"&CHAR(10),"")) | C26: =TRIM(IF(AND($C5,COUNTIFS('Wedding Checklist'!$C$5:$C$855,C25,'Wedding Checklist'!$A$5:$A$855,FALSE())>0),COUNTIFS('Wedding Checklist'!$C$5:$C$855,C25,'Wedding Checklist'!$A$5:$A$855,FALSE())&" checklist item(s)"&CHAR(10),"")&IF(AND($B5,COUNTIFS('Wedding Budget'!$C$36:$C$75,C25)>0),COUNTIFS('Wedding Budget'!$C$36:$C$75,C25)&" payment(s) due"&CHAR(10),"")) | D26: =TRIM(IF(AND($C5,COUNTIFS('Wedding Checklist'!$C$5:$C$855,D25,'Wedding Checklist'!$A$5:$A$855,FALSE())>0),COUNTIFS('Wedding Checklist'!$C$5:$C$855,D25,'Wedding Checklist'!$A$5:$A$855,FALSE())&" checklist item(s)"&CHAR(10),"")&IF(AND($B5,COUNTIFS('Wedding Budget'!$C$36:$C$75,D25)>0),COUNTIFS('Wedding Budget'!$C$36:$C$75,D25)&" payment(s) due"&CHAR(10),"")) | E26: =TRIM(IF(AND($C5,COUNTIFS('Wedding Checklist'!$C$5:$C$855,E25,'Wedding Checklist'!$A$5:$A$855,FALSE())>0),COUNTIFS('Wedding Checklist'!$C$5:$C$855,E25,'Wedding Checklist'!$A$5:$A$855,FALSE())&" checklist item(s)"&CHAR(10),"")&IF(AND($B5,COUNTIFS('Wedding Budget'!$C$36:$C$75,E25)>0),COUNTIFS('Wedding Budget'!$C$36:$C$75,E25)&" payment(s) due"&CHAR(10),"")) | F26: =TRIM(IF(AND($C5,COUNTIFS('Wedding Checklist'!$C$5:$C$855,F25,'Wedding Checklist'!$A$5:$A$855,FALSE())>0),COUNTIFS('Wedding Checklist'!$C$5:$C$855,F25,'Wedding Checklist'!$A$5:$A$855,FALSE())&" checklist item(s)"&CHAR(10),"")&IF(AND($B5,COUNTIFS('Wedding Budget'!$C$36:$C$75,F25)>0),COUNTIFS('Wedding Budget'!$C$36:$C$75,F25)&" payment(s) due"&CHAR(10),"")) | G26: =TRIM(IF(AND($C5,COUNTIFS('Wedding Checklist'!$C$5:$C$855,G25,'Wedding Checklist'!$A$5:$A$855,FALSE())>0),COUNTIFS('Wedding Checklist'!$C$5:$C$855,G25,'Wedding Checklist'!$A$5:$A$855,FALSE())&" checklist item(s)"&CHAR(10),"")&IF(AND($B5,COUNTIFS('Wedding Budget'!$C$36:$C$75,G25)>0),COUNTIFS('Wedding Budget'!$C$36:$C$75,G25)&" payment(s) due"&CHAR(10),""))
A29: IMPORTANT DATES
A30: Task Description | B30: Due Date
A31: Book officiant meeting | B31: ='Get Started'!$C$4+(-300) -> 46252
A32: Order wedding invitations | B32: ='Get Started'!$C$4+(-180) -> 46372
A33: Final dress fitting | B33: ='Get Started'!$C$4+(-30) -> 46522
A34: Marriage license appointment | B34: ='Get Started'!$C$4+(-14) -> 46538
A35: Rehearsal dinner | B35: ='Get Started'!$C$4+(-1) -> 46551

Sheet Wedding Checklist
A1: WEDDING CHECKLIST
A2: Check off each task as you complete it. Due dates are examples, set to guide pacing before the wedding date on the Get Started tab.
A4: Done | B4: Task | C4: Due Date | D4: Assigned To | E4: Priority | F4: Section | H4: PROGRESS BY SECTION
A5: =FALSE() -> 0 | B5: Announce your engagement to family and close friends | C5: ='Get Started'!$C$4-400+-5 -> 46147 | D5: Both | E5: Medium | F5: 12+ Months Before | H5: Section | I5: % Done | J5: Count
A6: =FALSE() -> 0 | B6: Set a realistic wedding budget with your partner | C6: ='Get Started'!$C$4-400+-5 -> 46147 | D6: Both | E6: Medium | F6: 12+ Months Before | H6: 12+ Months Before | I6: =COUNTIFS(A5:A91,TRUE())/COUNTA(B5:B91) -> 0 | J6: =COUNTA(B5:B91) -> 87
A7: =FALSE() -> 0 | B7: Decide who is contributing to the budget and how much | C7: ='Get Started'!$C$4-400+-5 -> 46147 | D7: Both | E7: Medium | F7: 12+ Months Before | H7: 10-12 Months Before | I7: =COUNTIFS(A92:A192,TRUE())/COUNTA(B92:B192) -> 0 | J7: =COUNTA(B92:B192) -> 101
A8: =FALSE() -> 0 | B8: Choose your wedding date (or a short list of dates) | C8: ='Get Started'!$C$4-400+-5 -> 46147 | D8: Both | E8: Medium | F8: 12+ Months Before | H8: 8-10 Months Before | I8: =COUNTIFS(A193:A324,TRUE())/COUNTA(B193:B324) -> 0 | J8: =COUNTA(B193:B324) -> 132
A9: =FALSE() -> 0 | B9: Decide on wedding size (intimate, medium, large) | C9: ='Get Started'!$C$4-400+-5 -> 46147 | D9: Both | E9: Medium | F9: 12+ Months Before | H9: 6-8 Months Before | I9: =COUNTIFS(A325:A421,TRUE())/COUNTA(B325:B421) -> 0 | J9: =COUNTA(B325:B421) -> 97
A10: =FALSE() -> 0 | B10: Create a rough guest list headcount estimate | C10: ='Get Started'!$C$4-400+-5 -> 46147 | D10: Both | E10: Medium | F10: 12+ Months Before | H10: 4-6 Months Before | I10: =COUNTIFS(A422:A513,TRUE())/COUNTA(B422:B513) -> 0 | J10: =COUNTA(B422:B513) -> 92
A11: =FALSE() -> 0 | B11: Discuss and choose a wedding vision, theme, and color palette | C11: ='Get Started'!$C$4-400+-5 -> 46147 | D11: Both | E11: Medium | F11: 12+ Months Before | H11: 2-4 Months Before | I11: =COUNTIFS(A514:A609,TRUE())/COUNTA(B514:B609) -> 0 | J11: =COUNTA(B514:B609) -> 96
A12: =FALSE() -> 0 | B12: Choose the season and general location for the wedding | C12: ='Get Started'!$C$4-400+-5 -> 46147 | D12: Both | E12: Medium | F12: 12+ Months Before | H12: 1 Month Before | I12: =COUNTIFS(A610:A666,TRUE())/COUNTA(B610:B666) -> 0 | J12: =COUNTA(B610:B666) -> 57
A13: =FALSE() -> 0 | B13: Decide whether to hire a wedding planner | C13: ='Get Started'!$C$4-400+-5 -> 46147 | D13: Both | E13: Medium | F13: 12+ Months Before | H13: 2 Weeks Before | I13: =COUNTIFS(A667:A725,TRUE())/COUNTA(B667:B725) -> 0 | J13: =COUNTA(B667:B725) -> 59
A14: =FALSE() -> 0 | B14: Interview and hire a wedding planner if desired | C14: ='Get Started'!$C$4-400+-4 -> 46148 | D14: Both | E14: Medium | F14: 12+ Months Before | H14: 1 Week Before | I14: =COUNTIFS(A726:A772,TRUE())/COUNTA(B726:B772) -> 0 | J14: =COUNTA(B726:B772) -> 47
A15: =FALSE() -> 0 | B15: Start a shared wedding planning binder or spreadsheet | C15: ='Get Started'!$C$4-400+-4 -> 46148 | D15: Both | E15: Medium | F15: 12+ Months Before | H15: 2 Days Before | I15: =COUNTIFS(A773:A791,TRUE())/COUNTA(B773:B791) -> 0 | J15: =COUNTA(B773:B791) -> 19
A16: =FALSE() -> 0 | B16: Create a private wedding email address for vendor communication | C16: ='Get Started'!$C$4-400+-4 -> 46148 | D16: Both | E16: Medium | F16: 12+ Months Before | H16: 1 Day Before | I16: =COUNTIFS(A792:A804,TRUE())/COUNTA(B792:B804) -> 0 | J16: =COUNTA(B792:B804) -> 13
A17: =FALSE() -> 0 | B17: Set up a wedding website | C17: ='Get Started'!$C$4-400+-4 -> 46148 | D17: Both | E17: Medium | F17: 12+ Months Before | H17: Legal Items | I17: =COUNTIFS(A805:A855,TRUE())/COUNTA(B805:B855) -> 0 | J17: =COUNTA(B805:B855) -> 51
A18: =FALSE() -> 0 | B18: Choose a wedding hashtag | C18: ='Get Started'!$C$4-400+-4 -> 46148 | D18: Both | E18: Medium | F18: 12+ Months Before
A19: =FALSE() -> 0 | B19: Draft the full guest list with addresses | C19: ='Get Started'!$C$4-400+-4 -> 46148 | D19: Both | E19: Medium | F19: 12+ Months Before | H19: TASKS REMAINING BY PERSON
A20: =FALSE() -> 0 | B20: Consider a guest list cap and stick to it | C20: ='Get Started'!$C$4-400+-4 -> 46148 | D20: Both | E20: Medium | F20: 12+ Months Before | H20: Bride | I20: =COUNTIFS($D$5:$D$855,H20,$A$5:$A$855,FALSE()) -> 0
A21: =FALSE() -> 0 | B21: Research ceremony and reception venue options | C21: ='Get Started'!$C$4-400+-4 -> 46148 | D21: Both | E21: Medium | F21: 12+ Months Before | H21: Groom | I21: =COUNTIFS($D$5:$D$855,H21,$A$5:$A$855,FALSE()) -> 0
A22: =FALSE() -> 0 | B22: Tour at least 5 potential venues | C22: ='Get Started'!$C$4-400+-4 -> 46148 | D22: Both | E22: Medium | F22: 12+ Months Before | H22: Both | I22: =COUNTIFS($D$5:$D$855,H22,$A$5:$A$855,FALSE()) -> 851
A23: =FALSE() -> 0 | B23: Ask venues about capacity, availability, and included services | C23: ='Get Started'!$C$4-400+-3 -> 46149 | D23: Both | E23: Medium | F23: 12+ Months Before | H23: Wedding Planner | I23: =COUNTIFS($D$5:$D$855,H23,$A$5:$A$855,FALSE()) -> 0
A24: =FALSE() -> 0 | B24: Compare venue costs and what's included in each package | C24: ='Get Started'!$C$4-400+-3 -> 46149 | D24: Both | E24: Medium | F24: 12+ Months Before | H24: Maid of Honor | I24: =COUNTIFS($D$5:$D$855,H24,$A$5:$A$855,FALSE()) -> 0
A25: =FALSE() -> 0 | B25: Book ceremony venue and sign contract | C25: ='Get Started'!$C$4-400+-3 -> 46149 | D25: Both | E25: Medium | F25: 12+ Months Before | H25: Best Man | I25: =COUNTIFS($D$5:$D$855,H25,$A$5:$A$855,FALSE()) -> 0
A26: =FALSE() -> 0 | B26: Book reception venue and sign contract | C26: ='Get Started'!$C$4-400+-3 -> 46149 | D26: Both | E26: Medium | F26: 12+ Months Before | H26: Parent | I26: =COUNTIFS($D$5:$D$855,H26,$A$5:$A$855,FALSE()) -> 0
A27: =FALSE() -> 0 | B27: Pay venue deposit | C27: ='Get Started'!$C$4-400+-3 -> 46149 | D27: Both | E27: Medium | F27: 12+ Months Before | H27: Other | I27: =COUNTIFS($D$5:$D$855,H27,$A$5:$A$855,FALSE()) -> 0
A28: =FALSE() -> 0 | B28: Consider hiring an officiant or asking a friend to get ordained | C28: ='Get Started'!$C$4-400+-3 -> 46149 | D28: Both | E28: Medium | F28: 12+ Months Before
A29: =FALSE() -> 0 | B29: Start researching photographers and browsing portfolios | C29: ='Get Started'!$C$4-400+-3 -> 46149 | D29: Both | E29: Medium | F29: 12+ Months Before
A30: =FALSE() -> 0 | B30: Start researching videographers and browsing reels | C30: ='Get Started'!$C$4-400+-3 -> 46149 | D30: Both | E30: Medium | F30: 12+ Months Before
A31: =FALSE() -> 0 | B31: Start researching wedding planners or day-of coordinators | C31: ='Get Started'!$C$4-400+-2 -> 46150 | D31: Both | E31: Medium | F31: 12+ Months Before
A32: =FALSE() -> 0 | B32: Start a Pinterest or moodboard for overall wedding style | C32: ='Get Started'!$C$4-400+-2 -> 46150 | D32: Both | E32: Medium | F32: 12+ Months Before
A33: =FALSE() -> 0 | B33: Decide on a rough guest count range for catering purposes | C33: ='Get Started'!$C$4-400+-2 -> 46150 | D33: Both | E33: Medium | F33: 12+ Months Before
A34: =FALSE() -> 0 | B34: Research average wedding costs in your area for budgeting | C34: ='Get Started'!$C$4-400+-2 -> 46150 | D34: Both | E34: Medium | F34: 12+ Months Before
A35: =FALSE() -> 0 | B35: Open a dedicated wedding savings account | C35: ='Get Started'!$C$4-400+-2 -> 46150 | D35: Both | E35: Medium | F35: 12+ Months Before
A36: =FALSE() -> 0 | B36: Discuss honeymoon budget separately from wedding budget | C36: ='Get Started'!$C$4-400+-2 -> 46150 | D36: Both | E36: Medium | F36: 12+ Months Before
A37: =FALSE() -> 0 | B37: Ask parents or family about their wishes to be involved | C37: ='Get Started'!$C$4-400+-2 -> 46150 | D37: Both | E37: Medium | F37: 12+ Months Before
A38: =FALSE() -> 0 | B38: Decide on wedding party size and who to ask | C38: ='Get Started'!$C$4-400+-2 -> 46150 | D38: Both | E38: Medium | F38: 12+ Months Before
A39: =FALSE() -> 0 | B39: Draft a wedding party wish list (who you want to ask) | C39: ='Get Started'!$C$4-400+-2 -> 46150 | D39: Both | E39: Medium | F39: 12+ Months Before
A40: =FALSE() -> 0 | B40: Research marriage license requirements in your state | C40: ='Get Started'!$C$4-400+-1 -> 46151 | D40: Both | E40: Medium | F40: 12+ Months Before
A41: =FALSE() -> 0 | B41: Check passport expiration dates if honeymooning abroad | C41: ='Get Started'!$C$4-400+-1 -> 46151 | D41: Both | E41: Medium | F41: 12+ Months Before
...

Sheet Wedding Itinerary
A1: WEDDING DAY ITINERARY
A3: Time | B3: Event | C3: Person in Charge | D3: Location
A4: 8:00 AM | B4: Bridal Party Get Ready | C4: Hair and Makeup Team | D4: Bridal Suite
A5: 9:30 AM | B5: Groom's Party Get Ready | C5: Groomsmen | D5: Groom's Suite
A6: 11:00 AM | B6: First Look | C6: Photographer | D6: Garden
A7: 11:30 AM | B7: Wedding Party Photos | C7: Photographer | D7: Garden
A8: 12:30 PM | B8: Family Formal Photos | C8: Photographer | D8: Garden
A9: 2:00 PM | B9: Guests Arrive | C9: Ushers | D9: Ceremony Site
A10: 2:30 PM | B10: Ceremony | C10: Officiant | D10: Ceremony Site
A11: 3:00 PM | B11: Cocktail Hour | C11: Catering Staff | D11: Terrace
A12: 4:00 PM | B12: Grand Entrance | C12: DJ or Band | D12: Reception Hall
A13: 4:15 PM | B13: First Dance | C13: DJ or Band | D13: Reception Hall
A14: 4:30 PM | B14: Welcome Toast | C14: Best Man | D14: Reception Hall
... A22: 10:45 PM | B22: Send Off | C22: Wedding Party | D22: Venue Exit

Sheet Wedding Activities
A1: WEDDING ACTIVITIES
A3: PLANNED ACTIVITIES
A4: Time Slot | B4: Location | C4: Person in Charge | D4: Activity Description
A5: 3:00 PM | B5: Terrace | C5: Wedding Planner | D5: Photo booth open for guests
A6: 3:15 PM | B6: Lawn | C6: Ushers | D6: Lawn games: cornhole and giant Jenga
A7: 4:30 PM | B7: Reception Hall | C7: DJ | D7: Guest book table with instant camera
A10: 50+ ACTIVITY IDEAS (REFERENCE LIST)
A11: - Photo booth with props | B11: - Fireworks display | C11: - Yard Yahtzee
A12: - Guest book alternative: fingerprint tree | B12: - Karaoke station | C12: - Photo booth with Polaroid guest book
A13: - Guest book alternative: polaroid wall | B13: - Slideshow of couple's photos | C13: - Wine or whiskey barrel signing ceremony
A14: - Lawn games: cornhole | B14: - Advice cards for the couple | C14: - Unity sand ceremony
A15: - Lawn games: giant Jenga | B15: - Wishing well card box | C15: - Handfasting ceremony
A16: - Lawn games: ring toss | B16: - Time capsule for guests to fill | C16: - Wine box time capsule ceremony
A17: - Lawn games: bocce ball | B17: - Coloring book table for kids | C17: - Live band cocktail hour set
A18: - Photo booth with instant camera | B18: - Kids' activity table with crafts | C18: - String quartet ceremony music
A19: - Custom cocktail bar | B19: - Photo scavenger hunt | C19: - Fire pit lounge area
A20: - Wine pull table | B20: - Trivia about the couple | C20: - Cigar and whiskey bar
A21: - S'mores bar | B21: - Custom playlist request cards | C21: - Popcorn bar
A22: - Late night snack station | B22: - Signature drink naming contest | C22: - Hot chocolate bar
... A28: - Photo booth with backdrop | B28: - Giant chess or checkers | C28: - Custom neon sign photo backdrop
A29: - Dance floor confetti drop | B29: - Bean bag toss
A30: - Sparkler send off | B30: - Ladder golf

Sheet Music Planner
A1: MUSIC PLANNER
A3: Share this tab with your DJ or band. Fill in artist, notes, and duration for each moment.
A5: CEREMONY
A6: Moment | B6: Artist | C6: Song / Version Notes | D6: Duration
A7: Prelude Music
A8: Processional
A9: Recessional
A11: COCKTAIL HOUR
A12: Moment | B12: Artist | C12: Song / Version Notes | D12: Duration
A13: Background Playlist
A15: RECEPTION ENTRANCE
A16: Moment | B16: Artist | C16: Song / Version Notes | D16: Duration
A17: Grand Entrance Song
A19: FIRST DANCE
A20: Moment | B20: Artist | C20: Song / Version Notes | D20: Duration
A21: First Dance Song
A23: PARENT DANCES
A24: Moment | B24: Artist | C24: Song / Version Notes | D24: Duration
A25: Father Daughter Dance
A26: Mother Son Dance
A28: PARTY AND DANCING
A29: Moment | B29: Artist | C29: Song / Version Notes | D29: Duration
A30: Open Dance Playlist
A31: Do Not Play List
A33: LAST SONG
A34: Moment | B34: Artist | C34: Song / Version Notes | D34: Duration
A35: Last Song of the Night

Sheet Packing List
A1: PACKING LIST
A3: BRIDE SUITE
A4: Item | B4: Packed | C4: Assigned To | D4: Notes
A5: Wedding dress | B5: =FALSE() -> FALSE | C5: Both
A6: Veil | B6: =FALSE() -> 0 | C6: Both
A7: Shoes | B7: =FALSE() -> 0 | C7: Both
A8: Undergarments | B8: =FALSE() -> 0 | C8: Both
A9: Jewelry | B9: =FALSE() -> 0 | C9: Both
A10: Something old, new, borrowed, blue | B10: =FALSE() -> 0 | C10: Both
A11: Emergency kit | B11: =FALSE() -> 0 | C11: Both
A12: Robe | B12: =FALSE() -> 0 | C12: Both
A14: GROOM SUITE
A15: Item | B15: Packed | C15: Assigned To | D15: Notes
A16: Suit or tuxedo | B16: =FALSE() -> FALSE | C16: Both
A17: Shoes | B17: =FALSE() -> 0 | C17: Both
A18: Tie or bow tie | B18: =FALSE() -> 0 | C18: Both
A19: Cufflinks | B19: =FALSE() -> 0 | C19: Both
A20: Belt | B20: =FALSE() -> 0 | C20: Both
A21: Socks | B21: =FALSE() -> 0 | C21: Both
A22: Watch | B22: =FALSE() -> 0 | C22: Both
A24: CEREMONY
A25: Item | B25: Packed | C25: Assigned To | D25: Notes
A26: Vows | B26: =FALSE() -> FALSE | C26: Both
A27: Rings | B27: =FALSE() -> 0 | C27: Both
A28: Marriage license | B28: =FALSE() -> 0 | C28: Both
A29: Unity ceremony items | B29: =FALSE() -> 0 | C29: Both
A30: Programs | B30: =FALSE() -> 0 | C30: Both
A32: RECEPTION
A33: Item | B33: Packed | C33: Assigned To | D33: Notes
A34: Guest book and pen | B34: =FALSE() -> FALSE | C34: Both
A35: Card box | B35: =FALSE() -> 0 | C35: Both
A36: Table numbers | B36: =FALSE() -> 0 | C36: Both
A37: Place cards | B37: =FALSE() -> 0 | C37: Both
A38: Cake serving set | B38: =FALSE() -> 0 | C38: Both
A39: Toasting flutes | B39: =FALSE() -> 0 | C39: Both
A41: EMERGENCY KIT
A42: Item | B42: Packed | C42: Assigned To | D42: Notes
A43: Safety pins | B43: =FALSE() -> FALSE | C43: Both
A44: Stain remover | B44: =FALSE() -> 0 | C44: Both
A45: Sewing kit | B45: =FALSE() -> 0 | C45: Both
...

Sheet Wedding Budget
A1: WEDDING BUDGET
A3: TOTAL BUDGET | C3: LEFT TO BUDGET | E3: TOTAL SPENT | G3: LEFT TO SPEND | I3: VENDOR PAYMENTS LEFT
A4: =B13 -> 21000 | C4: =B13-C32 -> 1400 | E4: =D32 -> 17900 | G4: =B13-D32 -> 3100 | I4: =SUMPRODUCT((A36:A75<>"")*(F36:F75<>"Paid")*D36:D75) -> 1600
A6: BUDGET FUNDING
A7: Contributor | B7: Amount
A8: Bride and Groom Savings | B8: 12000
A9: Bride's Parents | B9: 5000
A10: Groom's Parents | B10: 4000
A11: Other Family | B11: 0
A12: Other | B12: 0
A13: Total Budget | B13: =SUM(B8:B12) -> 21000
A15: EXPENSE SUMMARY
A16: Category | B16: Vendor / Subcategory | C16: Budget | D16: Actual | E16: Left
A17: Venue | B17: =IFERROR(INDEX('Vendor Selection'!$C$7:$C$96,MATCH(1,('Vendor Selection'!$B$7:$B$96=$A17)*('Vendor Selection'!$A$7:$A$96="Yes"),0)),"") -> Willow Creek Barn | C17: 6000 | D17: =IFERROR(SUMIFS('Vendor Selection'!$G$7:$G$96,'Vendor Selection'!$B$7:$B$96,$A17,'Vendor Selection'!$A$7:$A$96,"Yes"),0) -> 8500 | E17: =C17-D17 -> -2500
A18: Catering | B18: =IFERROR(INDEX('Vendor Selection'!$C$7:$C$96,MATCH(1,('Vendor Selection'!$B$7:$B$96=$A18)*('Vendor Selection'!$A$7:$A$96="Yes"),0)),"") -> Copper Table Catering | C18: 4200 | D18: =IFERROR(SUMIFS('Vendor Selection'!$G$7:$G$96,'Vendor Selection'!$B$7:$B$96,$A18,'Vendor Selection'!$A$7:$A$96,"Yes"),0) -> 6200 | E18: =C18-D18 -> -2000
A19: Photography | B19: =IFERROR(INDEX('Vendor Selection'!$C$7:$C$96,MATCH(1,('Vendor Selection'!$B$7:$B$96=$A19)*('Vendor Selection'!$A$7:$A$96="Yes"),0)),"") -> Golden Hour Studio | C19: 3200 | D19: =IFERROR(SUMIFS('Vendor Selection'!$G$7:$G$96,'Vendor Selection'!$B$7:$B$96,$A19,'Vendor Selection'!$A$7:$A$96,"Yes"),0) -> 3200 | E19: =C19-D19 -> 0
A20: Videography | B20: =IFERROR(INDEX('Vendor Selection'!$C$7:$C$96,MATCH(1,('Vendor Selection'!$B$7:$B$96=$A20)*('Vendor Selection'!$A$7:$A$96="Yes"),0)),"") | C20: 1500 | D20: =IFERROR(SUMIFS('Vendor Selection'!$G$7:$G$96,'Vendor Selection'!$B$7:$B$96,$A20,'Vendor Selection'!$A$7:$A$96,"Yes"),0) -> 0 | E20: =C20-D20 -> 1500
A21: Florist | B21: =IFERROR(INDEX('Vendor Selection'!$C$7:$C$96,MATCH(1,('Vendor Selection'!$B$7:$B$96=$A21)*('Vendor Selection'!$A$7:$A$96="Yes"),0)),"") | C21: 900 | D21: =IFERROR(SUMIFS('Vendor Selection'!$G$7:$G$96,'Vendor Selection'!$B$7:$B$96,$A21,'Vendor Selection'!$A$7:$A$96,"Yes"),0) -> 0 | E21: =C21-D21 -> 900
A22: DJ/Band | B22: =IFERROR(INDEX('Vendor Selection'!$C$7:$C$96,MATCH(1,('Vendor Selection'!$B$7:$B$96=$A22)*('Vendor Selection'!$A$7:$A$96="Yes"),0)),"") | C22: 800 | D22: =IFERROR(SUMIFS('Vendor Selection'!$G$7:$G$96,'Vendor Selection'!$B$7:$B$96,$A22,'Vendor Selection'!$A$7:$A$96,"Yes"),0) -> 0 | E22: =C22-D22 -> 800
A23: Officiant | B23: =IFERROR(INDEX('Vendor Selection'!$C$7:$C$96,MATCH(1,('Vendor Selection'!$B$7:$B$96=$A23)*('Vendor Selection'!$A$7:$A$96="Yes"),0)),"") | C23: 400 | D23: =IFERROR(SUMIFS('Vendor Selection'!$G$7:$G$96,'Vendor Selection'!$B$7:$B$96,$A23,'Vendor Selection'!$A$7:$A$96,"Yes"),0) -> 0 | E23: =C23-D23 -> 400
A24: Rentals | B24: =IFERROR(INDEX('Vendor Selection'!$C$7:$C$96,MATCH(1,('Vendor Selection'!$B$7:$B$96=$A24)*('Vendor Selection'!$A$7:$A$96="Yes"),0)),"") | C24: 500 | D24: =IFERROR(SUMIFS('Vendor Selection'!$G$7:$G$96,'Vendor Selection'!$B$7:$B$96,$A24,'Vendor Selection'!$A$7:$A$96,"Yes"),0) -> 0 | E24: =C24-D24 -> 500
A25: Decor | B25: =IFERROR(INDEX('Vendor Selection'!$C$7:$C$96,MATCH(1,('Vendor Selection'!$B$7:$B$96=$A25)*('Vendor Selection'!$A$7:$A$96="Yes"),0)),"") | C25: 400 | D25: =IFERROR(SUMIFS('Vendor Selection'!$G$7:$G$96,'Vendor Selection'!$B$7:$B$96,$A25,'Vendor Selection'!$A$7:$A$96,"Yes"),0) -> 0 | E25: =C25-D25 -> 400
A26: Hair & Makeup | B26: =IFERROR(INDEX('Vendor Selection'!$C$7:$C$96,MATCH(1,('Vendor Selection'!$B$7:$B$96=$A26)*('Vendor Selection'!$A$7:$A$96="Yes"),0)),"") | C26: 350 | D26: =IFERROR(SUMIFS('Vendor Selection'!$G$7:$G$96,'Vendor Selection'!$B$7:$B$96,$A26,'Vendor Selection'!$A$7:$A$96,"Yes"),0) -> 0 | E26: =C26-D26 -> 350
A27: Transportation | B27: =IFERROR(INDEX('Vendor Selection'!$C$7:$C$96,MATCH(1,('Vendor Selection'!$B$7:$B$96=$A27)*('Vendor Selection'!$A$7:$A$96="Yes"),0)),"") | C27: 250 | D27: =IFERROR(SUMIFS('Vendor Selection'!$G$7:$G$96,'Vendor Selection'!$B$7:$B$96,$A27,'Vendor Selection'!$A$7:$A$96,"Yes"),0) -> 0 | E27: =C27-D27 -> 250
A28: Cake | B28: =IFERROR(INDEX('Vendor Selection'!$C$7:$C$96,MATCH(1,('Vendor Selection'!$B$7:$B$96=$A28)*('Vendor Selection'!$A$7:$A$96="Yes"),0)),"") | C28: 350 | D28: =IFERROR(SUMIFS('Vendor Selection'!$G$7:$G$96,'Vendor Selection'!$B$7:$B$96,$A28,'Vendor Selection'!$A$7:$A$96,"Yes"),0) -> 0 | E28: =C28-D28 -> 350
... A31: Lighting | B31: =IFERROR(INDEX('Vendor Selection'!$C$7:$C$96,MATCH(1,('Vendor Selection'!$B$7:$B$96=$A31)*('Vendor Selection'!$A$7:$A$96="Yes"),0)),"") | C31: 250 | D31: =IFERROR(SUMIFS('Vendor Selection'!$G$7:$G$96,'Vendor Selection'!$B$7:$B$96,$A31,'Vendor Selection'!$A$7:$A$96,"Yes"),0) -> 0 | E31: =C31-D31 -> 250
A32: Total | C32: =SUM(C17:C31) -> 19600 | D32: =SUM(D17:D31) -> 17900 | E32: =SUM(E17:E31) -> 1700
A34: PAYMENT SCHEDULE AND LOG | I34: Reminder: payments turn red once past due and unpaid.
A35: Type | B35: Vendor Name | C35: Due Date | D35: Amount | E35: Paid Date | F35: Status | G35: Notes
A36: Deposit | B36: Willow Creek Barn | C36: ='Get Started'!$C$4+(-270) -> 46282 | D36: 4250 | E36: ='Get Started'!$C$4+(-260) -> 46292 | F36: =IF(E36<>"","Paid",IF(C36<TODAY(),"Overdue",IF(C36<=TODAY()+14,"Due Soon","Not Due"))) -> Paid
A37: Deposit | B37: Copper Table Catering | C37: ='Get Started'!$C$4+(-240) -> 46312 | D37: 3100 | E37: ='Get Started'!$C$4+(-230) -> 46322 | F37: =IF(E37<>"","Paid",IF(C37<TODAY(),"Overdue",IF(C37<=TODAY()+14,"Due Soon","Not Due"))) -> Paid
A38: Progress Payment | B38: Golden Hour Studio | C38: ='Get Started'!$C$4+(-120) -> 46432 | D38: 1600 | F38: =IF(E38<>"","Paid",IF(C38<TODAY(),"Overdue",IF(C38<=TODAY()+14,"Due Soon","Not Due"))) -> Not Due
F39: =IF(E39<>"","Paid",IF(AND(C39<>"",C39<TODAY()),"Overdue",IF(AND(C39<>"",C39<=TODAY()+14),"Due Soon",IF(C39<>"","Not Due",""))))
F40: =IF(E40<>"","Paid",IF(AND(C40<>"",C40<TODAY()),"Overdue",IF(AND(C40<>"",C40<=TODAY()+14),"Due Soon",IF(C40<>"","Not Due",""))))
F41: =IF(E41<>"","Paid",IF(AND(C41<>"",C41<TODAY()),"Overdue",IF(AND(C41<>"",C41<=TODAY()+14),"Due Soon",IF(C41<>"","Not Due",""))))
F42: =IF(E42<>"","Paid",IF(AND(C42<>"",C42<TODAY()),"Overdue",IF(AND(C42<>"",C42<=TODAY()+14),"Due Soon",IF(C42<>"","Not Due",""))))
F43: =IF(E43<>"","Paid",IF(AND(C43<>"",C43<TODAY()),"Overdue",IF(AND(C43<>"",C43<=TODAY()+14),"Due Soon",IF(C43<>"","Not Due",""))))
F44: =IF(E44<>"","Paid",IF(AND(C44<>"",C44<TODAY()),"Overdue",IF(AND(C44<>"",C44<=TODAY()+14),"Due Soon",IF(C44<>"","Not Due",""))))
F45: =IF(E45<>"","Paid",IF(AND(C45<>"",C45<TODAY()),"Overdue",IF(AND(C45<>"",C45<=TODAY()+14),"Due Soon",IF(C45<>"","Not Due",""))))
F46: =IF(E46<>"","Paid",IF(AND(C46<>"",C46<TODAY()),"Overdue",IF(AND(C46<>"",C46<=TODAY()+14),"Due Soon",IF(C46<>"","Not Due",""))))
...

Sheet Vendor Selection
A1: VENDOR SELECTION AND RESEARCH
A3: SELECTION PROGRESS | C3: TOTAL COST | E3: VENDORS FINALIZED | L3: Category | M3: Cost
A4: =COUNTIFS(A7:A96,"Yes")/COUNTIF(B7:B96,"<>") -> 0.6 | C4: =SUMIFS(G7:G96,A7:A96,"Yes") -> 17900 | E4: =COUNTIFS(A7:A96,"Yes") -> 3 | L4: Venue | M4: =SUMIFS($G$7:$G$96,$B$7:$B$96,L4,$A$7:$A$96,"Yes") -> 8500
L5: Catering | M5: =SUMIFS($G$7:$G$96,$B$7:$B$96,L5,$A$7:$A$96,"Yes") -> 6200
A6: Final | B6: Category | C6: Name | D6: Contact | E6: Email | F6: Package | G6: Amount | H6: Availability | I6: Rating (1-5) | J6: Notes | L6: Photography | M6: =SUMIFS($G$7:$G$96,$B$7:$B$96,L6,$A$7:$A$96,"Yes") -> 3200
A7: Yes | B7: Venue | C7: Willow Creek Barn | D7: 555-0101 | E7: info@willowcreekbarn.com | F7: Full Day Rental | G7: 8500 | H7: Confirmed | I7: 5 | J7: Holds 200 guests, includes tables and chairs | L7: Videography | M7: =SUMIFS($G$7:$G$96,$B$7:$B$96,L7,$A$7:$A$96,"Yes") -> 0
A8: Yes | B8: Catering | C8: Copper Table Catering | D8: 555-0102 | E8: hello@coppertable.com | F8: Plated Dinner, 3 Course | G8: 6200 | H8: Confirmed | I8: 5 | J8: Tasting scheduled, great reviews | L8: Florist | M8: =SUMIFS($G$7:$G$96,$B$7:$B$96,L8,$A$7:$A$96,"Yes") -> 0
A9: Yes | B9: Photography | C9: Golden Hour Studio | D9: 555-0103 | E9: book@goldenhourstudio.com | F9: 8 Hour Coverage | G9: 3200 | H9: Confirmed | I9: 5 | J9: Second shooter included | L9: DJ/Band | M9: =SUMIFS($G$7:$G$96,$B$7:$B$96,L9,$A$7:$A$96,"Yes") -> 0
A10: No | B10: Videography | C10: Storyframe Films | D10: 555-0104 | E10: team@storyframefilms.com | F10: Highlight Reel | G10: 2400 | H10: Pending | I10: 4 | J10: Waiting on final quote | L10: Officiant | M10: =SUMIFS($G$7:$G$96,$B$7:$B$96,L10,$A$7:$A$96,"Yes") -> 0
A11: No | B11: Florist | C11: Petal and Vine | D11: 555-0105 | E11: orders@petalandvine.com | F11: Full Florals Package | G11: 2100 | H11: Pending | I11: 4 | L11: Rentals | M11: =SUMIFS($G$7:$G$96,$B$7:$B$96,L11,$A$7:$A$96,"Yes") -> 0
A12: No | L12: Decor | M12: =SUMIFS($G$7:$G$96,$B$7:$B$96,L12,$A$7:$A$96,"Yes") -> 0
A13: No | L13: Hair & Makeup | M13: =SUMIFS($G$7:$G$96,$B$7:$B$96,L13,$A$7:$A$96,"Yes") -> 0
A14: No | L14: Transportation | M14: =SUMIFS($G$7:$G$96,$B$7:$B$96,L14,$A$7:$A$96,"Yes") -> 0
A15: No | L15: Cake | M15: =SUMIFS($G$7:$G$96,$B$7:$B$96,L15,$A$7:$A$96,"Yes") -> 0
A16: No | L16: Stationery | M16: =SUMIFS($G$7:$G$96,$B$7:$B$96,L16,$A$7:$A$96,"Yes") -> 0
A17: No | L17: Favors | M17: =SUMIFS($G$7:$G$96,$B$7:$B$96,L17,$A$7:$A$96,"Yes") -> 0
A18: No | L18: Lighting | M18: =SUMIFS($G$7:$G$96,$B$7:$B$96,L18,$A$7:$A$96,"Yes") -> 0
A19: No
A20: No
A21: No
A22: No
A23: No
A24: No
A25: No
A26: No
A27: No
A28: No
A29: No
A30: No
... A96: No

Sheet Venue Comparison
A1: VENUE COMPARISON
A3: Field | B3: Venue 1 | C3: Venue 2 | D3: Venue 3 | E3: Venue 4 | F3: Venue 5
A4: Name
A5: Photo Placeholder | B5: [ photo ] | C5: [ photo ] | D5: [ photo ] | E5: [ photo ] | F5: [ photo ]
A6: Contact Info
A7: Capacity
A8: Availability
A9: Venue Fee
A10: Ceremony Fee
A11: Reception Fee
A12: Setup Fee
A13: Cleanup Fee
A14: Service Charge
A15: Food and Drinks
A16: Alcohol
A17: Cake Cutting Fee
A18: Total | B18: =B9+B10+B11+B12+B13+B14+B15+B16+B17 -> 0 | C18: =C9+C10+C11+C12+C13+C14+C15+C16+C17 -> 0 | D18: =D9+D10+D11+D12+D13+D14+D15+D16+D17 -> 0 | E18: =E9+E10+E11+E12+E13+E14+E15+E16+E17 -> 0 | F18: =F9+F10+F11+F12+F13+F14+F15+F16+F17 -> 0
A19: Winner | B19: =IF(AND(B18<>0,B18=MIN(B18,C18,D18,E18,F18)),"Best Value","") | C19: =IF(AND(C18<>0,C18=MIN(B18,C18,D18,E18,F18)),"Best Value","") | D19: =IF(AND(D18<>0,D18=MIN(B18,C18,D18,E18,F18)),"Best Value","") | E19: =IF(AND(E18<>0,E18=MIN(B18,C18,D18,E18,F18)),"Best Value","") | F19: =IF(AND(F18<>0,F18=MIN(B18,C18,D18,E18,F18)),"Best Value","")

Sheet Food and Drinks
A1: FOOD AND DRINKS
A3: REHEARSAL DINNER
A4: APPETIZERS | I4: Event | J4: Total Cost
A5: Final | B5: Item | C5: Tasting Rating | D5: Amount | E5: Qty | F5: Total | I5: Rehearsal Dinner | J5: =B32 -> 0
A6: =FALSE() -> 0 | D6: 0 | E6: 1 | F6: =D6*E6 -> 0 | I6: Reception | J6: =B64 -> 0
A7: =FALSE() -> 0 | D7: 0 | E7: 1 | F7: =D7*E7 -> 0
A8: =FALSE() -> 0 | D8: 0 | E8: 1 | F8: =D8*E8 -> 0
A9: =FALSE() -> 0 | D9: 0 | E9: 1 | F9: =D9*E9 -> 0
A11: MAIN COURSE
A12: Final | B12: Item | C12: Tasting Rating | D12: Amount | E12: Qty | F12: Total
A13: =FALSE() -> 0 | D13: 0 | E13: 1 | F13: =D13*E13 -> 0
A14: =FALSE() -> 0 | D14: 0 | E14: 1 | F14: =D14*E14 -> 0
A15: =FALSE() -> 0 | D15: 0 | E15: 1 | F15: =D15*E15 -> 0
A16: =FALSE() -> 0 | D16: 0 | E16: 1 | F16: =D16*E16 -> 0
A18: DESSERTS
A19: Final | B19: Item | C19: Tasting Rating | D19: Amount | E19: Qty | F19: Total
A20: =FALSE() -> 0 | D20: 0 | E20: 1 | F20: =D20*E20 -> 0
A21: =FALSE() -> 0 | D21: 0 | E21: 1 | F21: =D21*E21 -> 0
A22: =FALSE() -> 0 | D22: 0 | E22: 1 | F22: =D22*E22 -> 0
A23: =FALSE() -> 0 | D23: 0 | E23: 1 | F23: =D23*E23 -> 0
A25: DRINKS
A26: Final | B26: Item | C26: Tasting Rating | D26: Amount | E26: Qty | F26: Total
A27: =FALSE() -> 0 | D27: 0 | E27: 1 | F27: =D27*E27 -> 0
A28: =FALSE() -> 0 | D28: 0 | E28: 1 | F28: =D28*E28 -> 0
A29: =FALSE() -> 0 | D29: 0 | E29: 1 | F29: =D29*E29 -> 0
A30: =FALSE() -> 0 | D30: 0 | E30: 1 | F30: =D30*E30 -> 0
A32: Rehearsal Dinner Total Cost | B32: =SUM(F6:F9)+SUM(F13:F16)+SUM(F20:F23)+SUM(F27:F30) -> 0
A35: RECEPTION
A36: APPETIZERS
A37: Final | B37: Item | C37: Tasting Rating | D37: Amount | E37: Qty | F37: Total
A38: =FALSE() -> 0 | D38: 0 | E38: 1 | F38: =D38*E38 -> 0
A39: =FALSE() -> 0 | D39: 0 | E39: 1 | F39: =D39*E39 -> 0
A40: =FALSE() -> 0 | D40: 0 | E40: 1 | F40: =D40*E40 -> 0
A41: =FALSE() -> 0 | D41: 0 | E41: 1 | F41: =D41*E41 -> 0
A43: MAIN COURSE
A44: Final | B44: Item | C44: Tasting Rating | D44: Amount | E44: Qty | F44: Total
A45: =FALSE() -> 0 | D45: 0 | E45: 1 | F45: =D45*E45 -> 0
A46: =FALSE() -> 0 | D46: 0 | E46: 1 | F46: =D46*E46 -> 0
A47: =FALSE() -> 0 | D47: 0 | E47: 1 | F47: =D47*E47 -> 0
A48: =FALSE() -> 0 | D48: 0 | E48: 1 | F48: =D48*E48 -> 0
...

Sheet Photo and Video Shot List
A1: PHOTO AND VIDEO SHOT LIST
A3: PHOTOGRAPHY
A4: GETTING READY
A5: Captured | B5: Shot | C5: Notes
A6: =FALSE() -> 0 | B6: Dress on hanger
A7: =FALSE() -> 0 | B7: Rings close up
A8: =FALSE() -> 0 | B8: Invitation suite flat lay
A9: =FALSE() -> 0 | B9: Bride getting into dress
A10: =FALSE() -> 0 | B10: Groom getting dressed
A11: =FALSE() -> 0 | B11: Bridesmaids helping bride
A12: =FALSE() -> 0 | B12: Groomsmen candid moments
A13: =FALSE() -> 0 | B13: First look with parent
A15: CEREMONY
A16: Captured | B16: Shot | C16: Notes
A17: =FALSE() -> 0 | B17: Ceremony site before guests arrive
A18: =FALSE() -> 0 | B18: Guests arriving
A19: =FALSE() -> 0 | B19: Processional
A20: =FALSE() -> 0 | B20: Bride's entrance
A21: =FALSE() -> 0 | B21: Vows exchange
A22: =FALSE() -> 0 | B22: Ring exchange
A23: =FALSE() -> 0 | B23: First kiss
A24: =FALSE() -> 0 | B24: Recessional
A26: FAMILY FORMALS
A27: Captured | B27: Shot | C27: Notes
A28: =FALSE() -> 0 | B28: Immediate family with couple
A29: =FALSE() -> 0 | B29: Extended family with couple
A30: =FALSE() -> 0 | B30: Bridal party with couple
A31: =FALSE() -> 0 | B31: Bride with her parents
A32: =FALSE() -> 0 | B32: Groom with his parents
A33: =FALSE() -> 0 | B33: Grandparents with couple
A35: RECEPTION
A36: Captured | B36: Shot | C36: Notes
A37: =FALSE() -> 0 | B37: Reception decor detail shots
A38: =FALSE() -> 0 | B38: Grand entrance
A39: =FALSE() -> 0 | B39: First dance
A40: =FALSE() -> 0 | B40: Parent dances
A41: =FALSE() -> 0 | B41: Toasts and speeches
A42: =FALSE() -> 0 | B42: Cake cutting
A43: =FALSE() -> 0 | B43: Bouquet toss
A44: =FALSE() -> 0 | B44: Garter toss
...

Sheet Guest List
A1: GUEST LIST
A3: TOTAL GUESTS | C3: SAVE THE DATE SENT | E3: INVITATION SENT | G3: CONFIRMED | I3: RSVP DEADLINE | K3: DAYS LEFT TO RSVP | N3: Guest Of | O3: Count
A4: =COUNTA(A7:A206) -> 6 | C4: =COUNTIFS(D7:D206,TRUE()) -> 6 | E4: =COUNTIFS(E7:E206,TRUE()) -> 6 | G4: =COUNTIFS(F7:F206,"Yes") -> 2 | I4: ='Get Started'!$C$4-30 -> 46522 | K4: =I4-TODAY() -> 270 | N4: Bride | O4: =COUNTIFS($B$7:$B$206,N4) -> 2
N5: Groom | O5: =COUNTIFS($B$7:$B$206,N5) -> 2
A6: Name | B6: Guest Tag | C6: Child | D6: Save the Date | E6: Invitation | F6: RSVP | G6: Meal Preference | H6: Rehearsal Dinner | I6: Contact | J6: Email | K6: Address | N6: Both | O6: =COUNTIFS($B$7:$B$206,N6) -> 2
A7: Alex Johnson | B7: Bride | C7: =FALSE() -> 0 | D7: =TRUE() -> 1 | E7: =TRUE() -> 1 | F7: Yes | G7: Chicken | H7: =FALSE() -> 0
A8: Sam Rivera | B8: Groom | C8: =FALSE() -> 0 | D8: =TRUE() -> 1 | E8: =TRUE() -> 1 | F8: No | G8: Beef | H8: =FALSE() -> 0 | N8: Guest Type | O8: Count
A9: Jamie Lee | B9: Both | C9: =FALSE() -> 0 | D9: =TRUE() -> 1 | E9: =TRUE() -> 1 | F9: Awaited | G9: Fish | H9: =FALSE() -> 0 | N9: Chicken | O9: =COUNTIFS($G$7:$G$206,N9) -> 1
A10: Morgan Kim | B10: Bride | C10: =FALSE() -> 0 | D10: =TRUE() -> 1 | E10: =TRUE() -> 1 | F10: Yes | G10: Vegetarian | H10: =FALSE() -> 0 | N10: Beef | O10: =COUNTIFS($G$7:$G$206,N10) -> 1
A11: Taylor Brooks | B11: Groom | C11: =FALSE() -> 0 | D11: =TRUE() -> 1 | E11: =TRUE() -> 1 | F11: No | G11: Vegan | H11: =FALSE() -> 0 | N11: Fish | O11: =COUNTIFS($G$7:$G$206,N11) -> 1
A12: Casey Adams | B12: Both | C12: =FALSE() -> 0 | D12: =TRUE() -> 1 | E12: =TRUE() -> 1 | F12: Awaited | G12: Kids Meal | H12: =FALSE() -> 0 | N12: Vegetarian | O12: =COUNTIFS($G$7:$G$206,N12) -> 1
C13: =FALSE() -> 0 | D13: =FALSE() -> 0 | E13: =FALSE() -> 0 | H13: =FALSE() -> 0 | N13: Vegan | O13: =COUNTIFS($G$7:$G$206,N13) -> 1
C14: =FALSE() -> 0 | D14: =FALSE() -> 0 | E14: =FALSE() -> 0 | H14: =FALSE() -> 0 | N14: Kids Meal | O14: =COUNTIFS($G$7:$G$206,N14) -> 1
C15: =FALSE() -> 0 | D15: =FALSE() -> 0 | E15: =FALSE() -> 0 | H15: =FALSE() -> 0 | N15: No Preference | O15: =COUNTIFS($G$7:$G$206,N15) -> 0
C16: =FALSE() -> 0 | D16: =FALSE() -> 0 | E16: =FALSE() -> 0 | H16: =FALSE() -> 0
C17: =FALSE() -> 0 | D17: =FALSE() -> 0 | E17: =FALSE() -> 0 | H17: =FALSE() -> 0
C18: =FALSE() -> 0 | D18: =FALSE() -> 0 | E18: =FALSE() -> 0 | H18: =FALSE() -> 0
C19: =FALSE() -> 0 | D19: =FALSE() -> 0 | E19: =FALSE() -> 0 | H19: =FALSE() -> 0
C20: =FALSE() -> 0 | D20: =FALSE() -> 0 | E20: =FALSE() -> 0 | H20: =FALSE() -> 0
C21: =FALSE() -> 0 | D21: =FALSE() -> 0 | E21: =FALSE() -> 0 | H21: =FALSE() -> 0
C22: =FALSE() -> 0 | D22: =FALSE() -> 0 | E22: =FALSE() -> 0 | H22: =FALSE() -> 0
C23: =FALSE() -> 0 | D23: =FALSE() -> 0 | E23: =FALSE() -> 0 | H23: =FALSE() -> 0
C24: =FALSE() -> 0 | D24: =FALSE() -> 0 | E24: =FALSE() -> 0 | H24: =FALSE() -> 0
C25: =FALSE() -> 0 | D25: =FALSE() -> 0 | E25: =FALSE() -> 0 | H25: =FALSE() -> 0
C26: =FALSE() -> 0 | D26: =FALSE() -> 0 | E26: =FALSE() -> 0 | H26: =FALSE() -> 0
C27: =FALSE() -> 0 | D27: =FALSE() -> 0 | E27: =FALSE() -> 0 | H27: =FALSE() -> 0
... C206: =FALSE() -> 0 | D206: =FALSE() -> 0 | E206: =FALSE() -> 0 | H206: =FALSE() -> 0

Sheet Reception Seating Plan
A1: RECEPTION SEATING PLAN
A3: TOTAL SEATS | C3: CONFIRMED GUESTS | E3: CONFIRMED SEATS | G3: TENTATIVE SEATS | I3: REMAINING SEATS | K3: CONFIRMED TO BE SEATED
A4: =10*8 -> 80 | C4: =COUNTIFS('Guest List'!$F$7:$F$206,"Yes") -> 2 | E4: =COUNTIFS(D10:D29,"<>") -> 0 | G4: =COUNTIFS('Guest List'!$F$7:$F$206,"Awaited") -> 2 | I4: =A4-E4 -> 80 | K4: =IFERROR(E4/C4,0) -> 0
A6: Filter reference: Guest Tag / RSVP status are pulled live from the Guest List tab below.
A8: GUESTS WITHOUT A SEAT
A9: Name | B9: Guest Tag | C9: RSVP | D9: Table #
A10: =IF('Guest List'!$F7="Yes",'Guest List'!$A7,"") -> Alex Johnson | B10: =IF(A10<>"",'Guest List'!$B7,"") -> Bride | C10: =IF(A10<>"",'Guest List'!$F7,"") -> Yes
A11: =IF('Guest List'!$F8="Yes",'Guest List'!$A8,"") | B11: =IF(A11<>"",'Guest List'!$B8,"") | C11: =IF(A11<>"",'Guest List'!$F8,"")
A12: =IF('Guest List'!$F9="Yes",'Guest List'!$A9,"") | B12: =IF(A12<>"",'Guest List'!$B9,"") | C12: =IF(A12<>"",'Guest List'!$F9,"")
A13: =IF('Guest List'!$F10="Yes",'Guest List'!$A10,"") -> Morgan Kim | B13: =IF(A13<>"",'Guest List'!$B10,"") -> Bride | C13: =IF(A13<>"",'Guest List'!$F10,"") -> Yes
A14: =IF('Guest List'!$F11="Yes",'Guest List'!$A11,"") | B14: =IF(A14<>"",'Guest List'!$B11,"") | C14: =IF(A14<>"",'Guest List'!$F11,"")
A15: =IF('Guest List'!$F12="Yes",'Guest List'!$A12,"") | B15: =IF(A15<>"",'Guest List'!$B12,"") | C15: =IF(A15<>"",'Guest List'!$F12,"")
A16: =IF('Guest List'!$F13="Yes",'Guest List'!$A13,"") | B16: =IF(A16<>"",'Guest List'!$B13,"") | C16: =IF(A16<>"",'Guest List'!$F13,"")
A17: =IF('Guest List'!$F14="Yes",'Guest List'!$A14,"") | B17: =IF(A17<>"",'Guest List'!$B14,"") | C17: =IF(A17<>"",'Guest List'!$F14,"")
A18: =IF('Guest List'!$F15="Yes",'Guest List'!$A15,"") | B18: =IF(A18<>"",'Guest List'!$B15,"") | C18: =IF(A18<>"",'Guest List'!$F15,"")
A19: =IF('Guest List'!$F16="Yes",'Guest List'!$A16,"") | B19: =IF(A19<>"",'Guest List'!$B16,"") | C19: =IF(A19<>"",'Guest List'!$F16,"")
A20: =IF('Guest List'!$F17="Yes",'Guest List'!$A17,"") | B20: =IF(A20<>"",'Guest List'!$B17,"") | C20: =IF(A20<>"",'Guest List'!$F17,"")
A21: =IF('Guest List'!$F18="Yes",'Guest List'!$A18,"") | B21: =IF(A21<>"",'Guest List'!$B18,"") | C21: =IF(A21<>"",'Guest List'!$F18,"")
... A29: =IF('Guest List'!$F26="Yes",'Guest List'!$A26,"") | B29: =IF(A29<>"",'Guest List'!$B26,"") | C29: =IF(A29<>"",'Guest List'!$F26,"")
A31: TABLE BLOCKS
A32: Table 1 | G32: Table 2
A33: Capacity | B33: 8 | C33: Confirmed Seats | D33: =COUNTIFS(A36:A43,"<>") -> 0 | G33: Capacity | H33: 8 | I33: Confirmed Seats | J33: =COUNTIFS(A36:A43,"<>") -> 0
A34: Guest Tags Included | B34: =_xlfn.TEXTJOIN(", ",TRUE(),IF(COUNTIF(B36:B43,"Bride")>0,"Bride",""),IF(COUNTIF(B36:B43,"Groom")>0,"Groom",""),IF(COUNTIF(B36:B43,"Both")>0,"Both","")) | G34: Guest Tags Included | H34: =_xlfn.TEXTJOIN(", ",TRUE(),IF(COUNTIF(B36:B43,"Bride")>0,"Bride",""),IF(COUNTIF(B36:B43,"Groom")>0,"Groom",""),IF(COUNTIF(B36:B43,"Both")>0,"Both",""))
A35: Name | B35: Guest Tag | C35: # | G35: Name | H35: Guest Tag | I35: #
