Workbook
Name AsOfDate: 'Flexible Income Budget'!$B$66
Name BillingFrequencyList: Settings!$N$3:$N$5
Name CategoryList: Settings!$A$3:$A$82
Name CategoryTypeList: Settings!$B$3:$B$82
Name CurrencyList: Settings!$H$3:$H$7
Name GoalNameList: 'Savings & Debt Goal Tracker'!$J$6:$J$21
Name MonthList: Settings!$J$3:$J$14
Name PayFrequencyList: Settings!$F$3:$F$6
Name PeriodEnd: Example!$B$7
Name PeriodEnd: 'Flexible Income Budget'!$B$7
Name PeriodEnd: 'Paycheck Budget'!$B$7
Name PeriodStart: Example!$B$5
Name PeriodStart: 'Flexible Income Budget'!$B$5
Name PeriodStart: 'Paycheck Budget'!$B$5
Name SubCategoryList: Settings!$T$3:$T$10
Name TypeList: Settings!$D$3:$D$7
Name WeekStartList: Settings!$L$3:$L$4
Name YearList: Settings!$P$3:$P$9
Name YesNoList: Settings!$R$3:$R$4

Sheet Welcome
A1: Budget Planner
A2: A simple, automatic way to plan your money, no spreadsheet experience needed.
A4: Hi, welcome! This planner takes care of the math for you. You just fill in your numbers.
A6: This planner is built for Microsoft Excel (and Excel Online/OneDrive). It also works in Google Sheets once uploaded, though some conditional formatting and colors may shift slightly.
A8: How to Use This Planner
A9: 1. Make it yours first. Go to the Transactions Log tab and the Settings tab to add your own income sources, bill names, expense categories, savings goals, and debts. You only need to do this once. Everything else in the workbook updates automatically from this list.
A10: 2. Set your starting point. On the Paycheck Budget tab (or the Flexible Income Budget tab if your income varies), choose your Start Date and how often you get paid: Weekly, Biweekly, Semi-Monthly, or Monthly. You can start on any day, not just the 1st of the month.
A11: 3. Log everything in one place. Every time money comes in or goes out, add one line to the Transactions Log: the date, the category, the type (Bill, Expense, Saving, Debt, or Income), and the amount. This is the only place you enter numbers. Every other tab reads from this log automatically, so nothing needs to be typed twice.
A12: 4. Watch your dashboard update. The Paycheck Budget tab shows your "Amount Left to Spend," your income vs. bills vs. expenses vs. savings vs. debt, and simple charts. All of it updates the moment you add a transaction. You don't need to touch any formulas.
A13: 5. Add your bills once, and let the calendar do the rest. Log your bills as Type "Bill" in the Transactions Log with their due date, and they'll automatically appear on the Bill Calendar that month.
A14: 6. Track subscriptions and goals as bonuses. Use the Subscription Tracker to see what you're really paying for streaming, memberships, and software each month. Use the Savings & Debt Goal Tracker to watch progress toward specific goals (like a holiday fund or paying off a credit card) fill up visually.
A15: 7. Not sure where to start? Look at the Example tab. It's a fully filled-out sample month. If anything ever looks broken, compare it to the Example tab rather than guessing.
... A29: Quick guide: paycheck-based income → Paycheck Budget tab. Irregular or freelance income → Flexible Income Budget tab.

Sheet Example
A1: Example: A Filled-Out Month | G1: LEFT TO SPEND | I1: INCOME | J1: BILLS | K1: EXPENSES | L1: SAVINGS | M1: DEBT
A2: This tab shows what a real month looks like once it's filled in. It's just for reference. Your numbers go on the Paycheck Budget tab. If anything there ever looks broken, compare it to this tab. | G2: =E10 -> 233.03 | I2: =C20 -> 3850 | J2: =C32 -> 1942.97 | K2: =C44 -> 1049 | L2: =C53 -> 475 | M2: =C61 -> 150
N3: Chart data (auto — don't edit)
A4: Your Setup | D4: Cash Flow Summary | G4: ="Days left: "&IF(ISNUMBER(B7),MAX(B7-TODAY(),0),0) -> Days left: 0 | N4: Left to Spend | O4: =MAX(E10,0) -> 233.03
A5: Start Date | B5: 46023 | D5: Income | E5: =C20 -> 3850 | N5: Spent | O5: =C32+C44+C53+C61 -> 3616.97
A6: Pay Frequency | B6: Monthly | D6: Bills | E6: =-C32 -> -1942.97
A7: Budget Period End | B7: 46053 | D7: Expenses | E7: =-C44 -> -1049
A8: Currency | B8: USD | D8: Savings | E8: =-C53 -> -475 | N8: Bills | O8: =C32 -> 1942.97
D9: Debt | E9: =-C61 -> -150 | N9: Expenses | O9: =C44 -> 1049
D10: Amount Left to Spend | E10: =E5+E6+E7+E8+E9 -> 233.03 | I10: =E10 -> 233.03 | N10: Savings | O10: =C53 -> 475
N11: Debt | O11: =C61 -> 150
N12: Left to Spend | O12: =MAX(E10,0) -> 233.03
A14: Income Summary | B14: Budget | C14: Actual | D14: Above/Below Budget | E14: ✓
A15: =Settings!A3 -> Paycheck | B15: 3600 | C15: 3600 | D15: =C15-B15 -> 0 | N15: Category | O15: Actual
A16: =Settings!A4 -> Side Income | B16: 200 | C16: 150 | D16: =C16-B16 -> -50 | N16: =A36 -> Groceries | O16: =C36 -> 445
A17: =Settings!A5 -> Freelance Income | B17: 0 | C17: 100 | D17: =C17-B17 -> 100 | N17: =A37 -> Dining Out | O17: =C37 -> 187
A18: =Settings!A6 -> Bonus | B18: 0 | C18: 0 | D18: =C18-B18 -> 0 | N18: =A38 -> Transportation | O18: =C38 -> 95
A19: =Settings!A7 -> Other Income | B19: 0 | C19: 0 | D19: =C19-B19 -> 0 | N19: =A39 -> Entertainment | O19: =C39 -> 60
A20: Total Income | B20: =SUM(B15:B19) -> 3800 | C20: =SUM(C15:C19) -> 3850 | D20: =C20-B20 -> 50 | N20: =A40 -> Shopping | O20: =C40 -> 130
N21: =A41 -> Personal Care | O21: =C41 -> 45
N22: =A42 -> Household Supplies | O22: =C42 -> 35
A23: Bill Tracker | B23: Budget | C23: Actual | D23: Remaining | E23: ✓ | N23: =A43 -> Miscellaneous | O23: =C43 -> 52
A24: =Settings!A8 -> Rent or Mortgage | B24: 1200 | C24: 1200 | D24: =B24-C24 -> 0
A25: =Settings!A9 -> Electricity | B25: 90 | C25: 102 | D25: =B25-C25 -> -12
A26: =Settings!A10 -> Water | B26: 40 | C26: 38 | D26: =B26-C26 -> 2 | N26: Category | O26: Budget | P26: Actual
A27: =Settings!A11 -> Internet | B27: 60 | C27: 60 | D27: =B27-C27 -> 0 | N27: Income | O27: =B20 -> 3800 | P27: =C20 -> 3850
A28: =Settings!A12 -> Phone | B28: 50 | C28: 50 | D28: =B28-C28 -> 0 | N28: Bills | O28: =B32 -> 1930 | P28: =C32 -> 1942.97
A29: =Settings!A13 -> Car Payment | B29: 300 | C29: 300 | D29: =B29-C29 -> 0 | N29: Expenses | O29: =B44 -> 1000 | P29: =C44 -> 1049
A30: =Settings!A14 -> Insurance | B30: 150 | C30: 150 | D30: =B30-C30 -> 0 | N30: Savings | O30: =B53 -> 450 | P30: =C53 -> 475
A31: =Settings!A15 -> Subscriptions | B31: 40 | C31: 42.97 | D31: =B31-C31 -> -2.97 | N31: Debt | O31: =B61 -> 150 | P31: =C61 -> 150
A32: Total Bills | B32: =SUM(B24:B31) -> 1930 | C32: =SUM(C24:C31) -> 1942.97 | D32: =B32-C32 -> -12.97
A35: Expense Summary | B35: Budget | C35: Actual | D35: Remaining | E35: ✓
A36: =Settings!A16 -> Groceries | B36: 400 | C36: 445 | D36: =B36-C36 -> -45
A37: =Settings!A17 -> Dining Out | B37: 150 | C37: 187 | D37: =B37-C37 -> -37
A38: =Settings!A18 -> Transportation | B38: 120 | C38: 95 | D38: =B38-C38 -> 25
A39: =Settings!A19 -> Entertainment | B39: 80 | C39: 60 | D39: =B39-C39 -> 20
A40: =Settings!A20 -> Shopping | B40: 100 | C40: 130 | D40: =B40-C40 -> -30
A41: =Settings!A21 -> Personal Care | B41: 50 | C41: 45 | D41: =B41-C41 -> 5
A42: =Settings!A22 -> Household Supplies | B42: 40 | C42: 35 | D42: =B42-C42 -> 5
A43: =Settings!A23 -> Miscellaneous | B43: 60 | C43: 52 | D43: =B43-C43 -> 8
...

Sheet Paycheck Budget
A1: Paycheck Budget | G1: LEFT TO SPEND | I1: INCOME | J1: BILLS | K1: EXPENSES | L1: SAVINGS | M1: DEBT
A2: Your automatic budget dashboard. Log transactions on the Transactions Log tab and everything below updates on its own. | G2: =E10 -> 0 | I2: =C20 -> 0 | J2: =C32 -> 0 | K2: =C44 -> 0 | L2: =C53 -> 0 | M2: =C61 -> 0
N3: Chart data (auto — don't edit)
A4: Your Setup | D4: Cash Flow Summary | G4: ="Days left: "&IF(ISNUMBER(B7),MAX(B7-TODAY(),0),0) -> Days left: 16 | N4: Left to Spend | O4: =MAX(E10,0) -> 0
A5: Start Date | B5: 46235 | D5: Income | E5: =C20 -> 0 | N5: Spent | O5: =C32+C44+C53+C61 -> 0
A6: Pay Frequency | B6: Monthly | D6: Bills | E6: =-C32 -> 0
A7: Budget Period End | B7: 46265 | D7: Expenses | E7: =-C44 -> 0
A8: Currency | B8: USD | D8: Savings | E8: =-C53 -> 0 | N8: Bills | O8: =C32 -> 0
D9: Debt | E9: =-C61 -> 0 | N9: Expenses | O9: =C44 -> 0
D10: Amount Left to Spend | E10: =E5+E6+E7+E8+E9 -> 0 | I10: =E10 -> 0 | N10: Savings | O10: =C53 -> 0
N11: Debt | O11: =C61 -> 0
N12: Left to Spend | O12: =MAX(E10,0) -> 0
A14: Income Summary | B14: Budget | C14: Actual | D14: Above/Below Budget | E14: ✓
A15: =Settings!A3 -> Paycheck | C15: =SUMIFS(TransactionsLog[Amount],TransactionsLog[Category],$A15,TransactionsLog[Date],">="&PeriodStart,TransactionsLog[Date],"<="&PeriodEnd) -> 0 | D15: =C15-B15 -> 0 | N15: Category | O15: Actual
A16: =Settings!A4 -> Side Income | B16: 0 | C16: =SUMIFS(TransactionsLog[Amount],TransactionsLog[Category],$A16,TransactionsLog[Date],">="&PeriodStart,TransactionsLog[Date],"<="&PeriodEnd) -> 0 | D16: =C16-B16 -> 0 | N16: =A36 -> Groceries | O16: =C36 -> 0
A17: =Settings!A5 -> Freelance Income | B17: 0 | C17: =SUMIFS(TransactionsLog[Amount],TransactionsLog[Category],$A17,TransactionsLog[Date],">="&PeriodStart,TransactionsLog[Date],"<="&PeriodEnd) -> 0 | D17: =C17-B17 -> 0 | N17: =A37 -> Dining Out | O17: =C37 -> 0
A18: =Settings!A6 -> Bonus | B18: 0 | C18: =SUMIFS(TransactionsLog[Amount],TransactionsLog[Category],$A18,TransactionsLog[Date],">="&PeriodStart,TransactionsLog[Date],"<="&PeriodEnd) -> 0 | D18: =C18-B18 -> 0 | N18: =A38 -> Transportation | O18: =C38 -> 0
A19: =Settings!A7 -> Other Income | B19: 0 | C19: =SUMIFS(TransactionsLog[Amount],TransactionsLog[Category],$A19,TransactionsLog[Date],">="&PeriodStart,TransactionsLog[Date],"<="&PeriodEnd) -> 0 | D19: =C19-B19 -> 0 | N19: =A39 -> Entertainment | O19: =C39 -> 0
A20: Total Income | B20: =SUM(B15:B19) -> 0 | C20: =SUM(C15:C19) -> 0 | D20: =C20-B20 -> 0 | N20: =A40 -> Shopping | O20: =C40 -> 0
N21: =A41 -> Personal Care | O21: =C41 -> 0
N22: =A42 -> Household Supplies | O22: =C42 -> 0
A23: Bill Tracker | B23: Budget | C23: Actual | D23: Remaining | E23: ✓ | N23: =A43 -> Miscellaneous | O23: =C43 -> 0
A24: =Settings!A8 -> Rent or Mortgage | B24: 0 | C24: =SUMIFS(TransactionsLog[Amount],TransactionsLog[Category],$A24,TransactionsLog[Date],">="&PeriodStart,TransactionsLog[Date],"<="&PeriodEnd) -> 0 | D24: =B24-C24 -> 0
A25: =Settings!A9 -> Electricity | B25: 0 | C25: =SUMIFS(TransactionsLog[Amount],TransactionsLog[Category],$A25,TransactionsLog[Date],">="&PeriodStart,TransactionsLog[Date],"<="&PeriodEnd) -> 0 | D25: =B25-C25 -> 0
A26: =Settings!A10 -> Water | B26: 0 | C26: =SUMIFS(TransactionsLog[Amount],TransactionsLog[Category],$A26,TransactionsLog[Date],">="&PeriodStart,TransactionsLog[Date],"<="&PeriodEnd) -> 0 | D26: =B26-C26 -> 0 | N26: Category | O26: Budget | P26: Actual
A27: =Settings!A11 -> Internet | B27: 0 | C27: =SUMIFS(TransactionsLog[Amount],TransactionsLog[Category],$A27,TransactionsLog[Date],">="&PeriodStart,TransactionsLog[Date],"<="&PeriodEnd) -> 0 | D27: =B27-C27 -> 0 | N27: Income | O27: =B20 -> 0 | P27: =C20 -> 0
A28: =Settings!A12 -> Phone | B28: 0 | C28: =SUMIFS(TransactionsLog[Amount],TransactionsLog[Category],$A28,TransactionsLog[Date],">="&PeriodStart,TransactionsLog[Date],"<="&PeriodEnd) -> 0 | D28: =B28-C28 -> 0 | N28: Bills | O28: =B32 -> 0 | P28: =C32 -> 0
A29: =Settings!A13 -> Car Payment | B29: 0 | C29: =SUMIFS(TransactionsLog[Amount],TransactionsLog[Category],$A29,TransactionsLog[Date],">="&PeriodStart,TransactionsLog[Date],"<="&PeriodEnd) -> 0 | D29: =B29-C29 -> 0 | N29: Expenses | O29: =B44 -> 0 | P29: =C44 -> 0
A30: =Settings!A14 -> Insurance | B30: 0 | C30: =SUMIFS(TransactionsLog[Amount],TransactionsLog[Category],$A30,TransactionsLog[Date],">="&PeriodStart,TransactionsLog[Date],"<="&PeriodEnd) -> 0 | D30: =B30-C30 -> 0 | N30: Savings | O30: =B53 -> 0 | P30: =C53 -> 0
A31: =Settings!A15 -> Subscriptions | B31: 0 | C31: ='Subscription Tracker'!$C$4 -> 0 | D31: =B31-C31 -> 0 | N31: Debt | O31: =B61 -> 0 | P31: =C61 -> 0
A32: Total Bills | B32: =SUM(B24:B31) -> 0 | C32: =SUM(C24:C31) -> 0 | D32: =B32-C32 -> 0
A35: Expense Summary | B35: Budget | C35: Actual | D35: Remaining | E35: ✓
A36: =Settings!A16 -> Groceries | B36: 0 | C36: =SUMIFS(TransactionsLog[Amount],TransactionsLog[Category],$A36,TransactionsLog[Date],">="&PeriodStart,TransactionsLog[Date],"<="&PeriodEnd) -> 0 | D36: =B36-C36 -> 0
A37: =Settings!A17 -> Dining Out | B37: 0 | C37: =SUMIFS(TransactionsLog[Amount],TransactionsLog[Category],$A37,TransactionsLog[Date],">="&PeriodStart,TransactionsLog[Date],"<="&PeriodEnd) -> 0 | D37: =B37-C37 -> 0
A38: =Settings!A18 -> Transportation | B38: 0 | C38: =SUMIFS(TransactionsLog[Amount],TransactionsLog[Category],$A38,TransactionsLog[Date],">="&PeriodStart,TransactionsLog[Date],"<="&PeriodEnd) -> 0 | D38: =B38-C38 -> 0
A39: =Settings!A19 -> Entertainment | B39: 0 | C39: =SUMIFS(TransactionsLog[Amount],TransactionsLog[Category],$A39,TransactionsLog[Date],">="&PeriodStart,TransactionsLog[Date],"<="&PeriodEnd) -> 0 | D39: =B39-C39 -> 0
A40: =Settings!A20 -> Shopping | B40: 0 | C40: =SUMIFS(TransactionsLog[Amount],TransactionsLog[Category],$A40,TransactionsLog[Date],">="&PeriodStart,TransactionsLog[Date],"<="&PeriodEnd) -> 0 | D40: =B40-C40 -> 0
A41: =Settings!A21 -> Personal Care | B41: 0 | C41: =SUMIFS(TransactionsLog[Amount],TransactionsLog[Category],$A41,TransactionsLog[Date],">="&PeriodStart,TransactionsLog[Date],"<="&PeriodEnd) -> 0 | D41: =B41-C41 -> 0
A42: =Settings!A22 -> Household Supplies | B42: 0 | C42: =SUMIFS(TransactionsLog[Amount],TransactionsLog[Category],$A42,TransactionsLog[Date],">="&PeriodStart,TransactionsLog[Date],"<="&PeriodEnd) -> 0 | D42: =B42-C42 -> 0
A43: =Settings!A23 -> Miscellaneous | B43: 0 | C43: =SUMIFS(TransactionsLog[Amount],TransactionsLog[Category],$A43,TransactionsLog[Date],">="&PeriodStart,TransactionsLog[Date],"<="&PeriodEnd) -> 0 | D43: =B43-C43 -> 0
...

Sheet Flexible Income Budget
A1: Flexible Income Budget | G1: LEFT TO SPEND | I1: INCOME | J1: BILLS | K1: EXPENSES | L1: SAVINGS | M1: DEBT
A2: Built for income that changes month to month: freelance, commission, gig work, or multiple income streams. Everything below still reads from your Transactions Log automatically. | G2: =E10 -> 0 | I2: =C20 -> 0 | J2: =C32 -> 0 | K2: =C44 -> 0 | L2: =C53 -> 0 | M2: =C61 -> 0
N3: Chart data (auto — don't edit)
A4: Your Setup | D4: Cash Flow Summary | G4: ="Days left: "&IF(ISNUMBER(B7),MAX(B7-TODAY(),0),0) -> Days left: 16 | N4: Left to Spend | O4: =MAX(E10,0) -> 0
A5: Start Date | B5: 46235 | D5: Income | E5: =C20 -> 0 | N5: Spent | O5: =C32+C44+C53+C61 -> 0
A6: Pay Frequency | B6: Monthly | D6: Bills | E6: =-C32 -> 0
A7: Budget Period End | B7: 46265 | D7: Expenses | E7: =-C44 -> 0
A8: Currency | B8: USD | D8: Savings | E8: =-C53 -> 0 | N8: Bills | O8: =C32 -> 0
D9: Debt | E9: =-C61 -> 0 | N9: Expenses | O9: =C44 -> 0
D10: Amount Left to Spend | E10: =E5+E6+E7+E8+E9 -> 0 | I10: =E10 -> 0 | N10: Savings | O10: =C53 -> 0
N11: Debt | O11: =C61 -> 0
N12: Left to Spend | O12: =MAX(E10,0) -> 0
A14: Income Summary | B14: Budget | C14: Actual | D14: Above/Below Budget | E14: ✓
A15: =Settings!A3 -> Paycheck | B15: 0 | C15: =SUMIFS(TransactionsLog[Amount],TransactionsLog[Category],$A15,TransactionsLog[Date],">="&PeriodStart,TransactionsLog[Date],"<="&PeriodEnd) -> 0 | D15: =C15-B15 -> 0 | N15: Category | O15: Actual
A16: =Settings!A4 -> Side Income | B16: 0 | C16: =SUMIFS(TransactionsLog[Amount],TransactionsLog[Category],$A16,TransactionsLog[Date],">="&PeriodStart,TransactionsLog[Date],"<="&PeriodEnd) -> 0 | D16: =C16-B16 -> 0 | N16: =A36 -> Groceries | O16: =C36 -> 0
A17: =Settings!A5 -> Freelance Income | B17: 0 | C17: =SUMIFS(TransactionsLog[Amount],TransactionsLog[Category],$A17,TransactionsLog[Date],">="&PeriodStart,TransactionsLog[Date],"<="&PeriodEnd) -> 0 | D17: =C17-B17 -> 0 | N17: =A37 -> Dining Out | O17: =C37 -> 0
A18: =Settings!A6 -> Bonus | B18: 0 | C18: =SUMIFS(TransactionsLog[Amount],TransactionsLog[Category],$A18,TransactionsLog[Date],">="&PeriodStart,TransactionsLog[Date],"<="&PeriodEnd) -> 0 | D18: =C18-B18 -> 0 | N18: =A38 -> Transportation | O18: =C38 -> 0
A19: =Settings!A7 -> Other Income | B19: 0 | C19: =SUMIFS(TransactionsLog[Amount],TransactionsLog[Category],$A19,TransactionsLog[Date],">="&PeriodStart,TransactionsLog[Date],"<="&PeriodEnd) -> 0 | D19: =C19-B19 -> 0 | N19: =A39 -> Entertainment | O19: =C39 -> 0
A20: Total Income | B20: =SUM(B15:B19) -> 0 | C20: =SUM(C15:C19) -> 0 | D20: =C20-B20 -> 0 | N20: =A40 -> Shopping | O20: =C40 -> 0
N21: =A41 -> Personal Care | O21: =C41 -> 0
N22: =A42 -> Household Supplies | O22: =C42 -> 0
A23: Bill Tracker | B23: Budget | C23: Actual | D23: Remaining | E23: ✓ | N23: =A43 -> Miscellaneous | O23: =C43 -> 0
A24: =Settings!A8 -> Rent or Mortgage | B24: 0 | C24: =SUMIFS(TransactionsLog[Amount],TransactionsLog[Category],$A24,TransactionsLog[Date],">="&PeriodStart,TransactionsLog[Date],"<="&PeriodEnd) -> 0 | D24: =B24-C24 -> 0 | E24: ✓
A25: =Settings!A9 -> Electricity | B25: 0 | C25: =SUMIFS(TransactionsLog[Amount],TransactionsLog[Category],$A25,TransactionsLog[Date],">="&PeriodStart,TransactionsLog[Date],"<="&PeriodEnd) -> 0 | D25: =B25-C25 -> 0
A26: =Settings!A10 -> Water | B26: 0 | C26: =SUMIFS(TransactionsLog[Amount],TransactionsLog[Category],$A26,TransactionsLog[Date],">="&PeriodStart,TransactionsLog[Date],"<="&PeriodEnd) -> 0 | D26: =B26-C26 -> 0 | N26: Category | O26: Budget | P26: Actual
A27: =Settings!A11 -> Internet | B27: 0 | C27: =SUMIFS(TransactionsLog[Amount],TransactionsLog[Category],$A27,TransactionsLog[Date],">="&PeriodStart,TransactionsLog[Date],"<="&PeriodEnd) -> 0 | D27: =B27-C27 -> 0 | N27: Income | O27: =B20 -> 0 | P27: =C20 -> 0
A28: =Settings!A12 -> Phone | B28: 0 | C28: =SUMIFS(TransactionsLog[Amount],TransactionsLog[Category],$A28,TransactionsLog[Date],">="&PeriodStart,TransactionsLog[Date],"<="&PeriodEnd) -> 0 | D28: =B28-C28 -> 0 | N28: Bills | O28: =B32 -> 0 | P28: =C32 -> 0
A29: =Settings!A13 -> Car Payment | B29: 0 | C29: =SUMIFS(TransactionsLog[Amount],TransactionsLog[Category],$A29,TransactionsLog[Date],">="&PeriodStart,TransactionsLog[Date],"<="&PeriodEnd) -> 0 | D29: =B29-C29 -> 0 | N29: Expenses | O29: =B44 -> 0 | P29: =C44 -> 0
A30: =Settings!A14 -> Insurance | B30: 0 | C30: =SUMIFS(TransactionsLog[Amount],TransactionsLog[Category],$A30,TransactionsLog[Date],">="&PeriodStart,TransactionsLog[Date],"<="&PeriodEnd) -> 0 | D30: =B30-C30 -> 0 | N30: Savings | O30: =B53 -> 0 | P30: =C53 -> 0
A31: =Settings!A15 -> Subscriptions | B31: 0 | C31: ='Subscription Tracker'!$C$4 -> 0 | D31: =B31-C31 -> 0 | N31: Debt | O31: =B61 -> 0 | P31: =C61 -> 0
A32: Total Bills | B32: =SUM(B24:B31) -> 0 | C32: =SUM(C24:C31) -> 0 | D32: =B32-C32 -> 0
A35: Expense Summary | B35: Budget | C35: Actual | D35: Remaining | E35: ✓
A36: =Settings!A16 -> Groceries | B36: 0 | D36: =B36-C36 -> 0
A37: =Settings!A17 -> Dining Out | B37: 0 | C37: =SUMIFS(TransactionsLog[Amount],TransactionsLog[Category],$A37,TransactionsLog[Date],">="&PeriodStart,TransactionsLog[Date],"<="&PeriodEnd) -> 0 | D37: =B37-C37 -> 0
A38: =Settings!A18 -> Transportation | B38: 0 | C38: =SUMIFS(TransactionsLog[Amount],TransactionsLog[Category],$A38,TransactionsLog[Date],">="&PeriodStart,TransactionsLog[Date],"<="&PeriodEnd) -> 0 | D38: =B38-C38 -> 0
A39: =Settings!A19 -> Entertainment | B39: 0 | C39: =SUMIFS(TransactionsLog[Amount],TransactionsLog[Category],$A39,TransactionsLog[Date],">="&PeriodStart,TransactionsLog[Date],"<="&PeriodEnd) -> 0 | D39: =B39-C39 -> 0
A40: =Settings!A20 -> Shopping | B40: 0 | C40: =SUMIFS(TransactionsLog[Amount],TransactionsLog[Category],$A40,TransactionsLog[Date],">="&PeriodStart,TransactionsLog[Date],"<="&PeriodEnd) -> 0 | D40: =B40-C40 -> 0
A41: =Settings!A21 -> Personal Care | B41: 0 | C41: =SUMIFS(TransactionsLog[Amount],TransactionsLog[Category],$A41,TransactionsLog[Date],">="&PeriodStart,TransactionsLog[Date],"<="&PeriodEnd) -> 0 | D41: =B41-C41 -> 0
A42: =Settings!A22 -> Household Supplies | B42: 0 | C42: =SUMIFS(TransactionsLog[Amount],TransactionsLog[Category],$A42,TransactionsLog[Date],">="&PeriodStart,TransactionsLog[Date],"<="&PeriodEnd) -> 0 | D42: =B42-C42 -> 0
A43: =Settings!A23 -> Miscellaneous | B43: 0 | C43: =SUMIFS(TransactionsLog[Amount],TransactionsLog[Category],$A43,TransactionsLog[Date],">="&PeriodStart,TransactionsLog[Date],"<="&PeriodEnd) -> 0 | D43: =B43-C43 -> 0
...

Sheet Transactions Log
A1: Transactions Log
A2: Add one line every time money comes in or goes out. Type fills in automatically once you choose a Category. Every other tab reads from this list, so you only ever type a number once.
A4: Date | B4: Category | C4: Type | D4: Amount | E4: Notes
C6: =IFERROR(_xlfn.XLOOKUP(TransactionsLog[[#This Row],[Category]],CategoryList,CategoryTypeList),"") -> 0
C7: =IFERROR(_xlfn.XLOOKUP(TransactionsLog[[#This Row],[Category]],CategoryList,CategoryTypeList),"") -> 0
C8: =IFERROR(_xlfn.XLOOKUP(TransactionsLog[[#This Row],[Category]],CategoryList,CategoryTypeList),"") -> 0
C9: =IFERROR(_xlfn.XLOOKUP(TransactionsLog[[#This Row],[Category]],CategoryList,CategoryTypeList),"") -> 0
C10: =IFERROR(_xlfn.XLOOKUP(TransactionsLog[[#This Row],[Category]],CategoryList,CategoryTypeList),"") -> 0
C11: =IFERROR(_xlfn.XLOOKUP(TransactionsLog[[#This Row],[Category]],CategoryList,CategoryTypeList),"") -> 0
C12: =IFERROR(_xlfn.XLOOKUP(TransactionsLog[[#This Row],[Category]],CategoryList,CategoryTypeList),"") -> 0
C13: =IFERROR(_xlfn.XLOOKUP(TransactionsLog[[#This Row],[Category]],CategoryList,CategoryTypeList),"") -> 0
C14: =IFERROR(_xlfn.XLOOKUP(TransactionsLog[[#This Row],[Category]],CategoryList,CategoryTypeList),"") -> 0
C15: =IFERROR(_xlfn.XLOOKUP(TransactionsLog[[#This Row],[Category]],CategoryList,CategoryTypeList),"") -> 0
C16: =IFERROR(_xlfn.XLOOKUP(TransactionsLog[[#This Row],[Category]],CategoryList,CategoryTypeList),"") -> 0
C17: =IFERROR(_xlfn.XLOOKUP(TransactionsLog[[#This Row],[Category]],CategoryList,CategoryTypeList),"") -> 0
... C304: =IFERROR(_xlfn.XLOOKUP(TransactionsLog[[#This Row],[Category]],CategoryList,CategoryTypeList),"") -> 0

Sheet Bank Import
A1: Bank Import Helper
A2: 1. Export your bank statement as Excel or CSV. 2. Copy the Date, Description, and Amount columns and paste them into the yellow area below (paste values only). 3. Check the suggested category in column D. Change it using the dropdown if it's wrong. 4. Once everything looks right, copy columns E through I below and paste them into your Transactions Log.
A3: This tool does not connect to your bank. You export your statement yourself and paste it in here. | K3: Keyword List (edit this to teach the import your own categories)
A4: Paste your bank export here | D4: Ready to copy into Transactions Log | K4: Add your own rows here any time. If a bank description contains this keyword anywhere, it will suggest that category automatically.
A5: Date | B5: Description | C5: Amount | D5: Suggested Category | E5: Date | F5: Category | G5: Type | H5: Amount | I5: Notes | K5: Keyword | L5: Category
D6: {=IF(B6="","",IFERROR(INDEX($L$6:$L$33,MATCH(TRUE,ISNUMBER(SEARCH($K$6:$K$33,B6)),0)),"Review Manually"))} | E6: =IF(A6="","",A6) | F6: =IF(B6="","",D6) | G6: =IF(F6="","",IFERROR(_xlfn.XLOOKUP(F6,CategoryList,CategoryTypeList),"")) | H6: =IF(C6="","",C6) | K6: NETFLIX | L6: Subscriptions
D7: {=IF(B7="","",IFERROR(INDEX($L$6:$L$33,MATCH(TRUE,ISNUMBER(SEARCH($K$6:$K$33,B7)),0)),"Review Manually"))} | E7: =IF(A7="","",A7) | F7: =IF(B7="","",D7) | G7: =IF(F7="","",IFERROR(_xlfn.XLOOKUP(F7,CategoryList,CategoryTypeList),"")) | H7: =IF(C7="","",C7) | K7: SPOTIFY | L7: Subscriptions
D8: {=IF(B8="","",IFERROR(INDEX($L$6:$L$33,MATCH(TRUE,ISNUMBER(SEARCH($K$6:$K$33,B8)),0)),"Review Manually"))} | E8: =IF(A8="","",A8) | F8: =IF(B8="","",D8) | G8: =IF(F8="","",IFERROR(_xlfn.XLOOKUP(F8,CategoryList,CategoryTypeList),"")) | H8: =IF(C8="","",C8) | K8: HULU | L8: Subscriptions
D9: {=IF(B9="","",IFERROR(INDEX($L$6:$L$33,MATCH(TRUE,ISNUMBER(SEARCH($K$6:$K$33,B9)),0)),"Review Manually"))} | E9: =IF(A9="","",A9) | F9: =IF(B9="","",D9) | G9: =IF(F9="","",IFERROR(_xlfn.XLOOKUP(F9,CategoryList,CategoryTypeList),"")) | H9: =IF(C9="","",C9) | K9: DISNEY+ | L9: Subscriptions
D10: {=IF(B10="","",IFERROR(INDEX($L$6:$L$33,MATCH(TRUE,ISNUMBER(SEARCH($K$6:$K$33,B10)),0)),"Review Manually"))} | E10: =IF(A10="","",A10) | F10: =IF(B10="","",D10) | G10: =IF(F10="","",IFERROR(_xlfn.XLOOKUP(F10,CategoryList,CategoryTypeList),"")) | H10: =IF(C10="","",C10) | K10: UBER | L10: Transportation
D11: {=IF(B11="","",IFERROR(INDEX($L$6:$L$33,MATCH(TRUE,ISNUMBER(SEARCH($K$6:$K$33,B11)),0)),"Review Manually"))} | E11: =IF(A11="","",A11) | F11: =IF(B11="","",D11) | G11: =IF(F11="","",IFERROR(_xlfn.XLOOKUP(F11,CategoryList,CategoryTypeList),"")) | H11: =IF(C11="","",C11) | K11: LYFT | L11: Transportation
D12: {=IF(B12="","",IFERROR(INDEX($L$6:$L$33,MATCH(TRUE,ISNUMBER(SEARCH($K$6:$K$33,B12)),0)),"Review Manually"))} | E12: =IF(A12="","",A12) | F12: =IF(B12="","",D12) | G12: =IF(F12="","",IFERROR(_xlfn.XLOOKUP(F12,CategoryList,CategoryTypeList),"")) | H12: =IF(C12="","",C12) | K12: SHELL | L12: Transportation
D13: {=IF(B13="","",IFERROR(INDEX($L$6:$L$33,MATCH(TRUE,ISNUMBER(SEARCH($K$6:$K$33,B13)),0)),"Review Manually"))} | E13: =IF(A13="","",A13) | F13: =IF(B13="","",D13) | G13: =IF(F13="","",IFERROR(_xlfn.XLOOKUP(F13,CategoryList,CategoryTypeList),"")) | H13: =IF(C13="","",C13) | K13: GAS STATION | L13: Transportation
D14: {=IF(B14="","",IFERROR(INDEX($L$6:$L$33,MATCH(TRUE,ISNUMBER(SEARCH($K$6:$K$33,B14)),0)),"Review Manually"))} | E14: =IF(A14="","",A14) | F14: =IF(B14="","",D14) | G14: =IF(F14="","",IFERROR(_xlfn.XLOOKUP(F14,CategoryList,CategoryTypeList),"")) | H14: =IF(C14="","",C14) | K14: WALMART | L14: Groceries
D15: {=IF(B15="","",IFERROR(INDEX($L$6:$L$33,MATCH(TRUE,ISNUMBER(SEARCH($K$6:$K$33,B15)),0)),"Review Manually"))} | E15: =IF(A15="","",A15) | F15: =IF(B15="","",D15) | G15: =IF(F15="","",IFERROR(_xlfn.XLOOKUP(F15,CategoryList,CategoryTypeList),"")) | H15: =IF(C15="","",C15) | K15: TESCO | L15: Groceries
D16: {=IF(B16="","",IFERROR(INDEX($L$6:$L$33,MATCH(TRUE,ISNUMBER(SEARCH($K$6:$K$33,B16)),0)),"Review Manually"))} | E16: =IF(A16="","",A16) | F16: =IF(B16="","",D16) | G16: =IF(F16="","",IFERROR(_xlfn.XLOOKUP(F16,CategoryList,CategoryTypeList),"")) | H16: =IF(C16="","",C16) | K16: WHOLE FOODS | L16: Groceries
D17: {=IF(B17="","",IFERROR(INDEX($L$6:$L$33,MATCH(TRUE,ISNUMBER(SEARCH($K$6:$K$33,B17)),0)),"Review Manually"))} | E17: =IF(A17="","",A17) | F17: =IF(B17="","",D17) | G17: =IF(F17="","",IFERROR(_xlfn.XLOOKUP(F17,CategoryList,CategoryTypeList),"")) | H17: =IF(C17="","",C17) | K17: COSTCO | L17: Groceries
... D33: {=IF(B33="","",IFERROR(INDEX($L$6:$L$33,MATCH(TRUE,ISNUMBER(SEARCH($K$6:$K$33,B33)),0)),"Review Manually"))} | E33: =IF(A33="","",A33) | F33: =IF(B33="","",D33) | G33: =IF(F33="","",IFERROR(_xlfn.XLOOKUP(F33,CategoryList,CategoryTypeList),"")) | H33: =IF(C33="","",C33) | K33: DIRECT DEPOSIT | L33: Paycheck
D34: {=IF(B34="","",IFERROR(INDEX($L$6:$L$33,MATCH(TRUE,ISNUMBER(SEARCH($K$6:$K$33,B34)),0)),"Review Manually"))} | E34: =IF(A34="","",A34) | F34: =IF(B34="","",D34) | G34: =IF(F34="","",IFERROR(_xlfn.XLOOKUP(F34,CategoryList,CategoryTypeList),"")) | H34: =IF(C34="","",C34)
D35: {=IF(B35="","",IFERROR(INDEX($L$6:$L$33,MATCH(TRUE,ISNUMBER(SEARCH($K$6:$K$33,B35)),0)),"Review Manually"))} | E35: =IF(A35="","",A35) | F35: =IF(B35="","",D35) | G35: =IF(F35="","",IFERROR(_xlfn.XLOOKUP(F35,CategoryList,CategoryTypeList),"")) | H35: =IF(C35="","",C35)
D36: {=IF(B36="","",IFERROR(INDEX($L$6:$L$33,MATCH(TRUE,ISNUMBER(SEARCH($K$6:$K$33,B36)),0)),"Review Manually"))} | E36: =IF(A36="","",A36) | F36: =IF(B36="","",D36) | G36: =IF(F36="","",IFERROR(_xlfn.XLOOKUP(F36,CategoryList,CategoryTypeList),"")) | H36: =IF(C36="","",C36)
D37: {=IF(B37="","",IFERROR(INDEX($L$6:$L$33,MATCH(TRUE,ISNUMBER(SEARCH($K$6:$K$33,B37)),0)),"Review Manually"))} | E37: =IF(A37="","",A37) | F37: =IF(B37="","",D37) | G37: =IF(F37="","",IFERROR(_xlfn.XLOOKUP(F37,CategoryList,CategoryTypeList),"")) | H37: =IF(C37="","",C37)
D38: {=IF(B38="","",IFERROR(INDEX($L$6:$L$33,MATCH(TRUE,ISNUMBER(SEARCH($K$6:$K$33,B38)),0)),"Review Manually"))} | E38: =IF(A38="","",A38) | F38: =IF(B38="","",D38) | G38: =IF(F38="","",IFERROR(_xlfn.XLOOKUP(F38,CategoryList,CategoryTypeList),"")) | H38: =IF(C38="","",C38)
D39: {=IF(B39="","",IFERROR(INDEX($L$6:$L$33,MATCH(TRUE,ISNUMBER(SEARCH($K$6:$K$33,B39)),0)),"Review Manually"))} | E39: =IF(A39="","",A39) | F39: =IF(B39="","",D39) | G39: =IF(F39="","",IFERROR(_xlfn.XLOOKUP(F39,CategoryList,CategoryTypeList),"")) | H39: =IF(C39="","",C39)
D40: {=IF(B40="","",IFERROR(INDEX($L$6:$L$33,MATCH(TRUE,ISNUMBER(SEARCH($K$6:$K$33,B40)),0)),"Review Manually"))} | E40: =IF(A40="","",A40) | F40: =IF(B40="","",D40) | G40: =IF(F40="","",IFERROR(_xlfn.XLOOKUP(F40,CategoryList,CategoryTypeList),"")) | H40: =IF(C40="","",C40)
D41: {=IF(B41="","",IFERROR(INDEX($L$6:$L$33,MATCH(TRUE,ISNUMBER(SEARCH($K$6:$K$33,B41)),0)),"Review Manually"))} | E41: =IF(A41="","",A41) | F41: =IF(B41="","",D41) | G41: =IF(F41="","",IFERROR(_xlfn.XLOOKUP(F41,CategoryList,CategoryTypeList),"")) | H41: =IF(C41="","",C41)
D42: {=IF(B42="","",IFERROR(INDEX($L$6:$L$33,MATCH(TRUE,ISNUMBER(SEARCH($K$6:$K$33,B42)),0)),"Review Manually"))} | E42: =IF(A42="","",A42) | F42: =IF(B42="","",D42) | G42: =IF(F42="","",IFERROR(_xlfn.XLOOKUP(F42,CategoryList,CategoryTypeList),"")) | H42: =IF(C42="","",C42)
D43: {=IF(B43="","",IFERROR(INDEX($L$6:$L$33,MATCH(TRUE,ISNUMBER(SEARCH($K$6:$K$33,B43)),0)),"Review Manually"))} | E43: =IF(A43="","",A43) | F43: =IF(B43="","",D43) | G43: =IF(F43="","",IFERROR(_xlfn.XLOOKUP(F43,CategoryList,CategoryTypeList),"")) | H43: =IF(C43="","",C43)
D44: {=IF(B44="","",IFERROR(INDEX($L$6:$L$33,MATCH(TRUE,ISNUMBER(SEARCH($K$6:$K$33,B44)),0)),"Review Manually"))} | E44: =IF(A44="","",A44) | F44: =IF(B44="","",D44) | G44: =IF(F44="","",IFERROR(_xlfn.XLOOKUP(F44,CategoryList,CategoryTypeList),"")) | H44: =IF(C44="","",C44)
D45: {=IF(B45="","",IFERROR(INDEX($L$6:$L$33,MATCH(TRUE,ISNUMBER(SEARCH($K$6:$K$33,B45)),0)),"Review Manually"))} | E45: =IF(A45="","",A45) | F45: =IF(B45="","",D45) | G45: =IF(F45="","",IFERROR(_xlfn.XLOOKUP(F45,CategoryList,CategoryTypeList),"")) | H45: =IF(C45="","",C45)
... D105: {=IF(B105="","",IFERROR(INDEX($L$6:$L$33,MATCH(TRUE,ISNUMBER(SEARCH($K$6:$K$33,B105)),0)),"Review Manually"))} | E105: =IF(A105="","",A105) | F105: =IF(B105="","",D105) | G105: =IF(F105="","",IFERROR(_xlfn.XLOOKUP(F105,CategoryList,CategoryTypeList),"")) | H105: =IF(C105="","",C105)

Sheet Bill Calendar
A1: Bill Calendar
A2: Bills you've logged as Type "Bill" in your Transactions Log show up here automatically, on the day you dated them. Pick a month, year, and which day your week starts on.
A4: Month | B4: January | C4: Year | D4: 2026 | E4: Week Starts On | F4: Monday | I4: Month # | J4: =MATCH($B$4,MonthList,0) -> 1
I5: 1st of Month | J5: =DATE($D$4,$J$4,1) -> 46023
B6: {=IF($F$4="Monday",INDEX({"Mon";"Tue";"Wed";"Thu";"Fri";"Sat";"Sun"},1),INDEX({"Sun";"Mon";"Tue";"Wed";"Thu";"Fri";"Sat"},1))} -> Mon | C6: {=IF($F$4="Monday",INDEX({"Mon";"Tue";"Wed";"Thu";"Fri";"Sat";"Sun"},2),INDEX({"Sun";"Mon";"Tue";"Wed";"Thu";"Fri";"Sat"},2))} -> Tue | D6: {=IF($F$4="Monday",INDEX({"Mon";"Tue";"Wed";"Thu";"Fri";"Sat";"Sun"},3),INDEX({"Sun";"Mon";"Tue";"Wed";"Thu";"Fri";"Sat"},3))} -> Wed | E6: {=IF($F$4="Monday",INDEX({"Mon";"Tue";"Wed";"Thu";"Fri";"Sat";"Sun"},4),INDEX({"Sun";"Mon";"Tue";"Wed";"Thu";"Fri";"Sat"},4))} -> Thu | F6: {=IF($F$4="Monday",INDEX({"Mon";"Tue";"Wed";"Thu";"Fri";"Sat";"Sun"},5),INDEX({"Sun";"Mon";"Tue";"Wed";"Thu";"Fri";"Sat"},5))} -> Fri | G6: {=IF($F$4="Monday",INDEX({"Mon";"Tue";"Wed";"Thu";"Fri";"Sat";"Sun"},6),INDEX({"Sun";"Mon";"Tue";"Wed";"Thu";"Fri";"Sat"},6))} -> Sat | H6: {=IF($F$4="Monday",INDEX({"Mon";"Tue";"Wed";"Thu";"Fri";"Sat";"Sun"},7),INDEX({"Sun";"Mon";"Tue";"Wed";"Thu";"Fri";"Sat"},7))} -> Sun | I6: Offset | J6: =IF($F$4="Monday",WEEKDAY($J$5,2)-1,WEEKDAY($J$5,1)-1) -> 3
B7: =IF(MONTH(($J$5-$J$6+0))=$J$4,DAY(($J$5-$J$6+0)),"") | C7: =IF(MONTH(($J$5-$J$6+1))=$J$4,DAY(($J$5-$J$6+1)),"") | D7: =IF(MONTH(($J$5-$J$6+2))=$J$4,DAY(($J$5-$J$6+2)),"") | E7: =IF(MONTH(($J$5-$J$6+3))=$J$4,DAY(($J$5-$J$6+3)),"") -> 1 | F7: =IF(MONTH(($J$5-$J$6+4))=$J$4,DAY(($J$5-$J$6+4)),"") -> 2 | G7: =IF(MONTH(($J$5-$J$6+5))=$J$4,DAY(($J$5-$J$6+5)),"") -> 3 | H7: =IF(MONTH(($J$5-$J$6+6))=$J$4,DAY(($J$5-$J$6+6)),"") -> 4
B8: {=IF(MONTH($J$5-$J$6+((ROW()-8)/2)*7+(COLUMN()-2))=$J$4,IFERROR(_xlfn.TEXTJOIN(CHAR(10),TRUE,IF((TransactionsLog[Type]="Bill")*(TransactionsLog[Date]=($J$5-$J$6+((ROW()-8)/2)*7+(COLUMN()-2))),"☐ "&TransactionsLog[Category]&" "&TEXT(TransactionsLog[Amount],"$0"),"")),""),"")} | C8: {=IF(MONTH($J$5-$J$6+((ROW()-8)/2)*7+(COLUMN()-2))=$J$4,IFERROR(_xlfn.TEXTJOIN(CHAR(10),TRUE,IF((TransactionsLog[Type]="Bill")*(TransactionsLog[Date]=($J$5-$J$6+((ROW()-8)/2)*7+(COLUMN()-2))),"☐ "&TransactionsLog[Category]&" "&TEXT(TransactionsLog[Amount],"$0"),"")),""),"")} | D8: {=IF(MONTH($J$5-$J$6+((ROW()-8)/2)*7+(COLUMN()-2))=$J$4,IFERROR(_xlfn.TEXTJOIN(CHAR(10),TRUE,IF((TransactionsLog[Type]="Bill")*(TransactionsLog[Date]=($J$5-$J$6+((ROW()-8)/2)*7+(COLUMN()-2))),"☐ "&TransactionsLog[Category]&" "&TEXT(TransactionsLog[Amount],"$0"),"")),""),"")} | E8: {=IF(MONTH($J$5-$J$6+((ROW()-8)/2)*7+(COLUMN()-2))=$J$4,IFERROR(_xlfn.TEXTJOIN(CHAR(10),TRUE,IF((TransactionsLog[Type]="Bill")*(TransactionsLog[Date]=($J$5-$J$6+((ROW()-8)/2)*7+(COLUMN()-2))),"☐ "&TransactionsLog[Category]&" "&TEXT(TransactionsLog[Amount],"$0"),"")),""),"")} | F8: {=IF(MONTH($J$5-$J$6+((ROW()-8)/2)*7+(COLUMN()-2))=$J$4,IFERROR(_xlfn.TEXTJOIN(CHAR(10),TRUE,IF((TransactionsLog[Type]="Bill")*(TransactionsLog[Date]=($J$5-$J$6+((ROW()-8)/2)*7+(COLUMN()-2))),"☐ "&TransactionsLog[Category]&" "&TEXT(TransactionsLog[Amount],"$0"),"")),""),"")} | G8: {=IF(MONTH($J$5-$J$6+((ROW()-8)/2)*7+(COLUMN()-2))=$J$4,IFERROR(_xlfn.TEXTJOIN(CHAR(10),TRUE,IF((TransactionsLog[Type]="Bill")*(TransactionsLog[Date]=($J$5-$J$6+((ROW()-8)/2)*7+(COLUMN()-2))),"☐ "&TransactionsLog[Category]&" "&TEXT(TransactionsLog[Amount],"$0"),"")),""),"")} | H8: {=IF(MONTH($J$5-$J$6+((ROW()-8)/2)*7+(COLUMN()-2))=$J$4,IFERROR(_xlfn.TEXTJOIN(CHAR(10),TRUE,IF((TransactionsLog[Type]="Bill")*(TransactionsLog[Date]=($J$5-$J$6+((ROW()-8)/2)*7+(COLUMN()-2))),"☐ "&TransactionsLog[Category]&" "&TEXT(TransactionsLog[Amount],"$0"),"")),""),"")}
B9: =IF(MONTH(($J$5-$J$6+7))=$J$4,DAY(($J$5-$J$6+7)),"") -> 5 | C9: =IF(MONTH(($J$5-$J$6+8))=$J$4,DAY(($J$5-$J$6+8)),"") -> 6 | D9: =IF(MONTH(($J$5-$J$6+9))=$J$4,DAY(($J$5-$J$6+9)),"") -> 7 | E9: =IF(MONTH(($J$5-$J$6+10))=$J$4,DAY(($J$5-$J$6+10)),"") -> 8 | F9: =IF(MONTH(($J$5-$J$6+11))=$J$4,DAY(($J$5-$J$6+11)),"") -> 9 | G9: =IF(MONTH(($J$5-$J$6+12))=$J$4,DAY(($J$5-$J$6+12)),"") -> 10 | H9: =IF(MONTH(($J$5-$J$6+13))=$J$4,DAY(($J$5-$J$6+13)),"") -> 11
B10: {=IF(MONTH($J$5-$J$6+((ROW()-8)/2)*7+(COLUMN()-2))=$J$4,IFERROR(_xlfn.TEXTJOIN(CHAR(10),TRUE,IF((TransactionsLog[Type]="Bill")*(TransactionsLog[Date]=($J$5-$J$6+((ROW()-8)/2)*7+(COLUMN()-2))),"☐ "&TransactionsLog[Category]&" "&TEXT(TransactionsLog[Amount],"$0"),"")),""),"")} | C10: {=IF(MONTH($J$5-$J$6+((ROW()-8)/2)*7+(COLUMN()-2))=$J$4,IFERROR(_xlfn.TEXTJOIN(CHAR(10),TRUE,IF((TransactionsLog[Type]="Bill")*(TransactionsLog[Date]=($J$5-$J$6+((ROW()-8)/2)*7+(COLUMN()-2))),"☐ "&TransactionsLog[Category]&" "&TEXT(TransactionsLog[Amount],"$0"),"")),""),"")} | D10: {=IF(MONTH($J$5-$J$6+((ROW()-8)/2)*7+(COLUMN()-2))=$J$4,IFERROR(_xlfn.TEXTJOIN(CHAR(10),TRUE,IF((TransactionsLog[Type]="Bill")*(TransactionsLog[Date]=($J$5-$J$6+((ROW()-8)/2)*7+(COLUMN()-2))),"☐ "&TransactionsLog[Category]&" "&TEXT(TransactionsLog[Amount],"$0"),"")),""),"")} | E10: {=IF(MONTH($J$5-$J$6+((ROW()-8)/2)*7+(COLUMN()-2))=$J$4,IFERROR(_xlfn.TEXTJOIN(CHAR(10),TRUE,IF((TransactionsLog[Type]="Bill")*(TransactionsLog[Date]=($J$5-$J$6+((ROW()-8)/2)*7+(COLUMN()-2))),"☐ "&TransactionsLog[Category]&" "&TEXT(TransactionsLog[Amount],"$0"),"")),""),"")} | F10: {=IF(MONTH($J$5-$J$6+((ROW()-8)/2)*7+(COLUMN()-2))=$J$4,IFERROR(_xlfn.TEXTJOIN(CHAR(10),TRUE,IF((TransactionsLog[Type]="Bill")*(TransactionsLog[Date]=($J$5-$J$6+((ROW()-8)/2)*7+(COLUMN()-2))),"☐ "&TransactionsLog[Category]&" "&TEXT(TransactionsLog[Amount],"$0"),"")),""),"")} | G10: {=IF(MONTH($J$5-$J$6+((ROW()-8)/2)*7+(COLUMN()-2))=$J$4,IFERROR(_xlfn.TEXTJOIN(CHAR(10),TRUE,IF((TransactionsLog[Type]="Bill")*(TransactionsLog[Date]=($J$5-$J$6+((ROW()-8)/2)*7+(COLUMN()-2))),"☐ "&TransactionsLog[Category]&" "&TEXT(TransactionsLog[Amount],"$0"),"")),""),"")} | H10: {=IF(MONTH($J$5-$J$6+((ROW()-8)/2)*7+(COLUMN()-2))=$J$4,IFERROR(_xlfn.TEXTJOIN(CHAR(10),TRUE,IF((TransactionsLog[Type]="Bill")*(TransactionsLog[Date]=($J$5-$J$6+((ROW()-8)/2)*7+(COLUMN()-2))),"☐ "&TransactionsLog[Category]&" "&TEXT(TransactionsLog[Amount],"$0"),"")),""),"")}
B11: =IF(MONTH(($J$5-$J$6+14))=$J$4,DAY(($J$5-$J$6+14)),"") -> 12 | C11: =IF(MONTH(($J$5-$J$6+15))=$J$4,DAY(($J$5-$J$6+15)),"") -> 13 | D11: =IF(MONTH(($J$5-$J$6+16))=$J$4,DAY(($J$5-$J$6+16)),"") -> 14 | E11: =IF(MONTH(($J$5-$J$6+17))=$J$4,DAY(($J$5-$J$6+17)),"") -> 15 | F11: =IF(MONTH(($J$5-$J$6+18))=$J$4,DAY(($J$5-$J$6+18)),"") -> 16 | G11: =IF(MONTH(($J$5-$J$6+19))=$J$4,DAY(($J$5-$J$6+19)),"") -> 17 | H11: =IF(MONTH(($J$5-$J$6+20))=$J$4,DAY(($J$5-$J$6+20)),"") -> 18
B12: {=IF(MONTH($J$5-$J$6+((ROW()-8)/2)*7+(COLUMN()-2))=$J$4,IFERROR(_xlfn.TEXTJOIN(CHAR(10),TRUE,IF((TransactionsLog[Type]="Bill")*(TransactionsLog[Date]=($J$5-$J$6+((ROW()-8)/2)*7+(COLUMN()-2))),"☐ "&TransactionsLog[Category]&" "&TEXT(TransactionsLog[Amount],"$0"),"")),""),"")} | C12: {=IF(MONTH($J$5-$J$6+((ROW()-8)/2)*7+(COLUMN()-2))=$J$4,IFERROR(_xlfn.TEXTJOIN(CHAR(10),TRUE,IF((TransactionsLog[Type]="Bill")*(TransactionsLog[Date]=($J$5-$J$6+((ROW()-8)/2)*7+(COLUMN()-2))),"☐ "&TransactionsLog[Category]&" "&TEXT(TransactionsLog[Amount],"$0"),"")),""),"")} | D12: {=IF(MONTH($J$5-$J$6+((ROW()-8)/2)*7+(COLUMN()-2))=$J$4,IFERROR(_xlfn.TEXTJOIN(CHAR(10),TRUE,IF((TransactionsLog[Type]="Bill")*(TransactionsLog[Date]=($J$5-$J$6+((ROW()-8)/2)*7+(COLUMN()-2))),"☐ "&TransactionsLog[Category]&" "&TEXT(TransactionsLog[Amount],"$0"),"")),""),"")} | E12: {=IF(MONTH($J$5-$J$6+((ROW()-8)/2)*7+(COLUMN()-2))=$J$4,IFERROR(_xlfn.TEXTJOIN(CHAR(10),TRUE,IF((TransactionsLog[Type]="Bill")*(TransactionsLog[Date]=($J$5-$J$6+((ROW()-8)/2)*7+(COLUMN()-2))),"☐ "&TransactionsLog[Category]&" "&TEXT(TransactionsLog[Amount],"$0"),"")),""),"")} | F12: {=IF(MONTH($J$5-$J$6+((ROW()-8)/2)*7+(COLUMN()-2))=$J$4,IFERROR(_xlfn.TEXTJOIN(CHAR(10),TRUE,IF((TransactionsLog[Type]="Bill")*(TransactionsLog[Date]=($J$5-$J$6+((ROW()-8)/2)*7+(COLUMN()-2))),"☐ "&TransactionsLog[Category]&" "&TEXT(TransactionsLog[Amount],"$0"),"")),""),"")} | G12: {=IF(MONTH($J$5-$J$6+((ROW()-8)/2)*7+(COLUMN()-2))=$J$4,IFERROR(_xlfn.TEXTJOIN(CHAR(10),TRUE,IF((TransactionsLog[Type]="Bill")*(TransactionsLog[Date]=($J$5-$J$6+((ROW()-8)/2)*7+(COLUMN()-2))),"☐ "&TransactionsLog[Category]&" "&TEXT(TransactionsLog[Amount],"$0"),"")),""),"")} | H12: {=IF(MONTH($J$5-$J$6+((ROW()-8)/2)*7+(COLUMN()-2))=$J$4,IFERROR(_xlfn.TEXTJOIN(CHAR(10),TRUE,IF((TransactionsLog[Type]="Bill")*(TransactionsLog[Date]=($J$5-$J$6+((ROW()-8)/2)*7+(COLUMN()-2))),"☐ "&TransactionsLog[Category]&" "&TEXT(TransactionsLog[Amount],"$0"),"")),""),"")}
B13: =IF(MONTH(($J$5-$J$6+21))=$J$4,DAY(($J$5-$J$6+21)),"") -> 19 | C13: =IF(MONTH(($J$5-$J$6+22))=$J$4,DAY(($J$5-$J$6+22)),"") -> 20 | D13: =IF(MONTH(($J$5-$J$6+23))=$J$4,DAY(($J$5-$J$6+23)),"") -> 21 | E13: =IF(MONTH(($J$5-$J$6+24))=$J$4,DAY(($J$5-$J$6+24)),"") -> 22 | F13: =IF(MONTH(($J$5-$J$6+25))=$J$4,DAY(($J$5-$J$6+25)),"") -> 23 | G13: =IF(MONTH(($J$5-$J$6+26))=$J$4,DAY(($J$5-$J$6+26)),"") -> 24 | H13: =IF(MONTH(($J$5-$J$6+27))=$J$4,DAY(($J$5-$J$6+27)),"") -> 25
B14: {=IF(MONTH($J$5-$J$6+((ROW()-8)/2)*7+(COLUMN()-2))=$J$4,IFERROR(_xlfn.TEXTJOIN(CHAR(10),TRUE,IF((TransactionsLog[Type]="Bill")*(TransactionsLog[Date]=($J$5-$J$6+((ROW()-8)/2)*7+(COLUMN()-2))),"☐ "&TransactionsLog[Category]&" "&TEXT(TransactionsLog[Amount],"$0"),"")),""),"")} | C14: {=IF(MONTH($J$5-$J$6+((ROW()-8)/2)*7+(COLUMN()-2))=$J$4,IFERROR(_xlfn.TEXTJOIN(CHAR(10),TRUE,IF((TransactionsLog[Type]="Bill")*(TransactionsLog[Date]=($J$5-$J$6+((ROW()-8)/2)*7+(COLUMN()-2))),"☐ "&TransactionsLog[Category]&" "&TEXT(TransactionsLog[Amount],"$0"),"")),""),"")} | D14: {=IF(MONTH($J$5-$J$6+((ROW()-8)/2)*7+(COLUMN()-2))=$J$4,IFERROR(_xlfn.TEXTJOIN(CHAR(10),TRUE,IF((TransactionsLog[Type]="Bill")*(TransactionsLog[Date]=($J$5-$J$6+((ROW()-8)/2)*7+(COLUMN()-2))),"☐ "&TransactionsLog[Category]&" "&TEXT(TransactionsLog[Amount],"$0"),"")),""),"")} | E14: {=IF(MONTH($J$5-$J$6+((ROW()-8)/2)*7+(COLUMN()-2))=$J$4,IFERROR(_xlfn.TEXTJOIN(CHAR(10),TRUE,IF((TransactionsLog[Type]="Bill")*(TransactionsLog[Date]=($J$5-$J$6+((ROW()-8)/2)*7+(COLUMN()-2))),"☐ "&TransactionsLog[Category]&" "&TEXT(TransactionsLog[Amount],"$0"),"")),""),"")} | F14: {=IF(MONTH($J$5-$J$6+((ROW()-8)/2)*7+(COLUMN()-2))=$J$4,IFERROR(_xlfn.TEXTJOIN(CHAR(10),TRUE,IF((TransactionsLog[Type]="Bill")*(TransactionsLog[Date]=($J$5-$J$6+((ROW()-8)/2)*7+(COLUMN()-2))),"☐ "&TransactionsLog[Category]&" "&TEXT(TransactionsLog[Amount],"$0"),"")),""),"")} | G14: {=IF(MONTH($J$5-$J$6+((ROW()-8)/2)*7+(COLUMN()-2))=$J$4,IFERROR(_xlfn.TEXTJOIN(CHAR(10),TRUE,IF((TransactionsLog[Type]="Bill")*(TransactionsLog[Date]=($J$5-$J$6+((ROW()-8)/2)*7+(COLUMN()-2))),"☐ "&TransactionsLog[Category]&" "&TEXT(TransactionsLog[Amount],"$0"),"")),""),"")} | H14: {=IF(MONTH($J$5-$J$6+((ROW()-8)/2)*7+(COLUMN()-2))=$J$4,IFERROR(_xlfn.TEXTJOIN(CHAR(10),TRUE,IF((TransactionsLog[Type]="Bill")*(TransactionsLog[Date]=($J$5-$J$6+((ROW()-8)/2)*7+(COLUMN()-2))),"☐ "&TransactionsLog[Category]&" "&TEXT(TransactionsLog[Amount],"$0"),"")),""),"")}
B15: =IF(MONTH(($J$5-$J$6+28))=$J$4,DAY(($J$5-$J$6+28)),"") -> 26 | C15: =IF(MONTH(($J$5-$J$6+29))=$J$4,DAY(($J$5-$J$6+29)),"") -> 27 | D15: =IF(MONTH(($J$5-$J$6+30))=$J$4,DAY(($J$5-$J$6+30)),"") -> 28 | E15: =IF(MONTH(($J$5-$J$6+31))=$J$4,DAY(($J$5-$J$6+31)),"") -> 29 | F15: =IF(MONTH(($J$5-$J$6+32))=$J$4,DAY(($J$5-$J$6+32)),"") -> 30 | G15: =IF(MONTH(($J$5-$J$6+33))=$J$4,DAY(($J$5-$J$6+33)),"") -> 31 | H15: =IF(MONTH(($J$5-$J$6+34))=$J$4,DAY(($J$5-$J$6+34)),"")
B16: {=IF(MONTH($J$5-$J$6+((ROW()-8)/2)*7+(COLUMN()-2))=$J$4,IFERROR(_xlfn.TEXTJOIN(CHAR(10),TRUE,IF((TransactionsLog[Type]="Bill")*(TransactionsLog[Date]=($J$5-$J$6+((ROW()-8)/2)*7+(COLUMN()-2))),"☐ "&TransactionsLog[Category]&" "&TEXT(TransactionsLog[Amount],"$0"),"")),""),"")} | C16: {=IF(MONTH($J$5-$J$6+((ROW()-8)/2)*7+(COLUMN()-2))=$J$4,IFERROR(_xlfn.TEXTJOIN(CHAR(10),TRUE,IF((TransactionsLog[Type]="Bill")*(TransactionsLog[Date]=($J$5-$J$6+((ROW()-8)/2)*7+(COLUMN()-2))),"☐ "&TransactionsLog[Category]&" "&TEXT(TransactionsLog[Amount],"$0"),"")),""),"")} | D16: {=IF(MONTH($J$5-$J$6+((ROW()-8)/2)*7+(COLUMN()-2))=$J$4,IFERROR(_xlfn.TEXTJOIN(CHAR(10),TRUE,IF((TransactionsLog[Type]="Bill")*(TransactionsLog[Date]=($J$5-$J$6+((ROW()-8)/2)*7+(COLUMN()-2))),"☐ "&TransactionsLog[Category]&" "&TEXT(TransactionsLog[Amount],"$0"),"")),""),"")} | E16: {=IF(MONTH($J$5-$J$6+((ROW()-8)/2)*7+(COLUMN()-2))=$J$4,IFERROR(_xlfn.TEXTJOIN(CHAR(10),TRUE,IF((TransactionsLog[Type]="Bill")*(TransactionsLog[Date]=($J$5-$J$6+((ROW()-8)/2)*7+(COLUMN()-2))),"☐ "&TransactionsLog[Category]&" "&TEXT(TransactionsLog[Amount],"$0"),"")),""),"")} | F16: {=IF(MONTH($J$5-$J$6+((ROW()-8)/2)*7+(COLUMN()-2))=$J$4,IFERROR(_xlfn.TEXTJOIN(CHAR(10),TRUE,IF((TransactionsLog[Type]="Bill")*(TransactionsLog[Date]=($J$5-$J$6+((ROW()-8)/2)*7+(COLUMN()-2))),"☐ "&TransactionsLog[Category]&" "&TEXT(TransactionsLog[Amount],"$0"),"")),""),"")} | G16: {=IF(MONTH($J$5-$J$6+((ROW()-8)/2)*7+(COLUMN()-2))=$J$4,IFERROR(_xlfn.TEXTJOIN(CHAR(10),TRUE,IF((TransactionsLog[Type]="Bill")*(TransactionsLog[Date]=($J$5-$J$6+((ROW()-8)/2)*7+(COLUMN()-2))),"☐ "&TransactionsLog[Category]&" "&TEXT(TransactionsLog[Amount],"$0"),"")),""),"")} | H16: {=IF(MONTH($J$5-$J$6+((ROW()-8)/2)*7+(COLUMN()-2))=$J$4,IFERROR(_xlfn.TEXTJOIN(CHAR(10),TRUE,IF((TransactionsLog[Type]="Bill")*(TransactionsLog[Date]=($J$5-$J$6+((ROW()-8)/2)*7+(COLUMN()-2))),"☐ "&TransactionsLog[Category]&" "&TEXT(TransactionsLog[Amount],"$0"),"")),""),"")}
B17: =IF(MONTH(($J$5-$J$6+35))=$J$4,DAY(($J$5-$J$6+35)),"") | C17: =IF(MONTH(($J$5-$J$6+36))=$J$4,DAY(($J$5-$J$6+36)),"") | D17: =IF(MONTH(($J$5-$J$6+37))=$J$4,DAY(($J$5-$J$6+37)),"") | E17: =IF(MONTH(($J$5-$J$6+38))=$J$4,DAY(($J$5-$J$6+38)),"") | F17: =IF(MONTH(($J$5-$J$6+39))=$J$4,DAY(($J$5-$J$6+39)),"") | G17: =IF(MONTH(($J$5-$J$6+40))=$J$4,DAY(($J$5-$J$6+40)),"") | H17: =IF(MONTH(($J$5-$J$6+41))=$J$4,DAY(($J$5-$J$6+41)),"")
B18: {=IF(MONTH($J$5-$J$6+((ROW()-8)/2)*7+(COLUMN()-2))=$J$4,IFERROR(_xlfn.TEXTJOIN(CHAR(10),TRUE,IF((TransactionsLog[Type]="Bill")*(TransactionsLog[Date]=($J$5-$J$6+((ROW()-8)/2)*7+(COLUMN()-2))),"☐ "&TransactionsLog[Category]&" "&TEXT(TransactionsLog[Amount],"$0"),"")),""),"")} | C18: {=IF(MONTH($J$5-$J$6+((ROW()-8)/2)*7+(COLUMN()-2))=$J$4,IFERROR(_xlfn.TEXTJOIN(CHAR(10),TRUE,IF((TransactionsLog[Type]="Bill")*(TransactionsLog[Date]=($J$5-$J$6+((ROW()-8)/2)*7+(COLUMN()-2))),"☐ "&TransactionsLog[Category]&" "&TEXT(TransactionsLog[Amount],"$0"),"")),""),"")} | D18: {=IF(MONTH($J$5-$J$6+((ROW()-8)/2)*7+(COLUMN()-2))=$J$4,IFERROR(_xlfn.TEXTJOIN(CHAR(10),TRUE,IF((TransactionsLog[Type]="Bill")*(TransactionsLog[Date]=($J$5-$J$6+((ROW()-8)/2)*7+(COLUMN()-2))),"☐ "&TransactionsLog[Category]&" "&TEXT(TransactionsLog[Amount],"$0"),"")),""),"")} | E18: {=IF(MONTH($J$5-$J$6+((ROW()-8)/2)*7+(COLUMN()-2))=$J$4,IFERROR(_xlfn.TEXTJOIN(CHAR(10),TRUE,IF((TransactionsLog[Type]="Bill")*(TransactionsLog[Date]=($J$5-$J$6+((ROW()-8)/2)*7+(COLUMN()-2))),"☐ "&TransactionsLog[Category]&" "&TEXT(TransactionsLog[Amount],"$0"),"")),""),"")} | F18: {=IF(MONTH($J$5-$J$6+((ROW()-8)/2)*7+(COLUMN()-2))=$J$4,IFERROR(_xlfn.TEXTJOIN(CHAR(10),TRUE,IF((TransactionsLog[Type]="Bill")*(TransactionsLog[Date]=($J$5-$J$6+((ROW()-8)/2)*7+(COLUMN()-2))),"☐ "&TransactionsLog[Category]&" "&TEXT(TransactionsLog[Amount],"$0"),"")),""),"")} | G18: {=IF(MONTH($J$5-$J$6+((ROW()-8)/2)*7+(COLUMN()-2))=$J$4,IFERROR(_xlfn.TEXTJOIN(CHAR(10),TRUE,IF((TransactionsLog[Type]="Bill")*(TransactionsLog[Date]=($J$5-$J$6+((ROW()-8)/2)*7+(COLUMN()-2))),"☐ "&TransactionsLog[Category]&" "&TEXT(TransactionsLog[Amount],"$0"),"")),""),"")} | H18: {=IF(MONTH($J$5-$J$6+((ROW()-8)/2)*7+(COLUMN()-2))=$J$4,IFERROR(_xlfn.TEXTJOIN(CHAR(10),TRUE,IF((TransactionsLog[Type]="Bill")*(TransactionsLog[Date]=($J$5-$J$6+((ROW()-8)/2)*7+(COLUMN()-2))),"☐ "&TransactionsLog[Category]&" "&TEXT(TransactionsLog[Amount],"$0"),"")),""),"")}

Sheet Subscription Tracker
A1: Subscription Tracker
A2: See what you're really paying for streaming, memberships, and software each month. The total below flows into your Bill Tracker automatically. No need to log these in the Transactions Log too.
B4: Monthly Subscriptions Total | C4: =SUM(SubscriptionTracker[Monthly Price]) -> 0 | D4: Annual Subscriptions Total | E4: =SUM(SubscriptionTracker[Annual Price]) -> 0
K5: By Category | L5: Monthly
A6: Subscription | B6: Category | C6: Billing Frequency | D6: Auto-Renew | E6: Debit Day | F6: Price | G6: Monthly Price | H6: Annual Price | I6: Notes | K6: =Settings!T3 -> Streaming | L6: =SUMIF(SubscriptionTracker[Category],$K6,SubscriptionTracker[Monthly Price]) -> 0
G7: =IFERROR(IF(SubscriptionTracker[[#This Row],[Billing Frequency]]="Monthly",SubscriptionTracker[[#This Row],[Price]],IF(SubscriptionTracker[[#This Row],[Billing Frequency]]="Quarterly",SubscriptionTracker[[#This Row],[Price]]/3,IF(SubscriptionTracker[[#This Row],[Billing Frequency]]="Annually",SubscriptionTracker[[#This Row],[Price]]/12,""))),"") | H7: =IFERROR(SubscriptionTracker[[#This Row],[Monthly Price]]*12,"") | K7: =Settings!T4 -> Software & Apps | L7: =SUMIF(SubscriptionTracker[Category],$K7,SubscriptionTracker[Monthly Price]) -> 0
G8: =IFERROR(IF(SubscriptionTracker[[#This Row],[Billing Frequency]]="Monthly",SubscriptionTracker[[#This Row],[Price]],IF(SubscriptionTracker[[#This Row],[Billing Frequency]]="Quarterly",SubscriptionTracker[[#This Row],[Price]]/3,IF(SubscriptionTracker[[#This Row],[Billing Frequency]]="Annually",SubscriptionTracker[[#This Row],[Price]]/12,""))),"") | H8: =IFERROR(SubscriptionTracker[[#This Row],[Monthly Price]]*12,"") | K8: =Settings!T5 -> Music | L8: =SUMIF(SubscriptionTracker[Category],$K8,SubscriptionTracker[Monthly Price]) -> 0
G9: =IFERROR(IF(SubscriptionTracker[[#This Row],[Billing Frequency]]="Monthly",SubscriptionTracker[[#This Row],[Price]],IF(SubscriptionTracker[[#This Row],[Billing Frequency]]="Quarterly",SubscriptionTracker[[#This Row],[Price]]/3,IF(SubscriptionTracker[[#This Row],[Billing Frequency]]="Annually",SubscriptionTracker[[#This Row],[Price]]/12,""))),"") | H9: =IFERROR(SubscriptionTracker[[#This Row],[Monthly Price]]*12,"") | K9: =Settings!T6 -> News & Reading | L9: =SUMIF(SubscriptionTracker[Category],$K9,SubscriptionTracker[Monthly Price]) -> 0
G10: =IFERROR(IF(SubscriptionTracker[[#This Row],[Billing Frequency]]="Monthly",SubscriptionTracker[[#This Row],[Price]],IF(SubscriptionTracker[[#This Row],[Billing Frequency]]="Quarterly",SubscriptionTracker[[#This Row],[Price]]/3,IF(SubscriptionTracker[[#This Row],[Billing Frequency]]="Annually",SubscriptionTracker[[#This Row],[Price]]/12,""))),"") | H10: =IFERROR(SubscriptionTracker[[#This Row],[Monthly Price]]*12,"") | K10: =Settings!T7 -> Gaming | L10: =SUMIF(SubscriptionTracker[Category],$K10,SubscriptionTracker[Monthly Price]) -> 0
G11: =IFERROR(IF(SubscriptionTracker[[#This Row],[Billing Frequency]]="Monthly",SubscriptionTracker[[#This Row],[Price]],IF(SubscriptionTracker[[#This Row],[Billing Frequency]]="Quarterly",SubscriptionTracker[[#This Row],[Price]]/3,IF(SubscriptionTracker[[#This Row],[Billing Frequency]]="Annually",SubscriptionTracker[[#This Row],[Price]]/12,""))),"") | H11: =IFERROR(SubscriptionTracker[[#This Row],[Monthly Price]]*12,"") | K11: =Settings!T8 -> Fitness & Wellness | L11: =SUMIF(SubscriptionTracker[Category],$K11,SubscriptionTracker[Monthly Price]) -> 0
G12: =IFERROR(IF(SubscriptionTracker[[#This Row],[Billing Frequency]]="Monthly",SubscriptionTracker[[#This Row],[Price]],IF(SubscriptionTracker[[#This Row],[Billing Frequency]]="Quarterly",SubscriptionTracker[[#This Row],[Price]]/3,IF(SubscriptionTracker[[#This Row],[Billing Frequency]]="Annually",SubscriptionTracker[[#This Row],[Price]]/12,""))),"") | H12: =IFERROR(SubscriptionTracker[[#This Row],[Monthly Price]]*12,"") | K12: =Settings!T9 -> Memberships | L12: =SUMIF(SubscriptionTracker[Category],$K12,SubscriptionTracker[Monthly Price]) -> 0
G13: =IFERROR(IF(SubscriptionTracker[[#This Row],[Billing Frequency]]="Monthly",SubscriptionTracker[[#This Row],[Price]],IF(SubscriptionTracker[[#This Row],[Billing Frequency]]="Quarterly",SubscriptionTracker[[#This Row],[Price]]/3,IF(SubscriptionTracker[[#This Row],[Billing Frequency]]="Annually",SubscriptionTracker[[#This Row],[Price]]/12,""))),"") | H13: =IFERROR(SubscriptionTracker[[#This Row],[Monthly Price]]*12,"") | K13: =Settings!T10 -> Other | L13: =SUMIF(SubscriptionTracker[Category],$K13,SubscriptionTracker[Monthly Price]) -> 0
G14: =IFERROR(IF(SubscriptionTracker[[#This Row],[Billing Frequency]]="Monthly",SubscriptionTracker[[#This Row],[Price]],IF(SubscriptionTracker[[#This Row],[Billing Frequency]]="Quarterly",SubscriptionTracker[[#This Row],[Price]]/3,IF(SubscriptionTracker[[#This Row],[Billing Frequency]]="Annually",SubscriptionTracker[[#This Row],[Price]]/12,""))),"") | H14: =IFERROR(SubscriptionTracker[[#This Row],[Monthly Price]]*12,"")
G15: =IFERROR(IF(SubscriptionTracker[[#This Row],[Billing Frequency]]="Monthly",SubscriptionTracker[[#This Row],[Price]],IF(SubscriptionTracker[[#This Row],[Billing Frequency]]="Quarterly",SubscriptionTracker[[#This Row],[Price]]/3,IF(SubscriptionTracker[[#This Row],[Billing Frequency]]="Annually",SubscriptionTracker[[#This Row],[Price]]/12,""))),"") | H15: =IFERROR(SubscriptionTracker[[#This Row],[Monthly Price]]*12,"")
G16: =IFERROR(IF(SubscriptionTracker[[#This Row],[Billing Frequency]]="Monthly",SubscriptionTracker[[#This Row],[Price]],IF(SubscriptionTracker[[#This Row],[Billing Frequency]]="Quarterly",SubscriptionTracker[[#This Row],[Price]]/3,IF(SubscriptionTracker[[#This Row],[Billing Frequency]]="Annually",SubscriptionTracker[[#This Row],[Price]]/12,""))),"") | H16: =IFERROR(SubscriptionTracker[[#This Row],[Monthly Price]]*12,"")
G17: =IFERROR(IF(SubscriptionTracker[[#This Row],[Billing Frequency]]="Monthly",SubscriptionTracker[[#This Row],[Price]],IF(SubscriptionTracker[[#This Row],[Billing Frequency]]="Quarterly",SubscriptionTracker[[#This Row],[Price]]/3,IF(SubscriptionTracker[[#This Row],[Billing Frequency]]="Annually",SubscriptionTracker[[#This Row],[Price]]/12,""))),"") | H17: =IFERROR(SubscriptionTracker[[#This Row],[Monthly Price]]*12,"")
G18: =IFERROR(IF(SubscriptionTracker[[#This Row],[Billing Frequency]]="Monthly",SubscriptionTracker[[#This Row],[Price]],IF(SubscriptionTracker[[#This Row],[Billing Frequency]]="Quarterly",SubscriptionTracker[[#This Row],[Price]]/3,IF(SubscriptionTracker[[#This Row],[Billing Frequency]]="Annually",SubscriptionTracker[[#This Row],[Price]]/12,""))),"") | H18: =IFERROR(SubscriptionTracker[[#This Row],[Monthly Price]]*12,"")
G19: =IFERROR(IF(SubscriptionTracker[[#This Row],[Billing Frequency]]="Monthly",SubscriptionTracker[[#This Row],[Price]],IF(SubscriptionTracker[[#This Row],[Billing Frequency]]="Quarterly",SubscriptionTracker[[#This Row],[Price]]/3,IF(SubscriptionTracker[[#This Row],[Billing Frequency]]="Annually",SubscriptionTracker[[#This Row],[Price]]/12,""))),"") | H19: =IFERROR(SubscriptionTracker[[#This Row],[Monthly Price]]*12,"")
G20: =IFERROR(IF(SubscriptionTracker[[#This Row],[Billing Frequency]]="Monthly",SubscriptionTracker[[#This Row],[Price]],IF(SubscriptionTracker[[#This Row],[Billing Frequency]]="Quarterly",SubscriptionTracker[[#This Row],[Price]]/3,IF(SubscriptionTracker[[#This Row],[Billing Frequency]]="Annually",SubscriptionTracker[[#This Row],[Price]]/12,""))),"") | H20: =IFERROR(SubscriptionTracker[[#This Row],[Monthly Price]]*12,"")
G21: =IFERROR(IF(SubscriptionTracker[[#This Row],[Billing Frequency]]="Monthly",SubscriptionTracker[[#This Row],[Price]],IF(SubscriptionTracker[[#This Row],[Billing Frequency]]="Quarterly",SubscriptionTracker[[#This Row],[Price]]/3,IF(SubscriptionTracker[[#This Row],[Billing Frequency]]="Annually",SubscriptionTracker[[#This Row],[Price]]/12,""))),"") | H21: =IFERROR(SubscriptionTracker[[#This Row],[Monthly Price]]*12,"")
G22: =IFERROR(IF(SubscriptionTracker[[#This Row],[Billing Frequency]]="Monthly",SubscriptionTracker[[#This Row],[Price]],IF(SubscriptionTracker[[#This Row],[Billing Frequency]]="Quarterly",SubscriptionTracker[[#This Row],[Price]]/3,IF(SubscriptionTracker[[#This Row],[Billing Frequency]]="Annually",SubscriptionTracker[[#This Row],[Price]]/12,""))),"") | H22: =IFERROR(SubscriptionTracker[[#This Row],[Monthly Price]]*12,"")
G23: =IFERROR(IF(SubscriptionTracker[[#This Row],[Billing Frequency]]="Monthly",SubscriptionTracker[[#This Row],[Price]],IF(SubscriptionTracker[[#This Row],[Billing Frequency]]="Quarterly",SubscriptionTracker[[#This Row],[Price]]/3,IF(SubscriptionTracker[[#This Row],[Billing Frequency]]="Annually",SubscriptionTracker[[#This Row],[Price]]/12,""))),"") | H23: =IFERROR(SubscriptionTracker[[#This Row],[Monthly Price]]*12,"")
G24: =IFERROR(IF(SubscriptionTracker[[#This Row],[Billing Frequency]]="Monthly",SubscriptionTracker[[#This Row],[Price]],IF(SubscriptionTracker[[#This Row],[Billing Frequency]]="Quarterly",SubscriptionTracker[[#This Row],[Price]]/3,IF(SubscriptionTracker[[#This Row],[Billing Frequency]]="Annually",SubscriptionTracker[[#This Row],[Price]]/12,""))),"") | H24: =IFERROR(SubscriptionTracker[[#This Row],[Monthly Price]]*12,"")
G25: =IFERROR(IF(SubscriptionTracker[[#This Row],[Billing Frequency]]="Monthly",SubscriptionTracker[[#This Row],[Price]],IF(SubscriptionTracker[[#This Row],[Billing Frequency]]="Quarterly",SubscriptionTracker[[#This Row],[Price]]/3,IF(SubscriptionTracker[[#This Row],[Billing Frequency]]="Annually",SubscriptionTracker[[#This Row],[Price]]/12,""))),"") | H25: =IFERROR(SubscriptionTracker[[#This Row],[Monthly Price]]*12,"")
... G36: =IFERROR(IF(SubscriptionTracker[[#This Row],[Billing Frequency]]="Monthly",SubscriptionTracker[[#This Row],[Price]],IF(SubscriptionTracker[[#This Row],[Billing Frequency]]="Quarterly",SubscriptionTracker[[#This Row],[Price]]/3,IF(SubscriptionTracker[[#This Row],[Billing Frequency]]="Annually",SubscriptionTracker[[#This Row],[Price]]/12,""))),"") | H36: =IFERROR(SubscriptionTracker[[#This Row],[Monthly Price]]*12,"")

Sheet Savings & Debt Goal Tracker
A1: Savings & Debt Goal Tracker
A2: Set up to 8 savings goals and 8 debt payoff goals below. Log a contribution or payment at the bottom any time, and your progress updates automatically.
A4: Savings Goals
A5: Goal Name | B5: Goal Amount | C5: Starting Point | D5: Logged Contributions | E5: Total Saved | F5: Left to Save | G5: Progress % | J5: Goal List (auto)
A6: Emergency Fund | C6: 0 | D6: =IFERROR(SUMIF(GoalLog[Goal Name],$A6,GoalLog[Amount]),0) -> 0 | E6: =C6+D6 -> 0 | F6: =B6-E6 -> 0 | G6: =IFERROR(E6/B6,0) -> 0 | J6: =A6 -> Emergency Fund
A7: Vacation Fund | B7: 0 | C7: 0 | D7: =IFERROR(SUMIF(GoalLog[Goal Name],$A7,GoalLog[Amount]),0) -> 0 | E7: =C7+D7 -> 0 | F7: =B7-E7 -> 0 | G7: =IFERROR(E7/B7,0) -> 0 | J7: =A7 -> Vacation Fund
A8: Holiday Fund | B8: 0 | C8: 0 | D8: =IFERROR(SUMIF(GoalLog[Goal Name],$A8,GoalLog[Amount]),0) -> 0 | E8: =C8+D8 -> 0 | F8: =B8-E8 -> 0 | G8: =IFERROR(E8/B8,0) -> 0 | J8: =A8 -> Holiday Fund
A9: Retirement Savings | B9: 0 | C9: 0 | D9: =IFERROR(SUMIF(GoalLog[Goal Name],$A9,GoalLog[Amount]),0) -> 0 | E9: =C9+D9 -> 0 | F9: =B9-E9 -> 0 | G9: =IFERROR(E9/B9,0) -> 0 | J9: =A9 -> Retirement Savings
A10: General Savings | B10: 0 | C10: 0 | D10: =IFERROR(SUMIF(GoalLog[Goal Name],$A10,GoalLog[Amount]),0) -> 0 | E10: =C10+D10 -> 0 | F10: =B10-E10 -> 0 | G10: =IFERROR(E10/B10,0) -> 0 | J10: =A10 -> General Savings
B11: 0 | C11: 0 | D11: =IFERROR(SUMIF(GoalLog[Goal Name],$A11,GoalLog[Amount]),0) -> 0 | E11: =C11+D11 -> 0 | F11: =B11-E11 -> 0 | G11: =IFERROR(E11/B11,0) -> 0 | J11: =A11 -> 0
B12: 0 | C12: 0 | D12: =IFERROR(SUMIF(GoalLog[Goal Name],$A12,GoalLog[Amount]),0) -> 0 | E12: =C12+D12 -> 0 | F12: =B12-E12 -> 0 | G12: =IFERROR(E12/B12,0) -> 0 | J12: =A12 -> 0
B13: 0 | C13: 0 | D13: =IFERROR(SUMIF(GoalLog[Goal Name],$A13,GoalLog[Amount]),0) -> 0 | E13: =C13+D13 -> 0 | F13: =B13-E13 -> 0 | G13: =IFERROR(E13/B13,0) -> 0 | J13: =A13 -> 0
J14: =A17 -> Credit Card
A15: Debt Payoff Goals | J15: =A18 -> Student Loan
A16: Goal Name | B16: Starting Balance | C16: Already Paid | D16: Logged Payments | E16: Total Paid | F16: Remaining Balance | G16: Progress % | J16: =A19 -> Personal Loan
A17: Credit Card | D17: =IFERROR(SUMIF(GoalLog[Goal Name],$A17,GoalLog[Amount]),0) -> 0 | E17: =C17+D17 -> 0 | F17: =B17-E17 -> 0 | G17: =IFERROR(E17/B17,0) -> 0 | J17: =A20 -> Medical Debt
A18: Student Loan | B18: 0 | C18: 0 | D18: =IFERROR(SUMIF(GoalLog[Goal Name],$A18,GoalLog[Amount]),0) -> 0 | E18: =C18+D18 -> 0 | F18: =B18-E18 -> 0 | G18: =IFERROR(E18/B18,0) -> 0 | J18: =A21 -> 0
A19: Personal Loan | B19: 0 | C19: 0 | D19: =IFERROR(SUMIF(GoalLog[Goal Name],$A19,GoalLog[Amount]),0) -> 0 | E19: =C19+D19 -> 0 | F19: =B19-E19 -> 0 | G19: =IFERROR(E19/B19,0) -> 0 | J19: =A22 -> 0
A20: Medical Debt | B20: 0 | C20: 0 | D20: =IFERROR(SUMIF(GoalLog[Goal Name],$A20,GoalLog[Amount]),0) -> 0 | E20: =C20+D20 -> 0 | F20: =B20-E20 -> 0 | G20: =IFERROR(E20/B20,0) -> 0 | J20: =A23 -> 0
B21: 0 | C21: 0 | D21: =IFERROR(SUMIF(GoalLog[Goal Name],$A21,GoalLog[Amount]),0) -> 0 | E21: =C21+D21 -> 0 | F21: =B21-E21 -> 0 | G21: =IFERROR(E21/B21,0) -> 0 | J21: =A24 -> 0
B22: 0 | C22: 0 | D22: =IFERROR(SUMIF(GoalLog[Goal Name],$A22,GoalLog[Amount]),0) -> 0 | E22: =C22+D22 -> 0 | F22: =B22-E22 -> 0 | G22: =IFERROR(E22/B22,0) -> 0
